Workbook

Sheet AUX_MOD_10
B1: 10. MÓDULO PESSOA FÍSICA
B3: ALÍQUOTA DE REFERÊNCIA | C3: =[1]CONTROLE!$E$7 -> 0.085
B5: I. ARRECADAÇÃO PRÓPRIA
B7: Tabela Resumo - Arrecadação Própria | H7: (R$ bilhões)
C8: 2023 | F8: 2024
B9: Contribuinte Pessoa Física | C9: Débitos apurados | D9: Créditos apurados | E9: Arrecadação estimada | F9: Débitos apurados | G9: Créditos apurados | H9: Arrecadação estimada
B10: 10.1 - Produtor Rural contribuinte CBS - Art. 164 e 165. (Fatur. >3,6 mi e não integrado) | C10: =E20 -> 15.74228 | D10: =F51 -> 23.209398 | E10: =C10-D10 -> -7.4671187 | F10: =G20 -> 15.100024 | G10: =F64 -> 21.856827 | H10: =F10-G10 -> -6.7568027
B11: 10.2 - Serviços Prestados por Pessoas Físicas Contribuintes da CBS | C11: =E45 -> 4.3137172 | D11: =G51 -> 0.78661799 | E11: =C11-D11 -> 3.5270992 | F11: =G45 -> 4.7927644 | G11: =G64 -> 0.85358753 | H11: =F11-G11 -> 3.9391769
B15: 10.1 - Produtor Rural contribuinte da CBS - Art. 164 e 165.
G16: (R$ bilhões)
D17: 2023 | F17: 2024
B18: Alíquotas | C18: Alíquota CBS | D18: BC da produção (Débitos) | E18: Débitos apurados | F18: BC da produção (Débitos) | G18: Débitos apurados
B20: TOTAL | E20: =SUM(E21:E31) -> 15.74228 | G20: =SUM(G21:G31) -> 15.100024
B21: Alíquota 0% - Cesta Básica - Anexo I - Art 125 | C21: =$C$3*(1-100%) -> 0 | D21: =AUX_MOD_10.1!C12 -> 20.087342 | E21: =C21*D21 -> 0 | F21: =AUX_MOD_10.1!D12 -> 25.706661 | G21: =C21*F21 -> 0
B22: Alíquota 0% - Medicamentos - art 146 | C22: =$C$3*(1-100%) -> 0 | D22: =AUX_MOD_10.1!C13 -> 0.0062883362 | E22: =C22*D22 -> 0 | F22: =AUX_MOD_10.1!D13 -> 0.0016921097 | G22: =C22*F22 -> 0
B23: Alíquota 0% - Produtos Hortícolas - Anexo XV - Art 148 | C23: =$C$3*(1-100%) -> 0 | D23: =AUX_MOD_10.1!C14 -> 30.836087 | E23: =C23*D23 -> 0 | F23: =AUX_MOD_10.1!D14 -> 36.450298 | G23: =C23*F23 -> 0
B24: Alíquota 0% - Tratores, maq, caminhões, - Art 110 | C24: =$C$3*(1-100%) -> 0 | D24: =AUX_MOD_10.1!C15 -> 0.63798558 | E24: =C24*D24 -> 0 | F24: =AUX_MOD_10.1!D15 -> 0.46443726 | G24: =C24*F24 -> 0
B25: Alíquota reduzida 60% -Alimentos - Anexo VII - Art 135 | C25: =$C$3*(1-60%) -> 0.034 | D25: =AUX_MOD_10.1!C16 -> 72.868658 | E25: =C25*D25 -> 2.4775344 | F25: =AUX_MOD_10.1!D16 -> 59.656792 | G25: =C25*F25 -> 2.0283309
B26: Alíquota reduzida 60% - Anexo X - art 139 | C26: =$C$3*(1-60%) -> 0.034 | D26: =AUX_MOD_10.1!C17 -> 0 | E26: =C26*D26 -> 0 | F26: =AUX_MOD_10.1!D17 -> 8.985905e-05 | G26: =C26*F26 -> 3.0552077e-06
B27: Alíquota reduzida 60% -Dispositivos médicos - Anexo IV - Art 131 | C27: =$C$3*(1-60%) -> 0.034 | D27: =AUX_MOD_10.1!C18 -> 0.0006806494 | E27: =C27*D27 -> 2.3142079e-05 | F27: =AUX_MOD_10.1!D18 -> 0.018774172 | G27: =C27*F27 -> 0.00063832183
B28: Alíquota reduzida 60% -Insumos agropecuários - Anexo IX - art 138 | C28: =$C$3*(1-60%) -> 0.034 | D28: =AUX_MOD_10.1!C19 -> 213.36861 | E28: =C28*D28 -> 7.2545329 | F28: =AUX_MOD_10.1!D19 -> 200.52223 | G28: =C28*F28 -> 6.8177557
B29: Alíquota reduzida 60% -Medicamentos - Anexo VI - Art 133 § 1º | C29: =$C$3*(1-60%) -> 0.034 | D29: =AUX_MOD_10.1!C20 -> 0.00020917132 | E29: =C29*D29 -> 7.1118249e-06 | F29: =AUX_MOD_10.1!D20 -> 0.0012863894 | G29: =C29*F29 -> 4.3737241e-05
B30: Alíquota reduzida 60% -Produtos agropecuários in natura - art 137 | C30: =$C$3*(1-60%) -> 0.034 | D30: =AUX_MOD_10.1!C21 -> 165.73954 | E30: =C30*D30 -> 5.6351443 | F30: =AUX_MOD_10.1!D21 -> 173.33667 | G30: =C30*F30 -> 5.8934467
B31: Alíquota de Referência - Demais Produtos | C31: =$C$3 -> 0.085 | D31: =AUX_MOD_10.1!C22 -> 4.4122088 | E31: =C31*D31 -> 0.37503774 | F31: =AUX_MOD_10.1!D22 -> 4.2330063 | G31: =C31*F31 -> 0.35980554
B34: 10.2 - Serviços Prestados por Pessoas Físicas Contribuintes da CBS
G35: (R$ bilhões)
D36: 2023 | F36: 2024
B37: Alíquotas | C37: Alíquota CBS | D37: BC dos serviços (Débitos) | E37: Débitos apurados | F37: BC dos serviços (Débitos) | G37: Débitos apurados
B39: Alíq. Referência - Demais serviços e bens | C39: =$C$3 -> 0.085 | D39: =AUX_MOD_10.2!C8 -> 15.368781 | E39: =C39*D39 -> 1.3063464 | F39: =AUX_MOD_10.2!D8 -> 16.561593 | G39: =C39*F39 -> 1.4077354
B40: Alíq. Referência - Titular de Cartório | C40: =$C$3 -> 0.085 | D40: =AUX_MOD_10.2!C9 -> 24.278582 | E40: =C40*D40 -> 2.0636795 | F40: =AUX_MOD_10.2!D9 -> 28.07556 | G40: =C40*F40 -> 2.3864226
B41: Alíq. Reduzida em 30% - Profissionais Liberais - Art. 127 | C41: =$C$3*(1-30%) -> 0.0595 | D41: =AUX_MOD_10.2!C10 -> 4.3292555 | E41: =C41*D41 -> 0.2575907 | F41: =AUX_MOD_10.2!D10 -> 4.732387 | G41: =C41*F41 -> 0.28157703
B42: Alíq. reduzida em 60% - Serviços de saúde - Art. 130 (Anexo III) | C42: =$C$3*(1-60%) -> 0.034 | D42: =AUX_MOD_10.2!C11 -> 19.474973 | E42: =C42*D42 -> 0.66214909 | F42: =AUX_MOD_10.2!D11 -> 20.354267 | G42: =C42*F42 -> 0.69204507
B43: Alíq. reduzida em 60% - Prof. artes, cultura, eventos, jornalistica e audio - Art. 139 (Anexo X) | C43: =$C$3*(1-60%) -> 0.034 | D43: =AUX_MOD_10.2!C12 -> 0.22216157 | E43: =C43*D43 -> 0.0075534934 | F43: =AUX_MOD_10.2!D12 -> 0.22819328 | G43: =C43*F43 -> 0.0077585715
B44: Alíq. reduzida em 60% - Prof. educação - Art. 129 | C44: =$C$3*(1-60%) -> 0.034 | D44: =AUX_MOD_10.2!C13 -> 0.48229616 | E44: =C44*D44 -> 0.01639807 | F44: =AUX_MOD_10.2!D13 -> 0.50663873 | G44: =C44*F44 -> 0.017225717
B45: Total | E45: =SUM(E39:E44) -> 4.3137172 | G45: =SUM(G39:G44) -> 4.7927644
G47: (R$ bilhões)
D48: 2023
D49: BC dos custos e despesas (Créditos) | F49: Créditos apurados
B50: Custos e despesas sujeitos a tomada de crédito tributado as seguintes alíquotas | C50: Alíquota CBS | D50: 10.1 - Produtor Rural contribuinte CBS - Art. 164 e 165. | E50: 10.2 - Serviços Prestados por Pessoas Físicas Contribuintes da CBS | F50: 10.1 - Produtor Rural contribuinte CBS - Art. 164 e 165. | G50: 10.2 - Serviços Prestados por Pessoas Físicas Contribuintes da CBS
B51: Total | F51: =SUM(F52:F58) -> 23.209398 | G51: =SUM(G52:G58) -> 0.78661799
...

Sheet AUX_MOD_10.1
B1: 10. MÓDULO PESSOA FÍSICA
B4: 10.1 - Produtor Rural contribuinte da CBS - Art. 164 e 165.
D7: (R$ bilhões)
B8: Tabela 10.1.1 BC dos Débitos | C8: 2023 | D8: 2024
B9: Alíquotas | C9: BC da produção (Débitos) | D9: BC da produção (Débitos)
B11: TOTAL
B12: Alíquota 0% - Cesta Básica - Anexo I - Art 125 | C12: 20.087342 | D12: 25.706661
B13: Alíquota 0% - Medicamentos - art 146 | C13: 0.0062883362 | D13: 0.0016921097
B14: Alíquota 0% - Produtos Hortícolas - Anexo XV - Art 148 | C14: 30.836087 | D14: 36.450298
B15: Alíquota 0% - Tratores, maq, caminhões, - Art 110 | C15: 0.63798558 | D15: 0.46443726
B16: Alíquota reduzida 60% -Alimentos - Anexo VII - Art 135 | C16: 72.868658 | D16: 59.656792
B17: Alíquota reduzida 60% - Anexo X - art 139 | C17: 0 | D17: 8.985905e-05
B18: Alíquota reduzida 60% -Dispositivos médicos - Anexo IV - Art 131 | C18: 0.0006806494 | D18: 0.018774172
B19: Alíquota reduzida 60% -Insumos agropecuários - Anexo IX - art 138 | C19: 213.36861 | D19: 200.52223
B20: Alíquota reduzida 60% -Medicamentos - Anexo VI - Art 133 § 1º | C20: 0.00020917132 | D20: 0.0012863894
B21: Alíquota reduzida 60% -Produtos agropecuários in natura - art 137 | C21: 165.73954 | D21: 173.33667
B22: Alíquota de Referência - Demais Produtos | C22: 4.4122088 | D22: 4.2330063
D24: (R$ bilhões)
B25: Tabela 10.1.2 BC dos Créditos | C25: 2023 | D25: 2024
B26: Custos e despesas sujeitos a tomada de crédito tributado as seguintes alíquotas | C26: BC dos custos e despesas (Créditos) | D26: BC dos custos e despesas (Créditos)
B27: Total
B28: Alíquota 0% - Cesta Básica - Anexo I - Art 125 | C28: 1.828982 | D28: 2.0437089
B29: Alíquota 0% - Produtos Hortícolas - Anexo XV - Art 148 | C29: 1.8881865 | D29: 2.7161207
B30: Alíquota reduzida 60% -Alimentos - Anexo VII - Art 135 | C30: 13.311615 | D30: 13.142272
B31: Alíquota reduzida 60% -Insumos agropecuários - Anexo IX - art 138 | C31: 279.91974 | D31: 274.13595
B32: Alíquota reduzida 60% -Produtos agropecuários in natura - art 137 | C32: 52.627882 | D32: 60.553778
B33: Alíquota de Referência - Demais Produtos | C33: 116.98363 | D33: 100.51263
B34: Combustíveis | C34: 24.859576 | D34: 25.212835
B37: DADOS
B38: - Declaração do Imposto de Renda das Pessoas Físicas (DIRPF)
B39: - Nota Fiscal Eletrônica (NF-e)
B40: - Esocial
B41: - Dados de arrecadação DARF
B42: - Preço médio combustíveis ANP
B44: Especificação
B45: Periodicidade
B46: 2023-2024
B47: Escopo
B48: Receitas e Despesas da atividade rural dos produtores com renda anual superior a R$ 3,6 milhões, declarados na DIRPF
B49: Notas Fiscais emitidas por produtor rural PF ou pela empresa adquirente de sua produção
...

Sheet AUX_MOD_10.2
B1: 10. MÓDULO PESSOA FÍSICA
B3: 10.2 - Serviços Prestados por Pessoas Físicas Contribuintes da CBS
D4: (R$ bilhões)
B5: Tabela 10.2.1 BC dos Débitos | C5: 2023 | D5: 2024
B6: Alíquotas | C6: BC dos serviços (Débitos) | D6: BC dos serviços (Débitos)
B8: Alíq. Referência - Demais serviços e bens | C8: 15.368781 | D8: 16.561593
B9: Alíq. Referência - Titular de Cartório | C9: 24.278582 | D9: 28.07556
B10: Alíq. Reduzida em 30% - Profissionais Liberais - Art. 127 | C10: 4.3292555 | D10: 4.732387
B11: Alíq. reduzida em 60% - Serviços de saúde - Art. 130 (Anexo III) | C11: 19.474973 | D11: 20.354267
B12: Alíq. reduzida em 60% - Prof. artes, cultura, eventos, jornalistica e audio - Art. 139 (Anexo X) | C12: 0.22216157 | D12: 0.22819328
B13: Alíq. reduzida em 60% - Prof. educação - Art. 129 | C13: 0.48229616 | D13: 0.50663873
D16: (R$ bilhões)
B17: Tabela 10.2.2 BC dos Créditos | C17: 2023 | D17: 2024
B18: Custos e despesas sujeitos a tomada de crédito tributado as seguintes alíquotas | C18: BC dos custos e despesas (Créditos) | D18: BC dos custos e despesas (Créditos)
B19: Alíquota 0% - Cesta Básica - Anexo I - Art 125 | C19: 0 | D19: 0
B20: Alíquota 0% - Produtos Hortícolas - Anexo XV - Art 148 | C20: 0 | D20: 0
B21: Alíquota reduzida 60% -Alimentos - Anexo VII - Art 135 | C21: 0 | D21: 0
B22: Alíquota reduzida 60% -Insumos agropecuários - Anexo IX - art 138 | C22: 0 | D22: 0
B23: Alíquota reduzida 60% -Produtos agropecuários in natura - art 137 | C23: 0 | D23: 0
B24: Alíquota de Referência - Demais Produtos | C24: 9.2543293 | D24: 10.042206
B25: Combustíveis | C25: 0 | D25: 0
B28: DADOS
B29: - Declaração do Imposto de Renda das Pessoas Físicas (DIRPF)
B30: - Carne Leão Web | C30: 1000000000
B32: Especificação
B33: Periodicidade
B34: 2023-2024
B35: Escopo
B36: Ficha de rendimentos do trabalho não assalariado da DIRPF
B37: Informações das despesas discriminadas por tipo declaradas no Carne Leão Web
B39: Informação a extrair
B40: Receitas do trabalho não assalariado discriminadas pela atividade do contribuinte de acordo com a ocupação principal, declaradas na DIRPF
B41: Despesas registradas no livro caixa discriminadas pela atividade do contribuinte de acordo com a ocupação principal, declaradas na DIRPF
B42: Registro das despesas, discriminado por tipo de despesa, declaradas no Carne Leão Web
B44: Segregação/Tratamento dos Dados
B45: Estimativa da base de cálculo dos débitos da CBS pela distribuição dos rendimentos do trabalho não assalariado (DIRPF) de acordo com a classificação das ocupações dos contribuintes nas alíquotas incidentes de CBS sobre suas atividades
... B48: Estimativa da base de cálculo dos créditos pela aplicação desse percentual sobre o valor das despesas registrados na DIRPF, alocados a alíquota de referência

Sheet AUX_MOD_10.3
B1: 10. MÓDULO PESSOA FÍSICA
B4: 10.3 - Parcela destinada a Consumo Intermediário - Produtor Rural contribuinte da CBS - Art. 164 e 165.
D7: (R$ bilhões)
B8: Tabela 10.3 BC dos Débitos | C8: 2023 | D8: 2024
B9: Alíquotas | C9: Produtos/Serviços Prestados pela PF com aproveitamento de créditos pelo adquirente | D9: Produtos/Serviços Prestados pela PF com aproveitamento de créditos pelo adquirente
B10: TOTAL
B11: Alíquota 0% - Cesta Básica - Anexo I - Art 125 | C11: 17.118917 | D11: 21.263957
B12: Alíquota 0% - Medicamentos - art 146 | C12: 0.0053590717 | D12: 0.001399674
B13: Alíquota 0% - Produtos Hortícolas - Anexo XV - Art 148 | C13: 26.279257 | D13: 30.150844
B14: Alíquota 0% - Tratores, maq, caminhões, - Art 110 | C14: 0.5437067 | D14: 0.38417177
B15: Alíquota reduzida 60% -Alimentos - Anexo VII - Art 135 | C15: 62.100427 | D15: 49.34672
B16: Alíquota reduzida 60% - Anexo X - art 139 | C16: 0 | D16: 7.432933e-05
B17: Alíquota reduzida 60% -Dispositivos médicos - Anexo IV - Art 131 | C17: 0.00058006583 | D17: 0.015529561
B18: Alíquota reduzida 60% -Insumos agropecuários - Anexo IX - art 138 | C18: 181.83788 | D18: 165.86735
B19: Alíquota reduzida 60% -Medicamentos - Anexo VI - Art 133 § 1º | C19: 0.00017826084 | D19: 0.0010640716
B20: Alíquota reduzida 60% -Produtos agropecuários in natura - art 137 | C20: 141.24723 | D20: 143.38009
B21: Alíquota de Referência - Demais Produtos | C21: 3.7601907 | D21: 3.501445
B24: DADOS
B25: - Declaração do Imposto de Renda das Pessoas Físicas (DIRPF)
B26: - Nota Fiscal Eletrônica (NF-e)
B28: Especificação
B29: Periodicidade
B30: 2023-2024
B31: Escopo
B32: Receitas da atividade rural dos produtores com renda anual superior a R$ 3,6 milhões, declarados na DIRPF
B33: Notas Fiscais emitidas por produtor rural PF ou pela empresa adquirente de sua produção
B35: Informação a extrair
B36: Identificação do CPF dos produtores rurais PF na DIRPF => preencheu ficha de atividade rural e declarou mais de R$ 3,6 milhões de receita
B37: Valor da receita da atividade rural declaradas na DIRPF
... B46: Aplicação desse percentual sobre os dados produzidos na tabela 10.1.1

Sheet AUX_MOD_10.4
B1: 10. MÓDULO PESSOA FÍSICA
B3: 10.4 - Parcela destinada a Consumo Intermediário - Serviços Prestados por Pessoas Físicas Contribuintes da CBS
D4: (R$ bilhões)
B5: Tabela 10.4 BC dos Débitos Destinados a Consumo Intermediário | C5: 2023 | D5: 2024
B6: Alíquotas | C6: Produtos/Serviços Prestados pela PF com aproveitamento de créditos pelo adquirente | D6: Produtos/Serviços Prestados pela PF com aproveitamento de créditos pelo adquirente
B7: Alíq. Referência - Demais serviços e bens | C7: 7.6843904 | D7: 8.2807965
B8: Alíq. Referência - Titular de Cartório | C8: 22.398093 | D8: 25.900978
B9: Alíq. Reduzida em 30% - Profissionais Liberais - Art. 127 | C9: 3.6129727 | D9: 3.9560883
B10: Alíq. reduzida em 60% - Serviços de saúde - Art. 130 (Anexo III) | C10: 2.4009308 | D10: 2.5093327
B11: Alíq. reduzida em 60% - Prof. artes, cultura, eventos, jornalistica e audio - Art. 139 (Anexo X) | C11: 0.11653676 | D11: 0.11855034
B12: Alíq. reduzida em 60% - Prof. educação - Art. 129 | C12: 0.066488618 | D12: 0.069844447
B16: DADOS
B17: - Declaração do Imposto de Renda das Pessoas Físicas (DIRPF)
B18: - Contas Nacionais
B20: Especificação
B21: Periodicidade
B22: 2023-2024
B23: Escopo
B24: Ficha de rendimentos do trabalho não assalariado da DIRPF
B25: Tabela de Demanda das Contas Nacionais
B27: Informação a extrair
B28: Receitas do trabalho não assalariado discriminadas pela atividade do contribuinte de acordo com a ocupação principal, declaradas na DIRPF
B29: Valores da Demanda Final, da Demanda Total e da Exportação de Bens e Serviços da Tabela de Demanda das Contas Nacionais, discriminados por código do produto
... B35: Estimativa das bases de cálculo da CBS, referentes a parcela do consumo intermediário, discriminadas pelas regras de incidencia da CBS
