Workbook

Sheet CI
A1: Tabela 2 - Usos de bens e serviços - 2021
A3: Código do produto | B3: Descrição do produto | C3: Consumo intermediário das atividades (valores correntes em 1 000 000 R$)
C4: 0191 Agricultura, inclusive o apoio à agricultura e a pós-colheita | D4: 0192 Pecuária, inclusive o apoio à pecuária | E4: 0280 Produção florestal; pesca e aquicultura | F4: 0580 Extração de carvão mineral e de minerais não-metálicos | G4: 0680 Extração de petróleo e gás, inclusive as atividades de apoio | H4: 0791 Extração de minério de ferro, inclusive beneficiamentos e a aglomeração | I4: 0792 Extração de minerais metálicos não-ferrosos, inclusive beneficiamentos | J4: 1091 Abate e produtos de carne, inclusive os produtos do laticínio e da pesca | K4: 1092 Fabricação e refino de açúcar | L4: 1093 Outros produtos alimentares | M4: 1100 Fabricação de bebidas | N4: 1200 Fabricação de produtos do fumo | O4: 1300 Fabricação de produtos têxteis | P4: 1400 Confecção de artefatos do vestuário e acessórios | Q4: 1500 Fabricação de calçados e de artefatos de couro | R4: 1600 Fabricação de produtos da madeira | S4: 1700 Fabricação de celulose, papel e produtos de papel | T4: 1800 Impressão e reprodução de gravações | U4: 1991 Refino de petróleo e coquerias | V4: 1992 Fabricação de biocombustíveis | W4: 2091 Fabricação de químicos orgânicos e inorgânicos, resinas e elastômeros | X4: 2092 Fabricação de defensivos, desinfestantes, tintas e químicos diversos | Y4: 2093 Fabricação de produtos de limpeza, cosméticos/perfumaria e higiene pessoal | Z4: 2100 Fabricação de produtos farmoquímicos e farmacêuticos | AA4: 2200 Fabricação de produtos de borracha e de material plástico | AB4: 2300 Fabricação de produtos de minerais não-metálicos | AC4: 2491 Produção de ferro-gusa/ferroligas, siderurgia e tubos de aço sem costura | AD4: 2492 Metalurgia de metais não-ferrosos e a fundição de metais | AE4: 2500 Fabricação de produtos de metal, exceto máquinas e equipamentos | AF4: 2600 Fabricação de equipamentos de informática, produtos eletrônicos e ópticos | AG4: 2700 Fabricação de máquinas e equipamentos elétricos | AH4: 2800 Fabricação de máquinas e equipamentos mecânicos | AI4: 2991 Fabricação de automóveis, caminhões e ônibus, exceto peças | AJ4: 2992 Fabricação de peças e acessórios para veículos automotores | AK4: 3000 Fabricação de outros equipamentos de transporte, exceto veículos automotores | AL4: 3180 Fabricação de móveis e de produtos de indústrias diversas | AM4: 3300 Manutenção, reparação e instalação de máquinas e equipamentos | AN4: 3500 Energia elétrica, gás natural e outras utilidades | AO4: 3680 Água, esgoto e gestão de resíduos | AP4: 4180 Construção | AQ4: 4500 Comércio e reparação de veículos automotores e motocicletas | AR4: 4680 Comércio por atacado e a varejo, exceto veículos automotores | AS4: 4900 Transporte terrestre | AT4: 5000 Transporte aquaviário | AU4: 5100 Transporte aéreo | AV4: 5280 Armazenamento, atividades auxiliares dos transportes e correio | AW4: 5500 Alojamento | AX4: 5600 Alimentação | AY4: 5800 Edição e edição integrada à impressão | AZ4: 5980 Atividades de televisão, rádio, cinema e gravação/edição de som e imagem | BA4: 6100 Telecomunicações | BB4: 6280 Desenvolvimento de sistemas e outros serviços de informação | BC4: 6480 Intermediação financeira, seguros e previdência complementar | BD4: 6800 Atividades imobiliárias | BE4: 6980 Atividades jurídicas, contábeis, consultoria e sedes de empresas | BF4: 7180 Serviços de arquitetura, engenharia, testes/análises técnicas e P & D | BG4: 7380 Outras atividades profissionais, científicas e técnicas | BH4: 7700 Aluguéis não-imobiliários e gestão de ativos de propriedade intelectual | BI4: 7880 Outras atividades administrativas e serviços complementares | BJ4: 8000 Atividades de vigilância, segurança e investigação | BK4: 8400 Administração pública, defesa e seguridade social | BL4: 8591 Educação pública | BM4: 8592 Educação privada | BN4: 8691 Saúde pública | BO4: 8692 Saúde privada | BP4: 9080 Atividades artísticas, criativas e de espetáculos | BQ4: 9480 Organizações associativas e outros serviços pessoais | BR4: 9700 Serviços domésticos | BS4: ADM PUBLICA | BT4: Total do produto
A6: 01911 | B6: Arroz, trigo e outros cereais | C6: 810 | D6: 616 | E6: 1 | F6: 0 | G6: 0 | H6: 0 | I6: 0 | J6: 103 | K6: 0 | L6: 30748 | M6: 824 | N6: 0 | O6: 0 | P6: 0 | Q6: 0 | R6: 0 | S6: 0 | T6: 0 | U6: 0 | V6: 0 | W6: 0 | X6: 0 | Y6: 0 | Z6: 0 | AA6: 0 | AB6: 0 | AC6: 0 | AD6: 0 | AE6: 0 | AF6: 0 | AG6: 0 | AH6: 0 | AI6: 0 | AJ6: 0 | AK6: 0 | AL6: 0 | AM6: 0 | AN6: 0 | AO6: 0 | AP6: 0 | AQ6: 0 | AR6: 1567 | AS6: 0 | AT6: 0 | AU6: 0 | AV6: 0 | AW6: 1 | AX6: 0 | AY6: 0 | AZ6: 0 | BA6: 0 | BB6: 0 | BC6: 0 | BD6: 0 | BE6: 0 | BF6: 0 | BG6: 0 | BH6: 0 | BI6: 0 | BJ6: 0 | BK6: 216 | BL6: 0 | BM6: 0 | BN6: 0 | BO6: 0 | BP6: 0 | BQ6: 0 | BR6: 0 | BS6: =BN6+BL6+BK6 -> 216 | BT6: =SUM(C6:BR6) -> 34886
A7: 01912 | B7: Milho em grão | C7: 4154 | D7: 13921 | E7: 45 | F7: 0 | G7: 0 | H7: 0 | I7: 0 | J7: 3009 | K7: 0 | L7: 38536 | M7: 0 | N7: 0 | O7: 0 | P7: 0 | Q7: 0 | R7: 0 | S7: 0 | T7: 0 | U7: 0 | V7: 816 | W7: 0 | X7: 0 | Y7: 0 | Z7: 0 | AA7: 0 | AB7: 0 | AC7: 0 | AD7: 0 | AE7: 0 | AF7: 0 | AG7: 0 | AH7: 0 | AI7: 0 | AJ7: 0 | AK7: 0 | AL7: 0 | AM7: 0 | AN7: 0 | AO7: 0 | AP7: 0 | AQ7: 0 | AR7: 1982 | AS7: 0 | AT7: 0 | AU7: 0 | AV7: 0 | AW7: 0 | AX7: 563 | AY7: 0 | AZ7: 0 | BA7: 0 | BB7: 0 | BC7: 0 | BD7: 0 | BE7: 0 | BF7: 0 | BG7: 0 | BH7: 0 | BI7: 0 | BJ7: 0 | BK7: 284 | BL7: 2 | BM7: 0 | BN7: 2 | BO7: 7 | BP7: 0 | BQ7: 0 | BR7: 0 | BS7: =BN7+BL7+BK7 -> 288 | BT7: =SUM(C7:BR7) -> 63321
A8: 01913 | B8: Algodão herbáceo, outras fibras da lav. temporária | C8: 1157 | D8: 51 | E8: 0 | F8: 0 | G8: 0 | H8: 0 | I8: 0 | J8: 0 | K8: 0 | L8: 1849 | M8: 0 | N8: 0 | O8: 12975 | P8: 0 | Q8: 0 | R8: 0 | S8: 0 | T8: 0 | U8: 0 | V8: 343 | W8: 0 | X8: 0 | Y8: 0 | Z8: 0 | AA8: 0 | AB8: 0 | AC8: 0 | AD8: 0 | AE8: 0 | AF8: 0 | AG8: 0 | AH8: 0 | AI8: 0 | AJ8: 0 | AK8: 0 | AL8: 0 | AM8: 0 | AN8: 0 | AO8: 0 | AP8: 0 | AQ8: 0 | AR8: 625 | AS8: 0 | AT8: 0 | AU8: 0 | AV8: 0 | AW8: 0 | AX8: 0 | AY8: 0 | AZ8: 0 | BA8: 0 | BB8: 0 | BC8: 0 | BD8: 0 | BE8: 0 | BF8: 0 | BG8: 0 | BH8: 0 | BI8: 0 | BJ8: 0 | BK8: 0 | BL8: 0 | BM8: 0 | BN8: 0 | BO8: 0 | BP8: 0 | BQ8: 0 | BR8: 0 | BS8: =BN8+BL8+BK8 -> 0 | BT8: =SUM(C8:BR8) -> 17000
A9: 01914 | B9: Cana-de-açúcar | C9: 1270 | D9: 334 | E9: 5 | F9: 0 | G9: 0 | H9: 0 | I9: 0 | J9: 0 | K9: 43018 | L9: 0 | M9: 3465 | N9: 0 | O9: 0 | P9: 0 | Q9: 0 | R9: 0 | S9: 0 | T9: 0 | U9: 0 | V9: 30879 | W9: 0 | X9: 0 | Y9: 0 | Z9: 0 | AA9: 0 | AB9: 0 | AC9: 0 | AD9: 0 | AE9: 0 | AF9: 0 | AG9: 0 | AH9: 0 | AI9: 0 | AJ9: 0 | AK9: 0 | AL9: 0 | AM9: 0 | AN9: 0 | AO9: 0 | AP9: 0 | AQ9: 0 | AR9: 0 | AS9: 0 | AT9: 0 | AU9: 0 | AV9: 0 | AW9: 0 | AX9: 1676 | AY9: 0 | AZ9: 0 | BA9: 0 | BB9: 0 | BC9: 0 | BD9: 0 | BE9: 0 | BF9: 0 | BG9: 0 | BH9: 0 | BI9: 0 | BJ9: 0 | BK9: 0 | BL9: 0 | BM9: 0 | BN9: 0 | BO9: 0 | BP9: 0 | BQ9: 0 | BR9: 0 | BS9: =BN9+BL9+BK9 -> 0 | BT9: =SUM(C9:BR9) -> 80647
A10: 01915 | B10: Soja em grão | C10: 5730 | D10: 475 | E10: 4 | F10: 0 | G10: 0 | H10: 0 | I10: 0 | J10: 1267 | K10: 0 | L10: 88515 | M10: 0 | N10: 0 | O10: 0 | P10: 0 | Q10: 0 | R10: 0 | S10: 0 | T10: 0 | U10: 0 | V10: 6892 | W10: 0 | X10: 0 | Y10: 0 | Z10: 0 | AA10: 0 | AB10: 0 | AC10: 0 | AD10: 0 | AE10: 0 | AF10: 0 | AG10: 0 | AH10: 0 | AI10: 0 | AJ10: 0 | AK10: 0 | AL10: 0 | AM10: 0 | AN10: 0 | AO10: 0 | AP10: 0 | AQ10: 0 | AR10: 19665 | AS10: 0 | AT10: 0 | AU10: 0 | AV10: 0 | AW10: 0 | AX10: 0 | AY10: 0 | AZ10: 0 | BA10: 0 | BB10: 0 | BC10: 0 | BD10: 0 | BE10: 0 | BF10: 0 | BG10: 0 | BH10: 0 | BI10: 0 | BJ10: 0 | BK10: 0 | BL10: 0 | BM10: 0 | BN10: 0 | BO10: 0 | BP10: 0 | BQ10: 0 | BR10: 0 | BS10: =BN10+BL10+BK10 -> 0 | BT10: =SUM(C10:BR10) -> 122548
A11: 01916 | B11: Outros produtos e serviços da lavoura temporária | C11: 8835 | D11: 1349 | E11: 81 | F11: 0 | G11: 0 | H11: 0 | I11: 0 | J11: 54 | K11: 0 | L11: 10512 | M11: 0 | N11: 8057 | O11: 0 | P11: 0 | Q11: 0 | R11: 0 | S11: 0 | T11: 0 | U11: 0 | V11: 1258 | W11: 0 | X11: 0 | Y11: 0 | Z11: 0 | AA11: 0 | AB11: 0 | AC11: 0 | AD11: 0 | AE11: 0 | AF11: 0 | AG11: 0 | AH11: 0 | AI11: 0 | AJ11: 0 | AK11: 0 | AL11: 0 | AM11: 0 | AN11: 0 | AO11: 90 | AP11: 4 | AQ11: 0 | AR11: 785 | AS11: 0 | AT11: 0 | AU11: 0 | AV11: 0 | AW11: 384 | AX11: 3948 | AY11: 0 | AZ11: 0 | BA11: 0 | BB11: 0 | BC11: 0 | BD11: 0 | BE11: 7 | BF11: 0 | BG11: 0 | BH11: 0 | BI11: 249 | BJ11: 0 | BK11: 1023 | BL11: 508 | BM11: 108 | BN11: 658 | BO11: 313 | BP11: 1 | BQ11: 595 | BR11: 0 | BS11: =BN11+BL11+BK11 -> 2189 | BT11: =SUM(C11:BR11) -> 38819
A12: 01917 | B12: Laranja | C12: 20 | D12: 20 | E12: 8 | F12: 0 | G12: 0 | H12: 0 | I12: 0 | J12: 0 | K12: 0 | L12: 15241 | M12: 0 | N12: 0 | O12: 0 | P12: 0 | Q12: 0 | R12: 0 | S12: 0 | T12: 0 | U12: 0 | V12: 0 | W12: 0 | X12: 0 | Y12: 0 | Z12: 0 | AA12: 0 | AB12: 0 | AC12: 0 | AD12: 0 | AE12: 0 | AF12: 0 | AG12: 0 | AH12: 0 | AI12: 0 | AJ12: 0 | AK12: 0 | AL12: 0 | AM12: 0 | AN12: 0 | AO12: 0 | AP12: 0 | AQ12: 0 | AR12: 0 | AS12: 0 | AT12: 0 | AU12: 0 | AV12: 0 | AW12: 142 | AX12: 565 | AY12: 0 | AZ12: 0 | BA12: 0 | BB12: 0 | BC12: 0 | BD12: 0 | BE12: 0 | BF12: 0 | BG12: 0 | BH12: 0 | BI12: 0 | BJ12: 0 | BK12: 18 | BL12: 10 | BM12: 0 | BN12: 10 | BO12: 0 | BP12: 0 | BQ12: 8 | BR12: 0 | BS12: =BN12+BL12+BK12 -> 38 | BT12: =SUM(C12:BR12) -> 16042
A13: 01918 | B13: Café em grão | C13: 64 | D13: 232 | E13: 1 | F13: 0 | G13: 0 | H13: 0 | I13: 0 | J13: 0 | K13: 0 | L13: 8972 | M13: 0 | N13: 0 | O13: 0 | P13: 0 | Q13: 0 | R13: 0 | S13: 0 | T13: 0 | U13: 0 | V13: 0 | W13: 0 | X13: 0 | Y13: 0 | Z13: 0 | AA13: 0 | AB13: 0 | AC13: 0 | AD13: 0 | AE13: 0 | AF13: 0 | AG13: 0 | AH13: 0 | AI13: 0 | AJ13: 0 | AK13: 0 | AL13: 0 | AM13: 0 | AN13: 0 | AO13: 0 | AP13: 0 | AQ13: 0 | AR13: 0 | AS13: 0 | AT13: 0 | AU13: 0 | AV13: 0 | AW13: 0 | AX13: 0 | AY13: 0 | AZ13: 0 | BA13: 0 | BB13: 0 | BC13: 0 | BD13: 0 | BE13: 0 | BF13: 3 | BG13: 0 | BH13: 0 | BI13: 0 | BJ13: 0 | BK13: 6 | BL13: 0 | BM13: 0 | BN13: 0 | BO13: 0 | BP13: 0 | BQ13: 14 | BR13: 0 | BS13: =BN13+BL13+BK13 -> 6 | BT13: =SUM(C13:BR13) -> 9292
A14: 01919 | B14: Outros produtos da lavoura permanente | C14: 316 | D14: 34 | E14: 1 | F14: 0 | G14: 0 | H14: 0 | I14: 0 | J14: 1 | K14: 0 | L14: 4765 | M14: 34 | N14: 0 | O14: 0 | P14: 0 | Q14: 0 | R14: 0 | S14: 0 | T14: 0 | U14: 0 | V14: 0 | W14: 0 | X14: 0 | Y14: 0 | Z14: 0 | AA14: 0 | AB14: 0 | AC14: 0 | AD14: 0 | AE14: 0 | AF14: 0 | AG14: 0 | AH14: 0 | AI14: 0 | AJ14: 0 | AK14: 0 | AL14: 0 | AM14: 0 | AN14: 0 | AO14: 0 | AP14: 0 | AQ14: 0 | AR14: 226 | AS14: 0 | AT14: 0 | AU14: 0 | AV14: 0 | AW14: 34 | AX14: 875 | AY14: 0 | AZ14: 0 | BA14: 0 | BB14: 0 | BC14: 0 | BD14: 0 | BE14: 0 | BF14: 2 | BG14: 0 | BH14: 0 | BI14: 0 | BJ14: 0 | BK14: 264 | BL14: 120 | BM14: 3 | BN14: 130 | BO14: 29 | BP14: 0 | BQ14: 3 | BR14: 0 | BS14: =BN14+BL14+BK14 -> 514 | BT14: =SUM(C14:BR14) -> 6837
A15: 01921 | B15: Bovinos e outros animais vivos, prods. animal, caça e serv. | C15: 960 | D15: 5137 | E15: 22 | F15: 0 | G15: 0 | H15: 0 | I15: 0 | J15: 104582 | K15: 0 | L15: 54 | M15: 0 | N15: 0 | O15: 0 | P15: 0 | Q15: 0 | R15: 0 | S15: 0 | T15: 0 | U15: 0 | V15: 0 | W15: 0 | X15: 0 | Y15: 0 | Z15: 0 | AA15: 0 | AB15: 0 | AC15: 0 | AD15: 0 | AE15: 0 | AF15: 0 | AG15: 0 | AH15: 0 | AI15: 0 | AJ15: 0 | AK15: 0 | AL15: 0 | AM15: 0 | AN15: 0 | AO15: 0 | AP15: 0 | AQ15: 0 | AR15: 0 | AS15: 0 | AT15: 0 | AU15: 0 | AV15: 0 | AW15: 0 | AX15: 0 | AY15: 0 | AZ15: 0 | BA15: 0 | BB15: 0 | BC15: 0 | BD15: 0 | BE15: 0 | BF15: 0 | BG15: 11 | BH15: 0 | BI15: 0 | BJ15: 0 | BK15: 236 | BL15: 75 | BM15: 5 | BN15: 0 | BO15: 119 | BP15: 0 | BQ15: 0 | BR15: 0 | BS15: =BN15+BL15+BK15 -> 311 | BT15: =SUM(C15:BR15) -> 111201
A16: 01922 | B16: Leite de vaca e de outros animais | C16: 130 | D16: 2955 | E16: 87 | F16: 0 | G16: 0 | H16: 0 | I16: 0 | J16: 36941 | K16: 0 | L16: 0 | M16: 0 | N16: 0 | O16: 0 | P16: 0 | Q16: 0 | R16: 0 | S16: 0 | T16: 0 | U16: 0 | V16: 0 | W16: 0 | X16: 0 | Y16: 0 | Z16: 0 | AA16: 0 | AB16: 0 | AC16: 0 | AD16: 0 | AE16: 0 | AF16: 0 | AG16: 0 | AH16: 0 | AI16: 0 | AJ16: 0 | AK16: 0 | AL16: 0 | AM16: 0 | AN16: 0 | AO16: 0 | AP16: 0 | AQ16: 0 | AR16: 0 | AS16: 0 | AT16: 0 | AU16: 0 | AV16: 0 | AW16: 0 | AX16: 123 | AY16: 0 | AZ16: 0 | BA16: 0 | BB16: 0 | BC16: 0 | BD16: 0 | BE16: 0 | BF16: 0 | BG16: 0 | BH16: 0 | BI16: 0 | BJ16: 0 | BK16: 0 | BL16: 0 | BM16: 0 | BN16: 0 | BO16: 0 | BP16: 0 | BQ16: 17 | BR16: 0 | BS16: =BN16+BL16+BK16 -> 0 | BT16: =SUM(C16:BR16) -> 40253
A17: 01923 | B17: Suínos | C17: 83 | D17: 536 | E17: 3 | F17: 0 | G17: 0 | H17: 0 | I17: 0 | J17: 17044 | K17: 0 | L17: 0 | M17: 0 | N17: 0 | O17: 0 | P17: 0 | Q17: 0 | R17: 0 | S17: 0 | T17: 0 | U17: 0 | V17: 0 | W17: 0 | X17: 0 | Y17: 0 | Z17: 0 | AA17: 0 | AB17: 0 | AC17: 0 | AD17: 0 | AE17: 0 | AF17: 0 | AG17: 0 | AH17: 0 | AI17: 0 | AJ17: 0 | AK17: 0 | AL17: 0 | AM17: 0 | AN17: 0 | AO17: 0 | AP17: 0 | AQ17: 0 | AR17: 0 | AS17: 0 | AT17: 0 | AU17: 0 | AV17: 0 | AW17: 0 | AX17: 0 | AY17: 0 | AZ17: 0 | BA17: 0 | BB17: 0 | BC17: 0 | BD17: 0 | BE17: 0 | BF17: 0 | BG17: 0 | BH17: 0 | BI17: 0 | BJ17: 0 | BK17: 0 | BL17: 0 | BM17: 0 | BN17: 0 | BO17: 0 | BP17: 0 | BQ17: 0 | BR17: 0 | BS17: =BN17+BL17+BK17 -> 0 | BT17: =SUM(C17:BR17) -> 17666
... A133: 97001 | B133: Serviços domésticos | C133: 0 | D133: 0 | E133: 0 | F133: 0 | G133: 0 | H133: 0 | I133: 0 | J133: 0 | K133: 0 | L133: 0 | M133: 0 | N133: 0 | O133: 0 | P133: 0 | Q133: 0 | R133: 0 | S133: 0 | T133: 0 | U133: 0 | V133: 0 | W133: 0 | X133: 0 | Y133: 0 | Z133: 0 | AA133: 0 | AB133: 0 | AC133: 0 | AD133: 0 | AE133: 0 | AF133: 0 | AG133: 0 | AH133: 0 | AI133: 0 | AJ133: 0 | AK133: 0 | AL133: 0 | AM133: 0 | AN133: 0 | AO133: 0 | AP133: 0 | AQ133: 0 | AR133: 0 | AS133: 0 | AT133: 0 | AU133: 0 | AV133: 0 | AW133: 0 | AX133: 0 | AY133: 0 | AZ133: 0 | BA133: 0 | BB133: 0 | BC133: 0 | BD133: 0 | BE133: 0 | BF133: 0 | BG133: 0 | BH133: 0 | BI133: 0 | BJ133: 0 | BK133: 0 | BL133: 0 | BM133: 0 | BN133: 0 | BO133: 0 | BP133: 0 | BQ133: 0 | BR133: 0 | BS133: =BN133+BL133+BK133 -> 0 | BT133: =SUM(C133:BR133) -> 0
C134: 0 | D134: 0 | E134: 0 | F134: 0 | G134: 0 | H134: 0 | I134: 0 | J134: 0 | K134: 0 | L134: 0 | M134: 0 | N134: 0 | O134: 0 | P134: 0 | Q134: 0 | R134: 0 | S134: 0 | T134: 0 | U134: 0 | V134: 0 | W134: 0 | X134: 0 | Y134: 0 | Z134: 0 | AA134: 0 | AB134: 0 | AC134: 0 | AD134: 0 | AE134: 0 | AF134: 0 | AG134: 0 | AH134: 0 | AI134: 0 | AJ134: 0 | AK134: 0 | AL134: 0 | AM134: 0 | AN134: 0 | AO134: 0 | AP134: 0 | AQ134: 0 | AR134: 0 | AS134: 0 | AT134: 0 | AU134: 0 | AV134: 0 | AW134: 0 | AX134: 0 | AY134: 0 | AZ134: 0 | BA134: 0 | BB134: 0 | BC134: 0 | BD134: 0 | BE134: 0 | BF134: 0 | BG134: 0 | BH134: 0 | BI134: 0 | BJ134: 0 | BK134: 0 | BL134: 0 | BM134: 0 | BN134: 0 | BO134: 0 | BP134: 0 | BQ134: 0 | BR134: 0 | BS134: =BN134+BL134+BK134 -> 0 | BT134: =SUM(C134:BR134) -> 0
A135: Total | C135: =SUM(C6:C134) -> 348051 | D135: =SUM(D6:D134) -> 141796 | E135: =SUM(E6:E134) -> 15212 | F135: =SUM(F6:F134) -> 18520 | G135: =SUM(G6:G134) -> 174814 | H135: =SUM(H6:H134) -> 111869 | I135: =SUM(I6:I134) -> 16523 | J135: =SUM(J6:J134) -> 435454 | ... BR135: =SUM(BR6:BR134) -> 0 | BS135: =BN135+BL135+BK135 -> 457769 | BT135: =SUM(BT6:BT134) -> 8867874
BS137: =BS135/BT135 -> 0.051621054
BK138: O consumo intermediário compreende as despesas correntes com a compra de bens e serviços, exclusive máquinas, equipamentos, construção e outros destinados à formação bruta de capital.
BK139: O SCN considera todas as construções da administração pública, inclusive as militares, como formação bruta de capital.
BK140: As despesas com a compra de serviços hospitalares pelo SUS não são tratadas como consumo intermediário, mas como consumo final mercantil das administrações públicas.
BK141: Fonte: nota 11

Sheet demanda
A1: Tabela 2 - Usos de bens e serviços - 2021
A3: Código do produto | B3: Descrição do produto | C3: Demanda final (valores correntes em 1 000 000 R$)
C4: Exportação de bens e serviços (1) | D4: Consumo do governo | E4: Consumo das ISFLSF | F4: Consumo das famílias | G4: Formação bruta de capital fixo | H4: Variação de estoque | I4: Demanda final | J4: Demanda total
A6: 01911 | B6: Arroz, trigo e outros cereais | C6: 1979 | D6: 70 | E6: 0 | F6: 1409 | G6: 0 | H6: 12245 | I6: =SUM(C6:H6) -> 15703 | J6: =I6+CI!BT6 -> 50589 | K6: =J6-I6 -> 34886
A7: 01912 | B7: Milho em grão | C7: 22656 | D7: 53 | E7: 0 | F7: 9779 | G7: 0 | H7: 30117 | I7: =SUM(C7:H7) -> 62605 | J7: =I7+CI!BT7 -> 125926
A8: 01913 | B8: Algodão herbáceo, outras fibras da lav. temporária | C8: 18609 | D8: 0 | E8: 0 | F8: 11 | G8: 0 | H8: -830 | I8: =SUM(C8:H8) -> 17790 | J8: =I8+CI!BT8 -> 34790
A9: 01914 | B9: Cana-de-açúcar | C9: 3 | D9: 0 | E9: 0 | F9: 2318 | G9: 0 | H9: 0 | I9: =SUM(C9:H9) -> 2321 | J9: =I9+CI!BT9 -> 82968
A10: 01915 | B10: Soja em grão | C10: 213948 | D10: 0 | E10: 0 | F10: 309 | G10: 0 | H10: 9032 | I10: =SUM(C10:H10) -> 223289 | J10: =I10+CI!BT10 -> 345837
A11: 01916 | B11: Outros produtos e serviços da lavoura temporária | C11: 3981 | D11: 53 | E11: 0 | F11: 100772 | G11: 0 | H11: -883 | I11: =SUM(C11:H11) -> 103923 | J11: =I11+CI!BT11 -> 142742
A12: 01917 | B12: Laranja | C12: 5 | D12: 0 | E12: 0 | F12: 4157 | G12: 356 | H12: 0 | I12: =SUM(C12:H12) -> 4518 | J12: =I12+CI!BT12 -> 20560
A13: 01918 | B13: Café em grão | C13: 31487 | D13: 0 | E13: 0 | F13: 936 | G13: 189 | H13: -1687 | I13: =SUM(C13:H13) -> 30925 | J13: =I13+CI!BT13 -> 40217
A14: 01919 | B14: Outros produtos da lavoura permanente | C14: 4124 | D14: 8 | E14: 0 | F14: 48240 | G14: 255 | H14: 0 | I14: =SUM(C14:H14) -> 52627 | J14: =I14+CI!BT14 -> 59464
A15: 01921 | B15: Bovinos e outros animais vivos, prods. animal, caça e serv. | C15: 1972 | D15: 0 | E15: 0 | F15: 1358 | G15: 27970 | H15: -1012 | I15: =SUM(C15:H15) -> 30288 | J15: =I15+CI!BT15 -> 141489
A16: 01922 | B16: Leite de vaca e de outros animais | C16: 0 | D16: 0 | E16: 0 | F16: 19981 | G16: 0 | H16: 0 | I16: =SUM(C16:H16) -> 19981 | J16: =I16+CI!BT16 -> 60234
A17: 01923 | B17: Suínos | C17: 23 | D17: 0 | E17: 0 | F17: 449 | G17: 82 | H17: 0 | I17: =SUM(C17:H17) -> 554 | J17: =I17+CI!BT17 -> 18220
A18: 01924 | B18: Aves e ovos | C18: 1737 | D18: 3 | E18: 0 | F18: 18764 | G18: 228 | H18: 8 | I18: =SUM(C18:H18) -> 20740 | J18: =I18+CI!BT18 -> 61667
... A133: 97001 | B133: Serviços domésticos | C133: 0 | D133: 0 | E133: 0 | F133: 61371 | G133: 0 | H133: 0 | I133: =SUM(C133:H133) -> 61371 | J133: =I133+CI!BT133 -> 61371
A135: Total | C135: =SUM(C6:C134) -> 1722169 | D135: =SUM(D6:D134) -> 1671535 | E135: =SUM(E6:E134) -> 115048 | F135: =SUM(F6:F134) -> 5415523 | G135: =SUM(G6:G134) -> 1614782 | H135: =SUM(H6:H134) -> 144558 | I135: =SUM(I6:I134) -> 10683615 | J135: =SUM(J6:J134) -> 19551489

Sheet VA
A1: Tabela 2 - Usos de bens e serviços - 2021
A3: Operações | B3: Componentes do valor adicionado (valores correntes em 1 000 000 R$)
B4: 0191 Agricultura, inclusive o apoio à agricultura e a pós-colheita | C4: 0192 Pecuária, inclusive o apoio à pecuária | D4: 0280 Produção florestal; pesca e aquicultura | E4: 0580 Extração de carvão mineral e de minerais não-metálicos | F4: 0680 Extração de petróleo e gás, inclusive as atividades de apoio | G4: 0791 Extração de minério de ferro, inclusive beneficiamentos e a aglomeração | H4: 0792 Extração de minerais metálicos não-ferrosos, inclusive beneficiamentos | I4: 1091 Abate e produtos de carne, inclusive os produtos do laticínio e da pesca | J4: 1092 Fabricação e refino de açúcar | K4: 1093 Outros produtos alimentares | L4: 1100 Fabricação de bebidas | M4: 1200 Fabricação de produtos do fumo | N4: 1300 Fabricação de produtos têxteis | O4: 1400 Confecção de artefatos do vestuário e acessórios | P4: 1500 Fabricação de calçados e de artefatos de couro | Q4: 1600 Fabricação de produtos da madeira | R4: 1700 Fabricação de celulose, papel e produtos de papel | S4: 1800 Impressão e reprodução de gravações | T4: 1991 Refino de petróleo e coquerias | U4: 1992 Fabricação de biocombustíveis | V4: 2091 Fabricação de químicos orgânicos e inorgânicos, resinas e elastômeros | W4: 2092 Fabricação de defensivos, desinfestantes, tintas e químicos diversos | X4: 2093 Fabricação de produtos de limpeza, cosméticos/perfumaria e higiene pessoal | Y4: 2100 Fabricação de produtos farmoquímicos e farmacêuticos | Z4: 2200 Fabricação de produtos de borracha e de material plástico | AA4: 2300 Fabricação de produtos de minerais não-metálicos | AB4: 2491 Produção de ferro-gusa/ferroligas, siderurgia e tubos de aço sem costura | AC4: 2492 Metalurgia de metais não-ferrosos e a fundição de metais | AD4: 2500 Fabricação de produtos de metal, exceto máquinas e equipamentos | AE4: 2600 Fabricação de equipamentos de informática, produtos eletrônicos e ópticos | AF4: 2700 Fabricação de máquinas e equipamentos elétricos | AG4: 2800 Fabricação de máquinas e equipamentos mecânicos | AH4: 2991 Fabricação de automóveis, caminhões e ônibus, exceto peças | AI4: 2992 Fabricação de peças e acessórios para veículos automotores | AJ4: 3000 Fabricação de outros equipamentos de transporte, exceto veículos automotores | AK4: 3180 Fabricação de móveis e de produtos de indústrias diversas | AL4: 3300 Manutenção, reparação e instalação de máquinas e equipamentos | AM4: 3500 Energia elétrica, gás natural e outras utilidades | AN4: 3680 Água, esgoto e gestão de resíduos | AO4: 4180 Construção | AP4: 4500 Comércio e reparação de veículos automotores e motocicletas | AQ4: 4680 Comércio por atacado e a varejo, exceto veículos automotores | AR4: 4900 Transporte terrestre | AS4: 5000 Transporte aquaviário | AT4: 5100 Transporte aéreo | AU4: 5280 Armazenamento, atividades auxiliares dos transportes e correio | AV4: 5500 Alojamento | AW4: 5600 Alimentação | AX4: 5800 Edição e edição integrada à impressão | AY4: 5980 Atividades de televisão, rádio, cinema e gravação/edição de som e imagem | AZ4: 6100 Telecomunicações | BA4: 6280 Desenvolvimento de sistemas e outros serviços de informação | BB4: 6480 Intermediação financeira, seguros e previdência complementar | BC4: 6800 Atividades imobiliárias | BD4: 6980 Atividades jurídicas, contábeis, consultoria e sedes de empresas | BE4: 7180 Serviços de arquitetura, engenharia, testes/análises técnicas e P & D | BF4: 7380 Outras atividades profissionais, científicas e técnicas | BG4: 7700 Aluguéis não-imobiliários e gestão de ativos de propriedade intelectual | BH4: 7880 Outras atividades administrativas e serviços complementares | BI4: 8000 Atividades de vigilância, segurança e investigação | BJ4: 8400 Administração pública, defesa e seguridade social | BK4: 8591 Educação pública | BL4: 8592 Educação privada | BM4: 8691 Saúde pública | BN4: 8692 Saúde privada | BO4: 9080 Atividades artísticas, criativas e de espetáculos | BP4: 9480 Organizações associativas e outros serviços pessoais | BQ4: 9700 Serviços domésticos | BR4: Total do produto
A6: Valor adicionado bruto ( PIB ) | B6: =B18-CI!C135 -> 421109 | C6: =C18-CI!D135 -> 130445 | D6: =D18-CI!E135 -> 39531 | E6: =E18-CI!F135 -> 11561 | F6: =F18-CI!G135 -> 231887 | G6: =G18-CI!H135 -> 167230 | H6: =H18-CI!I135 -> 14189 | I6: =I18-CI!J135 -> 59950 | ... BQ6: =BQ18-CI!BR135 -> 61371 | BR6: =SUM(B6:BQ6) -> 7713999
A7: Remunerações | B7: 37950 | C7: 25160 | D7: 2882 | E7: 4882 | F7: 21242 | G7: 5777 | H7: 3331 | I7: 40203 | J7: 9426 | K7: 39201 | L7: 11397 | M7: 1988 | N7: 12601 | O7: 19120 | P7: 10928 | Q7: 8175 | R7: 16184 | S7: 5338 | T7: 12103 | U7: 8112 | V7: 15965 | W7: 11824 | X7: 7306 | Y7: 15775 | Z7: 25874 | AA7: 23721 | AB7: 14974 | AC7: 7744 | AD7: 27076 | AE7: 10741 | AF7: 18582 | AG7: 35143 | AH7: 20439 | AI7: 22668 | AJ7: 8254 | AK7: 20315 | AL7: 18587 | AM7: 20258 | AN7: 25019 | AO7: 130162 | AP7: 58513 | AQ7: 413275 | AR7: 96653 | AS7: 6472 | AT7: 6682 | AU7: 48512 | AV7: 10988 | AW7: 57472 | AX7: 6183 | AY7: 12175 | AZ7: 23331 | BA7: 81702 | BB7: 201153 | BC7: 9646 | BD7: 80109 | BE7: 24050 | BF7: 22628 | BG7: 14950 | BH7: 145387 | BI7: 32583 | BJ7: 603962 | BK7: 323126 | BL7: 87511 | BM7: 149825 | BN7: 122204 | BO7: 13514 | BP7: 44244 | BQ7: 61371 | BR7: =SUM(B7:BQ7) -> 3534648
A8: Salários | B8: 32130 | C8: 21953 | D8: 2497 | E8: 3819 | F8: 16134 | G8: 4505 | H8: 2646 | I8: 31659 | J8: 6714 | K8: 30796 | L8: 8785 | M8: 1508 | N8: 10276 | O8: 15412 | P8: 9104 | Q8: 6732 | R8: 12680 | S8: 4388 | T8: 8760 | U8: 6140 | V8: 12076 | W8: 9101 | X8: 5723 | Y8: 12102 | Z8: 20045 | AA8: 18923 | AB8: 11307 | AC8: 6216 | AD8: 21508 | AE8: 8468 | AF8: 14383 | AG8: 27444 | AH8: 15764 | AI8: 18860 | AJ8: 6705 | AK8: 16300 | AL8: 15342 | AM8: 14733 | AN8: 18965 | AO8: 107355 | AP8: 47603 | AQ8: 326040 | AR8: 78295 | AS8: 5296 | AT8: 5574 | AU8: 37541 | AV8: 9134 | AW8: 48793 | AX8: 5210 | AY8: 10231 | AZ8: 17555 | BA8: 65562 | BB8: 153797 | BC8: 7572 | BD8: 65440 | BE8: 19296 | BF8: 18734 | BG8: 11963 | BH8: 117177 | BI8: 25808 | BJ8: 429084 | BK8: 260257 | BL8: 73352 | BM8: 122956 | BN8: 105371 | BO8: 11720 | BP8: 37798 | BQ8: 59897 | BR8: =SUM(B8:BQ8) -> 2795014
A9: Contribuições sociais efetivas | B9: 5820 | C9: 3207 | D9: 385 | E9: 1063 | F9: 5108 | G9: 1272 | H9: 685 | I9: 8544 | J9: 2712 | K9: 8405 | L9: 2612 | M9: 480 | N9: 2325 | O9: 3708 | P9: 1824 | Q9: 1443 | R9: 3504 | S9: 950 | T9: 3343 | U9: 1972 | V9: 3889 | W9: 2723 | X9: 1583 | Y9: 3673 | Z9: 5829 | AA9: 4798 | AB9: 3667 | AC9: 1528 | AD9: 5568 | AE9: 2273 | AF9: 4199 | AG9: 7699 | AH9: 4675 | AI9: 3808 | AJ9: 1549 | AK9: 4015 | AL9: 3245 | AM9: 5525 | AN9: 6054 | AO9: 22807 | AP9: 10910 | AQ9: 87235 | AR9: 18358 | AS9: 1176 | AT9: 1108 | AU9: 10971 | AV9: 1854 | AW9: 8679 | AX9: 973 | AY9: 1944 | AZ9: 5776 | BA9: 16140 | BB9: 47356 | BC9: 2074 | BD9: 14669 | BE9: 4754 | BF9: 3894 | BG9: 2987 | BH9: 28210 | BI9: 6775 | BJ9: 88731 | BK9: 55672 | BL9: 14159 | BM9: 19588 | BN9: 16833 | BO9: 1794 | BP9: 6446 | BQ9: 1474 | BR9: =SUM(B9:BQ9) -> 639009
A10: Previdência oficial /FGTS | B10: 5820 | C10: 3207 | D10: 385 | E10: 1053 | F10: 4097 | G10: 1223 | H10: 647 | I10: 8291 | J10: 2655 | K10: 8085 | L10: 2516 | M10: 435 | N10: 2271 | O10: 3666 | P10: 1802 | Q10: 1384 | R10: 3122 | S10: 910 | T10: 2000 | U10: 1952 | V10: 3494 | W10: 2411 | X10: 1546 | Y10: 3417 | Z10: 5648 | AA10: 4653 | AB10: 3355 | AC10: 1443 | AD10: 5407 | AE10: 2206 | AF10: 4021 | AG10: 7342 | AH10: 4427 | AI10: 3642 | AJ10: 1454 | AK10: 3899 | AL10: 3124 | AM10: 4041 | AN10: 5385 | AO10: 22210 | AP10: 10857 | AQ10: 86104 | AR10: 17574 | AS10: 1128 | AT10: 1085 | AU10: 9486 | AV10: 1807 | AW10: 8628 | AX10: 943 | AY10: 1873 | AZ10: 4576 | BA10: 15121 | BB10: 41014 | BC10: 2015 | BD10: 13441 | BE10: 4573 | BF10: 3792 | BG10: 2904 | BH10: 27696 | BI10: 6725 | BJ10: 86596 | BK10: 55338 | BL10: 14077 | BM10: 19567 | BN10: 16723 | BO10: 1741 | BP10: 6349 | BQ10: 1474 | BR10: =SUM(B10:BQ10) -> 611853
A11: Previdência privada | B11: 0 | C11: 0 | D11: 0 | E11: 10 | F11: 1011 | G11: 49 | H11: 38 | I11: 253 | J11: 57 | K11: 320 | L11: 96 | M11: 45 | N11: 54 | O11: 42 | P11: 22 | Q11: 59 | R11: 382 | S11: 40 | T11: 1343 | U11: 20 | V11: 395 | W11: 312 | X11: 37 | Y11: 256 | Z11: 181 | AA11: 145 | AB11: 312 | AC11: 85 | AD11: 161 | AE11: 67 | AF11: 178 | AG11: 357 | AH11: 248 | AI11: 166 | AJ11: 95 | AK11: 116 | AL11: 121 | AM11: 1484 | AN11: 669 | AO11: 597 | AP11: 53 | AQ11: 1131 | AR11: 784 | AS11: 48 | AT11: 23 | AU11: 1485 | AV11: 47 | AW11: 51 | AX11: 30 | AY11: 71 | AZ11: 1200 | BA11: 1019 | BB11: 6342 | BC11: 59 | BD11: 1228 | BE11: 181 | BF11: 102 | BG11: 83 | BH11: 514 | BI11: 50 | BJ11: 2135 | BK11: 334 | BL11: 82 | BM11: 21 | BN11: 110 | BO11: 53 | BP11: 97 | BQ11: 0 | BR11: =SUM(B11:BQ11) -> 27156
A12: Contribuições sociais imputadas | B12: 0 | C12: 0 | D12: 0 | E12: 0 | F12: 0 | G12: 0 | H12: 0 | I12: 0 | J12: 0 | K12: 0 | L12: 0 | M12: 0 | N12: 0 | O12: 0 | P12: 0 | Q12: 0 | R12: 0 | S12: 0 | T12: 0 | U12: 0 | V12: 0 | W12: 0 | X12: 0 | Y12: 0 | Z12: 0 | AA12: 0 | AB12: 0 | AC12: 0 | AD12: 0 | AE12: 0 | AF12: 0 | AG12: 0 | AH12: 0 | AI12: 0 | AJ12: 0 | AK12: 0 | AL12: 0 | AM12: 0 | AN12: 0 | AO12: 0 | AP12: 0 | AQ12: 0 | AR12: 0 | AS12: 0 | AT12: 0 | AU12: 0 | AV12: 0 | AW12: 0 | AX12: 0 | AY12: 0 | AZ12: 0 | BA12: 0 | BB12: 0 | BC12: 0 | BD12: 0 | BE12: 0 | BF12: 0 | BG12: 0 | BH12: 0 | BI12: 0 | BJ12: 86147 | BK12: 7197 | BL12: 0 | BM12: 7281 | BN12: 0 | BO12: 0 | BP12: 0 | BQ12: 0 | BR12: =SUM(B12:BQ12) -> 100625
A13: Excedente operacional bruto e rendimento misto bruto | B13: 387668 | C13: 104422 | D13: 36464 | E13: 6459 | F13: 208581 | G13: 159899 | H13: 10623 | I13: 16083 | J13: 8407 | K13: 34467 | L13: 13705 | M13: 983 | N13: 6140 | O13: 9028 | P13: 4952 | Q13: 10843 | R13: 12579 | S13: 2534 | T13: 76087 | U13: 12070 | V13: 44152 | W13: 6759 | X13: 3494 | Y13: 28971 | Z13: 9935 | AA13: 17937 | AB13: 79135 | AC13: 20949 | AD13: 23055 | AE13: 7925 | AF13: 9878 | AG13: 22082 | AH13: 3503 | AI13: 8612 | AJ13: 249 | AK13: 23406 | AL13: 17962 | AM13: 133278 | AN13: 37659 | AO13: 141157 | AP13: 61806 | AQ13: 416875 | AR13: 83255 | AS13: 7668 | AT13: -4181 | AU13: 52461 | AV13: 5073 | AW13: 61681 | AX13: 1631 | AY13: 4481 | AZ13: 52994 | BA13: 75511 | BB13: 239754 | BC13: 689238 | BD13: 111759 | BE13: 25863 | BF13: 30311 | BG13: 34254 | BH13: 63863 | BI13: 2789 | BJ13: 115808 | BK13: 17197 | BL13: 10805 | BM13: 8864 | BN13: 96532 | BO13: 9097 | BP13: 40908 | BQ13: 0 | BR13: =SUM(B13:BQ13) -> 4078389
A14: Rendimento misto bruto | B14: 184642 | C14: 69026 | D14: 16923 | E14: 269 | F14: 0 | G14: 0 | H14: 0 | I14: 406 | J14: 0 | K14: 4027 | L14: 27 | M14: 0 | N14: 1035 | O14: 4774 | P14: 733 | Q14: 1708 | R14: 309 | S14: 522 | T14: 0 | U14: 0 | V14: 0 | W14: 0 | X14: 613 | Y14: 0 | Z14: 389 | AA14: 856 | AB14: 0 | AC14: -19 | AD14: 2556 | AE14: 0 | AF14: 0 | AG14: 0 | AH14: 0 | AI14: 32 | AJ14: 1 | AK14: 1416 | AL14: 4388 | AM14: 0 | AN14: 1511 | AO14: 66152 | AP14: 24402 | AQ14: 58221 | AR14: 24784 | AS14: 271 | AT14: 0 | AU14: 1972 | AV14: 1448 | AW14: 39681 | AX14: 22 | AY14: 1137 | AZ14: 388 | BA14: 13885 | BB14: 3201 | BC14: 3741 | BD14: 37402 | BE14: 10984 | BF14: 6539 | BG14: 588 | BH14: 6740 | BI14: 924 | BJ14: 0 | BK14: 0 | BL14: 8883 | BM14: 0 | BN14: 58199 | BO14: 5814 | BP14: 29999 | BQ14: 0 | BR14: =SUM(B14:BQ14) -> 701521
A15: Excedente operacional bruto (EOB) | B15: 203026 | C15: 35396 | D15: 19541 | E15: 6190 | F15: 208581 | G15: 159899 | H15: 10623 | I15: 15677 | J15: 8407 | K15: 30440 | L15: 13678 | M15: 983 | N15: 5105 | O15: 4254 | P15: 4219 | Q15: 9135 | R15: 12270 | S15: 2012 | T15: 76087 | U15: 12070 | V15: 44152 | W15: 6759 | X15: 2881 | Y15: 28971 | Z15: 9546 | AA15: 17081 | AB15: 79135 | AC15: 20968 | AD15: 20499 | AE15: 7925 | AF15: 9878 | AG15: 22082 | AH15: 3503 | AI15: 8580 | AJ15: 248 | AK15: 21990 | AL15: 13574 | AM15: 133278 | AN15: 36148 | AO15: 75005 | AP15: 37404 | AQ15: 358654 | AR15: 58471 | AS15: 7397 | AT15: -4181 | AU15: 50489 | AV15: 3625 | AW15: 22000 | AX15: 1609 | AY15: 3344 | AZ15: 52606 | BA15: 61626 | BB15: 236553 | BC15: 685497 | BD15: 74357 | BE15: 14879 | BF15: 23772 | BG15: 33666 | BH15: 57123 | BI15: 1865 | BJ15: 115808 | BK15: 17197 | BL15: 1922 | BM15: 8864 | BN15: 38333 | BO15: 3283 | BP15: 10909 | BQ15: 0 | BR15: =SUM(B15:BQ15) -> 3376868
A16: Outros impostos sobre a produção | B16: 3349 | C16: 909 | D16: 219 | E16: 237 | F16: 2064 | G16: 1561 | H16: 235 | I16: 3687 | J16: 1186 | K16: 4679 | L16: 1100 | M16: 135 | N16: 635 | O16: 661 | P16: 463 | Q16: 555 | R16: 1123 | S16: 247 | T16: 2008 | U16: 838 | V16: 2120 | W16: 989 | X16: 540 | Y16: 804 | Z16: 1524 | AA16: 1168 | AB16: 1916 | AC16: 781 | AD16: 1497 | AE16: 1281 | AF16: 1075 | AG16: 1953 | AH16: 1655 | AI16: 1233 | AJ16: 423 | AK16: 879 | AL16: 550 | AM16: 3794 | AN16: 1014 | AO16: 3891 | AP16: 1593 | AQ16: 13816 | AR16: 4071 | AS16: 476 | AT16: 579 | AU16: 1858 | AV16: 354 | AW16: 1559 | AX16: 181 | AY16: 877 | AZ16: 2703 | BA16: 2779 | BB16: 6141 | BC16: 581 | BD16: 3206 | BE16: 857 | BF16: 834 | BG16: 680 | BH16: 4284 | BI16: 1004 | BJ16: 174 | BK16: 0 | BL16: 2412 | BM16: 0 | BN16: 3523 | BO16: 280 | BP16: 1118 | BQ16: 0 | BR16: =SUM(B16:BQ16) -> 110918
A17: Outros subsídios à produção | B17: -7858 | C17: -46 | D17: -34 | E17: -17 | F17: 0 | G17: -7 | H17: 0 | I17: -23 | J17: -31 | K17: -28 | L17: -9 | M17: 0 | N17: -6 | O17: 0 | P17: 0 | Q17: -9 | R17: -22 | S17: 0 | T17: -41 | U17: -26 | V17: -8 | W17: 0 | X17: 0 | Y17: -6 | Z17: -33 | AA17: -27 | AB17: -14 | AC17: -8 | AD17: -18 | AE17: 0 | AF17: -20 | AG17: -53 | AH17: -59 | AI17: -49 | AJ17: -14 | AK17: -8 | AL17: 0 | AM17: -32 | AN17: -8 | AO17: -99 | AP17: -8 | AQ17: -168 | AR17: -444 | AS17: 0 | AT17: -7 | AU17: -13 | AV17: 0 | AW17: 0 | AX17: 0 | AY17: 0 | AZ17: -17 | BA17: 0 | BB17: 0 | BC17: 0 | BD17: 0 | BE17: -594 | BF17: 0 | BG17: -42 | BH17: -13 | BI17: 0 | BJ17: 0 | BK17: 0 | BL17: 0 | BM17: 0 | BN17: -37 | BO17: 0 | BP17: 0 | BQ17: 0 | BR17: =SUM(B17:BQ17) -> -9956
A18: Valor da produção | B18: 769160 | C18: 272241 | D18: 54743 | E18: 30081 | F18: 406701 | G18: 279099 | H18: 30712 | I18: 495404 | J18: 94655 | K18: 513838 | L18: 110108 | M18: 18653 | N18: 82836 | O18: 80645 | P18: 50739 | Q18: 61516 | R18: 156926 | S18: 22332 | T18: 678319 | U18: 105728 | V18: 353156 | W18: 138097 | X18: 67872 | Y18: 99278 | Z18: 197694 | AA18: 143010 | AB18: 305615 | AC18: 121205 | AD18: 189661 | AE18: 146376 | AF18: 137668 | AG18: 242983 | AH18: 241683 | AI18: 145523 | AJ18: 50525 | AK18: 113057 | AL18: 107939 | AM18: 455696 | AN18: 107088 | AO18: 704341 | AP18: 225817 | AQ18: 1442385 | AR18: 506364 | AS18: 34706 | AT18: 35749 | AU18: 188012 | AV18: 31722 | AW18: 287344 | AX18: 17626 | AY18: 46662 | AZ18: 182343 | BA18: 267495 | BB18: 717847 | BC18: 758313 | BD18: 285030 | BE18: 85091 | BF18: 146292 | BG18: 75203 | BH18: 319061 | BI18: 46889 | BJ18: 993216 | BK18: 404343 | BL18: 150446 | BM18: 279166 | BN18: 382369 | BO18: 42806 | BP18: 185302 | BQ18: 61371 | BR18: =SUM(B18:BQ18) -> 16581873
A19: Fator trabalho (ocupações) | B19: 6934294 | C19: 5393173 | D19: 815655 | E19: 110127 | F19: 55195 | G19: 42815 | H19: 35085 | I19: 860656 | J19: 139807 | K19: 1272409 | L19: 188767 | M19: 17515 | N19: 638518 | O19: 1655089 | P19: 455637 | Q19: 389391 | R19: 216547 | S19: 168568 | T19: 22483 | U19: 108126 | V19: 112336 | W19: 97429 | X19: 138125 | Y19: 113456 | Z19: 444332 | AA19: 609593 | AB19: 131519 | AC19: 108045 | AD19: 702971 | AE19: 122788 | AF19: 228003 | AG19: 436572 | AH19: 155333 | AI19: 304453 | AJ19: 87198 | AK19: 773017 | AL19: 673031 | AM19: 174830 | AN19: 606919 | AO19: 8267084 | AP19: 2976940 | AQ19: 15848633 | AR19: 4123552 | AS19: 48865 | AT19: 51770 | AU19: 937458 | AV19: 402267 | AW19: 4980988 | AX19: 126997 | AY19: 154532 | AZ19: 322694 | BA19: 962675 | BB19: 1519655 | BC19: 518258 | BD19: 2206221 | BE19: 777044 | BF19: 850029 | BG19: 320139 | BH19: 4539907 | BI19: 785372 | BJ19: 4692057 | BK19: 4226629 | BL19: 2757268 | BM19: 2306888 | BN19: 3908377 | BO19: 937222 | BP19: 4342454 | BQ19: 5633396 | BR19: =SUM(B19:BQ19) -> 105065178
A22: Fonte: IBGE, Diretoria de Pesquisas, Coordenação de Contas Nacionais.
A23: (1) Exportação de bens e serviços acrescida de ajuste CIF/FOB.
BJ25: Excedente operacional bruto (EOB)
BJ26: o valor do consumo de capital fixo para a administração pública pode ser identificado na conta de geração da renda, equivalente ao excedente operacional bruto.
BJ27: excedente operacional bruto é igual ao consumo de capital fixo, sendo o excedente operacional líquido igual a zero.
BJ28: o consumo de capital fixo como o decréscimo, entre o início e o fim do período contábil, no valor dos ativos fixos detidos por uma unidade institucional, como resultado de sua deterioração física
BJ29: Fonte: nota 12
BJ31: A produção não-mercantil da administração pública é, por convenção, medida pelos seus custos por não ser objeto de transação no mercado. Estes custos envolvem as remunerações pagas aos assalariados, o consumo corrente de bens e serviços, o consumo de capital fixo e o pagamento de impostos incidentes sobre a sua produção.
BJ32: Fonte: nota 11

Sheet demanda (2)
A1: Tabela 2 - Usos de bens e serviços - 2021 | P1: critérios módulo central
P2: Base de débitos = receita bruta - exportações => proxy CN = Demanda Total - Export
A3: Código do produto | B3: Descrição do produto | C3: Demanda final (valores correntes em 1 000 000 R$) | P3: Segregação da base de débitos ECF => consumo intermediário adm pública / (Demanda Total - Exports)
C4: Exportação de bens e serviços (1) | D4: Consumo do governo | E4: Consumo das ISFLSF | F4: Consumo das famílias | G4: Formação bruta de capital fixo | H4: Variação de estoque | I4: Demanda final | J4: Demanda total | K4: CONSUMO INTERMEDIÁRIO TOTAL | L4: CONSUMO INTERMEDIÁRIO ADM PÚBLICA | M4: Demanda Total - Export | N4: % Compras ADM PÚBLICA | O4: % CONSUMO FINAL (proxy débitos CBS) | P4: AJUSTE VARIAÇÃO DE ESTOQUES
A6: 01911 | B6: Arroz, trigo e outros cereais | C6: 1979 | D6: 70 | E6: 0 | F6: 1409 | G6: 0 | H6: 12245 | I6: =SUM(C6:H6) -> 15703 | J6: =I6+CI!BT6 -> 50589 | K6: =J6-I6 -> 34886 | L6: =CI!BS6 -> 216 | M6: =J6-C6 -> 48610 | N6: =L6/M6 -> 0.0044435301 | O6: =(M6-K6)/M6 -> 0.28232874
A7: 01912 | B7: Milho em grão | C7: 22656 | D7: 53 | E7: 0 | F7: 9779 | G7: 0 | H7: 30117 | I7: =SUM(C7:H7) -> 62605 | J7: =I7+CI!BT7 -> 125926 | K7: =J7-I7 -> 63321 | L7: =CI!BS7 -> 288 | M7: =J7-C7 -> 103270 | N7: =L7/M7 -> 0.002788806 | O7: =(M7-K7)/M7 -> 0.38684032
A8: 01913 | B8: Algodão herbáceo, outras fibras da lav. temporária | C8: 18609 | D8: 0 | E8: 0 | F8: 11 | G8: 0 | H8: -830 | I8: =SUM(C8:H8) -> 17790 | J8: =I8+CI!BT8 -> 34790 | K8: =J8-I8 -> 17000 | L8: =CI!BS8 -> 0 | M8: =J8-C8 -> 16181 | N8: =L8/M8 -> 0 | O8: =(M8-K8)/M8 -> -0.050614919
A9: 01914 | B9: Cana-de-açúcar | C9: 3 | D9: 0 | E9: 0 | F9: 2318 | G9: 0 | H9: 0 | I9: =SUM(C9:H9) -> 2321 | J9: =I9+CI!BT9 -> 82968 | K9: =J9-I9 -> 80647 | L9: =CI!BS9 -> 0 | M9: =J9-C9 -> 82965 | N9: =L9/M9 -> 0 | O9: =(M9-K9)/M9 -> 0.027939493
A10: 01915 | B10: Soja em grão | C10: 213948 | D10: 0 | E10: 0 | F10: 309 | G10: 0 | H10: 9032 | I10: =SUM(C10:H10) -> 223289 | J10: =I10+CI!BT10 -> 345837 | K10: =J10-I10 -> 122548 | L10: =CI!BS10 -> 0 | M10: =J10-C10 -> 131889 | N10: =L10/M10 -> 0 | O10: =(M10-K10)/M10 -> 0.070824709
A11: 01916 | B11: Outros produtos e serviços da lavoura temporária | C11: 3981 | D11: 53 | E11: 0 | F11: 100772 | G11: 0 | H11: -883 | I11: =SUM(C11:H11) -> 103923 | J11: =I11+CI!BT11 -> 142742 | K11: =J11-I11 -> 38819 | L11: =CI!BS11 -> 2189 | M11: =J11-C11 -> 138761 | N11: =L11/M11 -> 0.015775326 | O11: =(M11-K11)/M11 -> 0.7202456
A12: 01917 | B12: Laranja | C12: 5 | D12: 0 | E12: 0 | F12: 4157 | G12: 356 | H12: 0 | I12: =SUM(C12:H12) -> 4518 | J12: =I12+CI!BT12 -> 20560 | K12: =J12-I12 -> 16042 | L12: =CI!BS12 -> 38 | M12: =J12-C12 -> 20555 | N12: =L12/M12 -> 0.0018486986 | O12: =(M12-K12)/M12 -> 0.21955729
A13: 01918 | B13: Café em grão | C13: 31487 | D13: 0 | E13: 0 | F13: 936 | G13: 189 | H13: -1687 | I13: =SUM(C13:H13) -> 30925 | J13: =I13+CI!BT13 -> 40217 | K13: =J13-I13 -> 9292 | L13: =CI!BS13 -> 6 | M13: =J13-C13 -> 8730 | N13: =L13/M13 -> 0.00068728522 | O13: =(M13-K13)/M13 -> -0.064375716
A14: 01919 | B14: Outros produtos da lavoura permanente | C14: 4124 | D14: 8 | E14: 0 | F14: 48240 | G14: 255 | H14: 0 | I14: =SUM(C14:H14) -> 52627 | J14: =I14+CI!BT14 -> 59464 | K14: =J14-I14 -> 6837 | L14: =CI!BS14 -> 514 | M14: =J14-C14 -> 55340 | N14: =L14/M14 -> 0.0092880376 | O14: =(M14-K14)/M14 -> 0.87645464
A15: 01921 | B15: Bovinos e outros animais vivos, prods. animal, caça e serv. | C15: 1972 | D15: 0 | E15: 0 | F15: 1358 | G15: 27970 | H15: -1012 | I15: =SUM(C15:H15) -> 30288 | J15: =I15+CI!BT15 -> 141489 | K15: =J15-I15 -> 111201 | L15: =CI!BS15 -> 311 | M15: =J15-C15 -> 139517 | N15: =L15/M15 -> 0.002229119 | O15: =(M15-K15)/M15 -> 0.20295735
A16: 01922 | B16: Leite de vaca e de outros animais | C16: 0 | D16: 0 | E16: 0 | F16: 19981 | G16: 0 | H16: 0 | I16: =SUM(C16:H16) -> 19981 | J16: =I16+CI!BT16 -> 60234 | K16: =J16-I16 -> 40253 | L16: =CI!BS16 -> 0 | M16: =J16-C16 -> 60234 | N16: =L16/M16 -> 0 | O16: =(M16-K16)/M16 -> 0.33172295
A17: 01923 | B17: Suínos | C17: 23 | D17: 0 | E17: 0 | F17: 449 | G17: 82 | H17: 0 | I17: =SUM(C17:H17) -> 554 | J17: =I17+CI!BT17 -> 18220 | K17: =J17-I17 -> 17666 | L17: =CI!BS17 -> 0 | M17: =J17-C17 -> 18197 | N17: =L17/M17 -> 0 | O17: =(M17-K17)/M17 -> 0.029180634
... A94: 36801 | B94: Água, esgoto, reciclagem e gestão de resíduos | C94: 3 | D94: 0 | E94: 0 | F94: 48830 | G94: 0 | H94: 54 | I94: =SUM(C94:H94) -> 48887 | J94: =I94+CI!BT94 -> 120930 | K94: =J94-I94 -> 72043 | L94: =CI!BS94 -> 17580 | M94: =J94-C94 -> 120927 | N94: =L94/M94 -> 0.14537696 | O94: =(M94-K94)/M94 -> 0.40424388
A95: 41801 | B95: Edificações | C95: 326 | D95: 0 | E95: 0 | F95: 0 | G95: 372106 | H95: 0 | I95: =SUM(C95:H95) -> 372432 | J95: =I95+CI!BT95 -> 423909 | K95: =J95-I95 -> 51477 | L95: =CI!BS95+(G95*'tab16'!$W$60) -> 42918.585 | M95: =J95-C95 -> 423583 | N95: =L95/M95 -> 0.10132273 | O95: =(M95-K95)/M95 -> 0.87847246
A96: 41802 | B96: Obras de infra-estrutura | C96: 0 | D96: 0 | E96: 0 | F96: 0 | G96: 155452 | H96: 0 | I96: =SUM(C96:H96) -> 155452 | J96: =I96+CI!BT96 -> 188300 | K96: =J96-I96 -> 32848 | L96: =CI!BS96+(G96*'tab16'!$W$60) -> 27316.678 | M96: =J96-C96 -> 188300 | N96: =L96/M96 -> 0.14506999 | O96: =(M96-K96)/M96 -> 0.82555497
A97: 41803 | B97: Serviços especializados para construção | C97: 3568 | D97: 0 | E97: 0 | F97: 0 | G97: 140581 | H97: 0 | I97: =SUM(C97:H97) -> 144149 | J97: =I97+CI!BT97 -> 190618 | K97: =J97-I97 -> 46469 | L97: =CI!BS97+(G97*'tab16'!$W$60) -> 18667.334 | M97: =J97-C97 -> 187050 | N97: =L97/M97 -> 0.099798634 | O97: =(M97-K97)/M97 -> 0.7515691 | P97: =K97/M97 -> 0.2484309
A98: 45001 | B98: Comércio e reparação de veículos | C98: 475 | D98: 0 | E98: 0 | F98: 69820 | G98: 0 | H98: 0 | I98: =SUM(C98:H98) -> 70295 | J98: =I98+CI!BT98 -> 104925 | K98: =J98-I98 -> 34630 | L98: =CI!BS98 -> 3847 | M98: =J98-C98 -> 104450 | N98: =L98/M98 -> 0.03683102 | O98: =(M98-K98)/M98 -> 0.66845381
A99: 46801 | B99: Comércio por atacado e a varejo, exceto veículos automotores | C99: 4516 | D99: 0 | E99: 0 | F99: 0 | G99: 0 | H99: 0 | I99: =SUM(C99:H99) -> 4516 | J99: =I99+CI!BT99 -> 64373 | K99: =J99-I99 -> 59857 | L99: =CI!BS99 -> 0 | M99: =J99-C99 -> 59857 | N99: =L99/M99 -> 0 | O99: =(M99-K99)/M99 -> 0
A100: 49001 | B100: Transporte terrestre de carga | C100: 544 | D100: 0 | E100: 0 | F100: 2500 | G100: 0 | H100: 0 | I100: =SUM(C100:H100) -> 3044 | J100: =I100+CI!BT100 -> 304566 | K100: =J100-I100 -> 301522 | L100: =CI!BS100 -> 1461 | M100: =J100-C100 -> 304022 | N100: =L100/M100 -> 0.0048055733 | O100: =(M100-K100)/M100 -> 0.0082230891
A101: 49002 | B101: Transporte terrestre de passageiros | C101: 261 | D101: 0 | E101: 0 | F101: 78609 | G101: 0 | H101: 0 | I101: =SUM(C101:H101) -> 78870 | J101: =I101+CI!BT101 -> 98861 | K101: =J101-I101 -> 19991 | L101: =CI!BS101 -> 4852 | M101: =J101-C101 -> 98600 | N101: =L101/M101 -> 0.049208925 | O101: =(M101-K101)/M101 -> 0.79725152
A102: 50001 | B102: Transporte aquaviário | C102: 11493 | D102: 0 | E102: 0 | F102: 1322 | G102: 0 | H102: 0 | I102: =SUM(C102:H102) -> 12815 | J102: =I102+CI!BT102 -> 47169 | K102: =J102-I102 -> 34354 | L102: =CI!BS102 -> 0 | M102: =J102-C102 -> 35676 | N102: =L102/M102 -> 0 | O102: =(M102-K102)/M102 -> 0.037055724
A103: 51001 | B103: Transporte aéreo | C103: 9120 | D103: 0 | E103: 0 | F103: 6167 | G103: 0 | H103: 0 | I103: =SUM(C103:H103) -> 15287 | J103: =I103+CI!BT103 -> 41533 | K103: =J103-I103 -> 26246 | L103: =CI!BS103 -> 1809 | M103: =J103-C103 -> 32413 | N103: =L103/M103 -> 0.05581094 | O103: =(M103-K103)/M103 -> 0.19026317
A104: 52801 | B104: Armazenamento e serviços auxiliares aos transportes | C104: 17529 | D104: 0 | E104: 0 | F104: 37287 | G104: 0 | H104: 0 | I104: =SUM(C104:H104) -> 54816 | J104: =I104+CI!BT104 -> 177494 | K104: =J104-I104 -> 122678 | L104: =CI!BS104 -> 2345 | M104: =J104-C104 -> 159965 | N104: =L104/M104 -> 0.014659457 | O104: =(M104-K104)/M104 -> 0.23309474
A105: 52802 | B105: Correio e outros serviços de entrega | C105: 2072 | D105: 0 | E105: 0 | F105: 3121 | G105: 0 | H105: 0 | I105: =SUM(C105:H105) -> 5193 | J105: =I105+CI!BT105 -> 33760 | K105: =J105-I105 -> 28567 | L105: =CI!BS105 -> 3108 | M105: =J105-C105 -> 31688 | N105: =L105/M105 -> 0.098081293 | O105: =(M105-K105)/M105 -> 0.098491543
A106: 55001 | B106: Serviços de alojamento em hotéis e similares | C106: 5097 | D106: 0 | E106: 0 | F106: 6863 | G106: 0 | H106: 0 | I106: =SUM(C106:H106) -> 11960 | J106: =I106+CI!BT106 -> 44768 | K106: =J106-I106 -> 32808 | L106: =CI!BS106 -> 3439 | M106: =J106-C106 -> 39671 | N106: =L106/M106 -> 0.086688009 | O106: =(M106-K106)/M106 -> 0.17299791
A107: 56001 | B107: Serviços de alimentação | C107: 3208 | D107: 0 | E107: 0 | F107: 269233 | G107: 0 | H107: 0 | I107: =SUM(C107:H107) -> 272441 | J107: =I107+CI!BT107 -> 327365 | K107: =J107-I107 -> 54924 | L107: =CI!BS107 -> 21680 | M107: =J107-C107 -> 324157 | N107: =L107/M107 -> 0.066881172 | O107: =(M107-K107)/M107 -> 0.83056358
A108: 58001 | B108: Livros, jornais e revistas | C108: 1062 | D108: 0 | E108: 0 | F108: 13731 | G108: 0 | H108: -855 | I108: =SUM(C108:H108) -> 13938 | J108: =I108+CI!BT108 -> 32173 | K108: =J108-I108 -> 18235 | L108: =CI!BS108 -> 6496 | M108: =J108-C108 -> 31111 | N108: =L108/M108 -> 0.20880075 | O108: =(M108-K108)/M108 -> 0.41387291
A109: 59801 | B109: Serviços cinematográficos, música, rádio e televisão | C109: 2041 | D109: 0 | E109: 0 | F109: 1256 | G109: 0 | H109: 0 | I109: =SUM(C109:H109) -> 3297 | J109: =I109+CI!BT109 -> 48729 | K109: =J109-I109 -> 45432 | L109: =CI!BS109 -> 0 | M109: =J109-C109 -> 46688 | N109: =L109/M109 -> 0 | O109: =(M109-K109)/M109 -> 0.026901988
... A127: 86911 | B127: Saúde pública | C127: 0 | D127: 273993 | E127: 0 | F127: 0 | G127: 0 | H127: 0 | I127: =SUM(C127:H127) -> 273993 | J127: =I127+CI!BT127 -> 273993 | K127: =J127-I127 -> 0 | L127: =CI!BS127 -> 0 | M127: =J127-C127 -> 273993 | N127: =L127/M127 -> 0 | O127: =(M127-K127)/M127 -> 1
A128: 86921 | B128: Saúde privada | C128: 572 | D128: 61105 | E128: 10067 | F128: 274870 | G128: 0 | H128: 0 | I128: =SUM(C128:H128) -> 346614 | J128: =I128+CI!BT128 -> 395274 | K128: =J128-I128 -> 48660 | L128: =CI!BS128+D128 -> 61192 | M128: =J128-C128 -> 394702 | N128: =L128/M128 -> 0.15503342 | O128: =(M128-K128)/M128 -> 0.87671712
A129: 90801 | B129: Serviços de artes, cultura, esporte e recreação | C129: 2729 | D129: 0 | E129: 13015 | F129: 35620 | G129: 0 | H129: 0 | I129: =SUM(C129:H129) -> 51364 | J129: =I129+CI!BT129 -> 57203 | K129: =J129-I129 -> 5839 | L129: =CI!BS129 -> 1100 | M129: =J129-C129 -> 54474 | N129: =L129/M129 -> 0.02019312 | O129: =(M129-K129)/M129 -> 0.89281125
A130: 94801 | B130: Organizações patronais, sindicais e outros serviços associativos | C130: 0 | D130: 0 | E130: 52913 | F130: 35709 | G130: 0 | H130: 0 | I130: =SUM(C130:H130) -> 88622 | J130: =I130+CI!BT130 -> 97965 | K130: =J130-I130 -> 9343 | L130: =CI!BS130 -> 0 | M130: =J130-C130 -> 97965 | N130: =L130/M130 -> 0 | O130: =(M130-K130)/M130 -> 0.9046292
A131: 94802 | B131: Manutenção de computadores, telefones e objetos domésticos | C131: 0 | D131: 0 | E131: 0 | F131: 11880 | G131: 0 | H131: 0 | I131: =SUM(C131:H131) -> 11880 | J131: =I131+CI!BT131 -> 35422 | K131: =J131-I131 -> 23542 | L131: =CI!BS131 -> 1640 | M131: =J131-C131 -> 35422 | N131: =L131/M131 -> 0.04629891 | O131: =(M131-K131)/M131 -> 0.33538479
A132: 94803 | B132: Serviços pessoais | C132: 0 | D132: 0 | E132: 0 | F132: 56374 | G132: 0 | H132: 0 | I132: =SUM(C132:H132) -> 56374 | J132: =I132+CI!BT132 -> 62144 | K132: =J132-I132 -> 5770 | L132: =CI!BS132 -> 1757 | M132: =J132-C132 -> 62144 | N132: =L132/M132 -> 0.028273043 | O132: =(M132-K132)/M132 -> 0.90715113
A133: 97001 | B133: Serviços domésticos | C133: 0 | D133: 0 | E133: 0 | F133: 61371 | G133: 0 | H133: 0 | I133: =SUM(C133:H133) -> 61371 | J133: =I133+CI!BT133 -> 61371 | K133: =J133-I133 -> 0 | L133: =CI!BS133 -> 0 | M133: =J133-C133 -> 61371 | N133: =L133/M133 -> 0 | O133: =(M133-K133)/M133 -> 1
K134: =J134-I134 -> 0 | L134: =CI!BS134 -> 0 | M134: =J134-C134 -> 0
...

Sheet tab16
A1: Tabela 16 - Principais agregados macroeconômicos das Contas Nacionais, por setor institucional - 2000-2021
A4: Principais agregados macroeconômicos das Contas Nacionais | B4: Valor (1 000 000 R$)
B5: 2000 | C5: 2001 | D5: 2002 | E5: 2003 | F5: 2004 | G5: 2005 | H5: 2006 | I5: 2007 | J5: 2008 | K5: 2009 | L5: 2010 | M5: 2011 | N5: 2012 | O5: 2013 | P5: 2014 | Q5: 2015 | R5: 2016 | S5: 2017 | T5: 2018 | U5: 2019 | V5: 2020 | W5: 2021
A6: Produto Interno Bruto (1) | B6: 1199092.1 | C6: 1315755.5 | D6: 1488787.3 | E6: 1717950.4 | F6: 1957751.2 | G6: 2170584.5 | H6: 2409449.9 | I6: 2720263 | J6: 3109803.1 | K6: 3333039.3 | L6: 3885847 | M6: 4376382 | N6: 4814760 | O6: 5331619 | P6: 5778953 | Q6: 5995787 | R6: 6269328 | S6: 6585479 | T6: 7004141 | U6: 7389131 | V6: 7609597 | W6: 9012142
A7: Valor adicionado bruto | B7: 1031326.4 | C7: 1120421.9 | D7: 1270214.6 | E7: 1470717.3 | F7: 1661982.1 | G7: 1842818.4 | H7: 2049289.9 | I7: 2319528.3 | J7: 2626477.7 | K7: 2849762.8 | L7: 3302840 | M7: 3720461 | N7: 4094259 | O7: 4553760 | P7: 4972734 | Q7: 5155601 | R7: 5419822 | S7: 5671926 | T7: 6011150 | U7: 6356684 | V7: 6594937 | W7: 7713999
A8: Empresas não financeiras | B8: 494237.92 | C8: 541906.49 | D8: 610666.38 | E8: 744166.88 | F8: 883952.57 | G8: 973458.23 | H8: 1096789.5 | I8: 1242342.3 | J8: 1435594.2 | K8: 1551806.9 | L8: 1836976 | M8: 2102992 | N8: 2301347 | O8: 2530103 | P8: 2755684 | Q8: 2777949 | R8: 2853045 | S8: 2992762 | T8: 3218885 | U8: 3400640 | V8: 3581664 | W8: 4512117
A9: Empresas financeiras | B9: 69560.564 | C9: 78939.558 | D9: 99597.935 | E9: 108335.91 | F9: 107035.83 | G9: 130099.72 | H9: 145943.47 | I9: 168569.87 | J9: 169327.14 | K9: 186083.49 | L9: 222761 | M9: 237620 | N9: 258358 | O9: 270196 | P9: 316339 | Q9: 362977 | R9: 423501 | S9: 427199 | T9: 419897 | U9: 457437 | V9: 451173 | W9: 443669
A10: Governo geral | B10: 161836.84 | C10: 184195.99 | D10: 209388.68 | E10: 235655.84 | F10: 259678.62 | G10: 295129.91 | H10: 333619.79 | I10: 377110.17 | J10: 434222.69 | K10: 487178.81 | L10: 537845 | M10: 598059 | N10: 652101 | O10: 746187 | P10: 816808 | Q10: 885587 | R10: 945121 | S10: 1000975 | T10: 1045385 | U10: 1106091 | V10: 1146900 | W10: 1218956
A11: Famílias | B11: 291381.72 | C11: 300183.55 | D11: 334861.53 | E11: 365331.14 | F11: 392109.77 | G11: 421033.65 | H11: 446448.94 | I11: 504786.83 | J11: 557663.39 | K11: 591455.25 | L11: 669111 | M11: 741634 | N11: 837725 | O11: 957897 | P11: 1032013 | Q11: 1074849 | R11: 1142223 | S11: 1192582 | T11: 1264920 | U11: 1327538 | V11: 1351100 | W11: 1472568
A12: Instituições sem fins de lucro a serviço das famílias | B12: 14309.379 | C12: 15196.295 | D12: 15700.119 | E12: 17227.482 | F12: 19205.322 | G12: 23096.905 | H12: 26488.26 | I12: 26719.169 | J12: 29670.291 | K12: 33238.349 | L12: 36147 | M12: 40156 | N12: 44728 | O12: 49377 | P12: 51890 | Q12: 54239 | R12: 55932 | S12: 58408 | T12: 62063 | U12: 64978 | V12: 64100 | W12: 66689
A13: Remuneração dos empregados | B13: 469949.23 | C13: 520500.94 | D13: 579309.68 | E13: 661552.03 | F13: 750180.11 | G13: 851698.06 | H13: 963283.28 | I13: 1094553.7 | J13: 1261043.7 | K13: 1413173.2 | L13: 1618190 | M13: 1846781 | N13: 2058854 | O13: 2305713 | P13: 2515369 | Q13: 2672020 | R13: 2802436 | S13: 2920537 | T13: 3055773 | U13: 3217680 | V13: 3192343 | W13: 3534648
A14: Empresas não financeiras | B14: 249976.28 | C14: 274694.43 | D14: 304879.19 | E14: 357366.74 | F14: 413063.26 | G14: 466294.34 | H14: 527019.32 | I14: 604014.61 | J14: 703462.59 | K14: 789265.56 | L14: 922732 | M14: 1075904 | N14: 1216947 | O14: 1351583 | P14: 1480692 | Q14: 1559842 | R14: 1614413 | S14: 1665988 | T14: 1746812 | U14: 1839784 | V14: 1798221 | W14: 2055730
A15: Empresas financeiras | B15: 37508.162 | C15: 39904.598 | D15: 41064.784 | E15: 43920.429 | F15: 47528.74 | G15: 53020.995 | H15: 59689.918 | I15: 66598.099 | J15: 73271.892 | K15: 78177.257 | L15: 90121 | M15: 98031 | N15: 110298 | O15: 119530 | P15: 128369 | Q15: 143104 | R15: 156672 | S15: 162621 | T15: 165090 | U15: 179652 | V15: 181149 | W15: 200975
A16: Governo geral | B16: 142192.5 | C16: 162611.25 | D16: 185592.71 | E16: 207752.07 | F16: 228704.24 | G16: 261357.85 | H16: 297899.34 | I16: 339490.46 | J16: 391998.69 | K16: 441006.14 | L16: 487166 | M16: 541126 | N16: 589064 | O16: 675979 | P16: 738605 | Q16: 797857 | R16: 847005 | S16: 897677 | T16: 938493 | U16: 990240 | V16: 1028949 | W16: 1076913
A17: Famílias | B17: 28608.028 | C17: 30382.191 | D17: 34392.831 | E17: 37852.265 | F17: 44380.888 | G17: 50145.892 | H17: 54669.831 | I17: 60780.696 | J17: 65928.421 | K17: 75149.259 | L17: 85299 | M17: 94667 | N17: 101493 | O17: 113286 | P17: 120386 | Q17: 121732 | R17: 133462 | S17: 141075 | T17: 148861 | U17: 149031 | V17: 125701 | W17: 140721
... A54: Instituições sem fins de lucro a serviço das famílias | B54: 133.124 | C54: 131.84 | D54: 115.967 | E54: 214.03 | F54: 669.157 | G54: 482.008 | H54: 425.729 | I54: 262.978 | J54: 213.256 | K54: 99.663 | L54: 18 | M54: 35 | N54: 31 | O54: 74 | P54: 249 | Q54: 224 | R54: 355 | S54: 665 | T54: 203 | U54: 1194 | V54: 4327 | W54: 2142
A56: Fonte: IBGE, Diretoria de Pesquisas, Coordenação de Contas Nacionais.
A57: (1) O Produto Interno Bruto - PIB corresponde ao somatório do valor adicionado pelos setores institucionais acrescido dos impostos, líquidos de subsídios, sobre produto.
A58: (2) Para o total da economia, o saldo das rendas primárias brutas corresponde à renda nacional bruta.
U60: =U46/U43 -> 0.105884 | V60: =V46/V43 -> 0.11084194 | W60: =W46/W43 -> 0.093628118

Sheet demanda 2021-2019
B1: Tabela 2 - Usos de bens e serviços - 2021 | W1: critérios módulo central | AC1: fontes:
W2: Base de débitos = receita bruta - exportações => proxy CN = Demanda Total - Export | AC2: Sistema de Contas Nacionais: Brasil | IBGE
B3: Código do produto | C3: Descrição do produto | D3: Demanda final (valores correntes em 1 000 000 R$) | W3: Segregação da base de débitos ECF => consumo intermediário adm pública / (Demanda Total - Exports)
D4: Exportação de bens e serviços (1) | E4: Consumo do governo | F4: Consumo das ISFLSF | G4: Consumo das famílias | H4: Formação bruta de capital fixo | I4: Variação de estoque | J4: Demanda final | K4: Demanda total | L4: CONSUMO INTERMEDIÁRIO TOTAL | M4: CONSUMO INTERMEDIÁRIO ADM PÚBLICA | N4: Demanda Total - Export | O4: % Compras ADM PÚBLICA 2021 | P4: % Compras ADM PÚBLICA 2020 | Q4: % Compras ADM PÚBLICA 2019 | R4: % Compras ADM PÚBLICA MÉDIA 2021-2019 | S4: % CONSUMO FINAL (proxy débitos CBS) 2021 | T4: % CONSUMO FINAL (proxy débitos CBS) 2020 | U4: % CONSUMO FINAL (proxy débitos CBS) 2019 | V4: % CONSUMO FINAL (proxy débitos CBS) MÉDIA 2021-2019 | W4: Ajuste variação de estoques - OK
A6: 0191 | B6: 01911 | C6: Arroz, trigo e outros cereais | D6: 1979 | E6: 70 | F6: 0 | G6: 1409 | H6: 0 | I6: 12245 | J6: =SUM(D6:I6) -> 15703 | K6: =J6+CI!BT6 -> 50589 | L6: =K6-J6 -> 34886 | M6: =CI!BS6 -> 216 | N6: =K6-D6 -> 48610 | O6: =M6/N6 -> 0.0044435301 | P6: ='[1]demanda (2)'!N6 -> 0.0060276389 | Q6: ='[2]demanda (2)'!N6 -> 0.008639842 | R6: =AVERAGE(O6:Q6) -> 0.006370337 | S6: =(N6-L6-I6)/(N6-I6) -> 0.040670975 | T6: ='[3]demanda (2)'!O6 -> 0.039764571 | U6: ='[4]demanda (2)'!O6 -> 0.036072802 | V6: =AVERAGE(S6:U6) -> 0.038836116
A7: 0191 | B7: 01912 | C7: Milho em grão | D7: 22656 | E7: 53 | F7: 0 | G7: 9779 | H7: 0 | I7: 30117 | J7: =SUM(D7:I7) -> 62605 | K7: =J7+CI!BT7 -> 125926 | L7: =K7-J7 -> 63321 | M7: =CI!BS7 -> 288 | N7: =K7-D7 -> 103270 | O7: =M7/N7 -> 0.002788806 | P7: ='[1]demanda (2)'!N7 -> 0.0049180328 | Q7: ='[2]demanda (2)'!N7 -> 0.0089243776 | R7: =AVERAGE(O7:Q7) -> 0.0055437388 | S7: =(N7-L7-I7)/(N7-I7) -> 0.13440324 | T7: ='[3]demanda (2)'!O7 -> 0.15207604 | U7: ='[4]demanda (2)'!O7 -> 0.16407415 | V7: =AVERAGE(S7:U7) -> 0.15018448
A8: 0191 | B8: 01913 | C8: Algodão herbáceo, outras fibras da lav. temporária | D8: 18609 | E8: 0 | F8: 0 | G8: 11 | H8: 0 | I8: -830 | J8: =SUM(D8:I8) -> 17790 | K8: =J8+CI!BT8 -> 34790 | L8: =K8-J8 -> 17000 | M8: =CI!BS8 -> 0 | N8: =K8-D8 -> 16181 | O8: =M8/N8 -> 0 | P8: ='[1]demanda (2)'!N8 -> 0 | Q8: ='[2]demanda (2)'!N8 -> 0 | R8: =AVERAGE(O8:Q8) -> 0 | S8: =(N8-L8-I8)/(N8-I8) -> 0.00064664041 | T8: ='[3]demanda (2)'!O8 -> 0.0010102144 | U8: ='[4]demanda (2)'!O8 -> 0.0011100319 | V8: =AVERAGE(S8:U8) -> 0.00092229557
A9: 0191 | B9: 01914 | C9: Cana-de-açúcar | D9: 3 | E9: 0 | F9: 0 | G9: 2318 | H9: 0 | I9: 0 | J9: =SUM(D9:I9) -> 2321 | K9: =J9+CI!BT9 -> 82968 | L9: =K9-J9 -> 80647 | M9: =CI!BS9 -> 0 | N9: =K9-D9 -> 82965 | O9: =M9/N9 -> 0 | P9: ='[1]demanda (2)'!N9 -> 0 | Q9: ='[2]demanda (2)'!N9 -> 0 | R9: =AVERAGE(O9:Q9) -> 0 | S9: =(N9-L9-I9)/(N9-I9) -> 0.027939493 | T9: ='[3]demanda (2)'!O9 -> 0.027063941 | U9: ='[4]demanda (2)'!O9 -> 0.02715499 | V9: =AVERAGE(S9:U9) -> 0.027386141
A10: 0191 | B10: 01915 | C10: Soja em grão | D10: 213948 | E10: 0 | F10: 0 | G10: 309 | H10: 0 | I10: 9032 | J10: =SUM(D10:I10) -> 223289 | K10: =J10+CI!BT10 -> 345837 | L10: =K10-J10 -> 122548 | M10: =CI!BS10 -> 0 | N10: =K10-D10 -> 131889 | O10: =M10/N10 -> 0 | P10: ='[1]demanda (2)'!N10 -> 0 | Q10: ='[2]demanda (2)'!N10 -> 0 | R10: =AVERAGE(O10:Q10) -> 0 | S10: =(N10-L10-I10)/(N10-I10) -> 0.0025151192 | T10: ='[3]demanda (2)'!O10 -> 0.001810055 | U10: ='[4]demanda (2)'!O10 -> 0.0019114524 | V10: =AVERAGE(S10:U10) -> 0.0020788755
A11: 0191 | B11: 01916 | C11: Outros produtos e serviços da lavoura temporária | D11: 3981 | E11: 53 | F11: 0 | G11: 100772 | H11: 0 | I11: -883 | J11: =SUM(D11:I11) -> 103923 | K11: =J11+CI!BT11 -> 142742 | L11: =K11-J11 -> 38819 | M11: =CI!BS11 -> 2189 | N11: =K11-D11 -> 138761 | O11: =M11/N11 -> 0.015775326 | P11: ='[1]demanda (2)'!N11 -> 0.015167372 | Q11: ='[2]demanda (2)'!N11 -> 0.016240245 | R11: =AVERAGE(O11:Q11) -> 0.015727648 | S11: =(N11-L11-I11)/(N11-I11) -> 0.72201455 | T11: ='[3]demanda (2)'!O11 -> 0.73727867 | U11: ='[4]demanda (2)'!O11 -> 0.7118582 | V11: =AVERAGE(S11:U11) -> 0.72371714
A12: 0191 | B12: 01917 | C12: Laranja | D12: 5 | E12: 0 | F12: 0 | G12: 4157 | H12: 356 | I12: 0 | J12: =SUM(D12:I12) -> 4518 | K12: =J12+CI!BT12 -> 20560 | L12: =K12-J12 -> 16042 | M12: =CI!BS12 -> 38 | N12: =K12-D12 -> 20555 | O12: =M12/N12 -> 0.0018486986 | P12: ='[1]demanda (2)'!N12 -> 0.0017547832 | Q12: ='[2]demanda (2)'!N12 -> 0.001592942 | R12: =AVERAGE(O12:Q12) -> 0.0017321413 | S12: =(N12-L12-I12)/(N12-I12) -> 0.21955729 | T12: ='[3]demanda (2)'!O12 -> 0.23519755 | U12: ='[4]demanda (2)'!O12 -> 0.21749786 | V12: =AVERAGE(S12:U12) -> 0.22408423
A13: 0191 | B13: 01918 | C13: Café em grão | D13: 31487 | E13: 0 | F13: 0 | G13: 936 | H13: 189 | I13: -1687 | J13: =SUM(D13:I13) -> 30925 | K13: =J13+CI!BT13 -> 40217 | L13: =K13-J13 -> 9292 | M13: =CI!BS13 -> 6 | N13: =K13-D13 -> 8730 | O13: =M13/N13 -> 0.00068728522 | P13: ='[1]demanda (2)'!N13 -> 0.00048123195 | Q13: ='[2]demanda (2)'!N13 -> 0.00066533599 | R13: =AVERAGE(O13:Q13) -> 0.00061128439 | S13: =(N13-L13-I13)/(N13-I13) -> 0.10799654 | T13: ='[3]demanda (2)'!O13 -> 0.1238201 | U13: ='[4]demanda (2)'!O13 -> 0.081168355 | V13: =AVERAGE(S13:U13) -> 0.10432833
A14: 0191 | B14: 01919 | C14: Outros produtos da lavoura permanente | D14: 4124 | E14: 8 | F14: 0 | G14: 48240 | H14: 255 | I14: 0 | J14: =SUM(D14:I14) -> 52627 | K14: =J14+CI!BT14 -> 59464 | L14: =K14-J14 -> 6837 | M14: =CI!BS14 -> 514 | N14: =K14-D14 -> 55340 | O14: =M14/N14 -> 0.0092880376 | P14: ='[1]demanda (2)'!N14 -> 0.009310037 | Q14: ='[2]demanda (2)'!N14 -> 0.0088137318 | R14: =AVERAGE(O14:Q14) -> 0.0091372688 | S14: =(N14-L14-I14)/(N14-I14) -> 0.87645464 | T14: ='[3]demanda (2)'!O14 -> 0.87361306 | U14: ='[4]demanda (2)'!O14 -> 0.86846488 | V14: =AVERAGE(S14:U14) -> 0.8728442
