Workbook

Sheet Metodologia
B2: Para gerar estimativa dos créditos provenientes do trabalho não assalariado foi utilizada a seguinte metodologia:
B3: 1) Identificados os registros referentes ao livro caixa por CPF enviados para o sistema Carnê-Leão Web para os anos de 2023 e 2024 | C3: 1.1) Criação de Tabela para armazenar registros de lançamentos referentes aos demonstrativos de 2023 e 2024: create table u08105524775.carne_leao_livcx ( ano smallint, cpf string, vl_livcx decimal(15,2) ) stored as parquet
C4: 1.2) Preenchimento da tabela: insert into u08105524775.carne_leao_livcx select cast(de.ano_calendario as smallint), de.cpf, cast(sum(zeroifnull(lp.conteudo_valor)) as decimal(15,2)) from dbbr_irpf_carne_leao.lancamentos_pagamentos lp, dbbr_irpf_carne_leao.demonstrativos de where de.id = lp.id_demonstrativo and de.ano_calendario in ('2023','2024') and de.configuracao like '%"trabalhadorAutonomo": true%' and lp.conteudo_codigo not like '20.%' and de.cpf = lp.cpf group by 1,2
B5: 2) Os totais por CPF do Carnê-Leão foram comparados com os valores do Livro Caixa declarados na DIRPF, e selecionada uma amostra de cpfs com uma variação máxima de 10% entre os dois valores | C5: 2.1) Criação de tabela para armazenar valores provenientes da DIRPF, ficha "Rendimentos Tributáveis Recebidos de Pessoa Física e do Exterior pelo Titular", referentes aos Rendimentos do Trabalho Não Assalariado e Livro Caixa: create table u08105524775.repf_rendim_livcx ( ano smallint, cpf string, principal double, vl_rendim decimal(15,2), vl_livcx decimal(15,2) ) stored as parquet
C6: 2.2) Preenchimento da tabela com dados referentes a 2023 e 2024: insert into u08105524775.repf_rendim_livcx select cast((ir.ano-1) as smallint), ir.nu_cpf, ir.principal, cast(sum(zeroifnull(va_renda)) as decimal(15,2)), cast(sum(zeroifnull(va_livro_caixa)) as decimal(15,2)) from u08105524775.gnirpf_irpf_repf as pf, u08105524775.gnirpf_irpf as ir where pf.nu_ident_decl = ir.nu_ident_decl and pf.an_exercicio = ir.ano and lpad(cast(pf.nu_cpf as string),11,'0') = ir.nu_cpf group by 1,2,3 insert into u08105524775.repf_rendim_livcx select cast((ir.ano-1) as smallint), ir.nu_cpf, ir.principal, cast(sum(zeroifnull(va_renda)) as decimal(15,2)), cast(sum(zeroifnull(va_livro_caixa)) as decimal(15,2)) from u08105524775.gnirpf_irpf_repf_ac2023 as pf, u08105524775.gnirpf_irpf_ac2023 as ir where pf.nu_ident_decl = ir.nu_ident_decl and pf.an_exercicio = ir.ano and lpad(cast(pf.nu_cpf as string),11,'0') = ir.nu_cpf group by 1,2,3
C7: 2.3) Identificação da amostra: create table u08105524775.amostra_livro_caixa ( ano smallint, cpf string, cod_ocup double ) stored as parquet insert into u08105524775.amostra_livro_caixa select ir.ano, ir.cpf, ir.principal from u08105524775.carne_leao_livcx cl, u08105524775.repf_rendim_livcx ir where cl.ano = ir.ano and cl.cpf = ir.cpf and ir.vl_livcx > 0 and ((cl.vl_livcx/ir.vl_livcx)-1)*100 >= -10 and ((cl.vl_livcx/ir.vl_livcx)-1)*100 <= 10
B8: 3) Os lançamentos do livro caixa no Carnê-Leão foram analisados para identificar qual percentual dos valores pode ser apropriado como crédito da CBS | C8: 3.1) Extração dos lançamentos do livro caixa dos cpfs incluídos na amostra: select de.ano_calendario, lp.conteudo_codigo, lp.conteudo_descricao, sum(zeroifnull(lp.conteudo_valor)) from dbbr_irpf_carne_leao.lancamentos_pagamentos lp, dbbr_irpf_carne_leao.demonstrativos de, u08105524775.amostra_livro_caixa am where de.cpf = am.cpf and de.ano_calendario = cast(am.ano as string) and de.cpf = lp.cpf and de.id = lp.id_demonstrativo and de.configuracao like '%"trabalhadorAutonomo": true%' and lp.conteudo_codigo not like '20.%' group by 1,2,3
C9: 3.2) Como os usuários do Carnê-Leão podem registrar seu próprio plano de contas (embora exista um plano de contas padrão), é necessário realizar a análise com base na descrição do lançamento. Foi verificado que cerca de 14% dos registros correspondiam a 95% do valor total, então, para simplificar o trabalho de análise, os registros correspondentes aos 5% restantes foram descartados
C10: 3.3) Os lançamentos foram classificados de acordo com a geração ou não de crédito da CBS, na planilha "Dados Amostra", de acordo com a planilha "Critérios"
B11: 4) Cálculo do percentual para aplicação ao valor total do livro caixa declarado na DIRPF | C11: ='Dados Amostra'!J7 -> 0.38092582
B12: 5) Aplicação do percentual calculado ao valor do livro caixa declarado na DIRPF | C12: 5.1) Extração dos valores totais declarados como livro caixanos anos de 2023 e 2024 select (ir.ano-1) as 'Ano-Calendário', ir.principal as 'Ocupação', sum(zeroifnull(va_livro_caixa)) as 'Total Livro Caixa' from u08105524775.gnirpf_irpf_repf as pf, u08105524775.gnirpf_irpf as ir where pf.nu_ident_decl = ir.nu_ident_decl and pf.an_exercicio = ir.ano and lpad(cast(pf.nu_cpf as string),11,'0') = ir.nu_cpf group by 1,2 union select (ir.ano-1) as 'Ano-Calendário', ir.principal as 'Ocupação', sum(zeroifnull(va_livro_caixa)) as 'Total Livro Caixa' from u08105524775.gnirpf_irpf_repf_ac2023 as pf, u08105524775.gnirpf_irpf_ac2023 as ir where pf.nu_ident_decl = ir.nu_ident_decl and pf.an_exercicio = ir.ano and lpad(cast(pf.nu_cpf as string),11,'0') = ir.nu_cpf group by 1,2
B13: OBS.: Sobre tabelas utilizadas 1) Tabela de Rendimentos recebidos de pessoa física: cópia de view original da base de dados da DIRPF, conforme comando de criação abaixo create table u08105524775.gnirpf_irpf_repf stored as parquet as select * from dbbr_irpf_119_11706_ada.tab_8_aa_irpfmx_rend_pf_view where an_exercicio = <ano>; 2) Tabela de Declarações de IRPF: tabela com dados originários da base de dados da DIRPF, tratados para manter apenas declarações válidas e vigentes, conforme processo utilizado para geração do estudo dos Grandes Números IRPF. SQL original abaixo select * from dbbr_irpf_119_11706_ada.tab_7_aa_irpfmx_declaracao_view where an_exercicio = <ano> and co_situacao_decl not in (85, 80); 3) Tabela de Demonstrativos do Carnê-Leão: demonstrativo anual do contribuinte, ao qual é associado o plano de contas dbbr_irpf_carne_leao.demonstrativos 4) Tabela de Lançamentos referentes a Pagamentos do Carnê-Leão: lançamentos individuais associados ao demonstrativo dbbr_irpf_carne_leao.lancamentos_pagamentos

Sheet Números
B2: Declarações com Rendimentos do Trabalho Não Assalariado
B3: Ano | C3: Qtde Declarações
B4: 2023 | C4: 1534042
B5: 2024 | C5: 1543647
B6: Total | C6: =SUM(C4:C5) -> 3077689
B8: Tamanho da Amostra
B9: Ano | C9: Qtde CPFs
B10: 2024 | C10: 87999
B11: 2023 | C11: 82190
B12: Total | C12: =SUM(C10:C11) -> 170189
B13: % do Total | C13: =C12/C6 -> 0.05529766
B15: Valor Total Livro Caixa declarado na DIRPF
B16: Ano | C16: Total Livro Caixa | D16: Créditos estimados
B17: 2023 | C17: =GETPIVOTDATA("total livro caixa",'Valor Livro Caixa - DIRPF'!$E$2,"ano-calendário",2023) -> 2.7643406e+10 | D17: =C17*Metodologia!$C$11 -> 1.0530087e+10
B18: 2024 | C18: =GETPIVOTDATA("total livro caixa",'Valor Livro Caixa - DIRPF'!$E$2,"ano-calendário",2024) -> 2.9874279e+10 | D18: =C18*Metodologia!$C$11 -> 1.1379884e+10

Sheet Valor Livro Caixa - DIRPF
A1: ano-calendário | B1: ocupação | C1: total livro caixa
A2: 2023 | B2: 0 | C2: 1.0162234e+09 | E2: Soma de total livro caixa | F2: Rótulos de Coluna
A3: 2024 | B3: 0 | C3: 1.0788772e+09 | E3: Rótulos de Linha | F3: 2023 | G3: 2024 | H3: Total Geral
A4: 2023 | B4: 10 | C4: 5608774.6 | E4: 0 | F4: 1.0162234e+09 | G4: 1.0788772e+09 | H4: 2.0951006e+09
A5: 2024 | B5: 10 | C5: 5063443.5 | E5: 10 | F5: 5608774.6 | G5: 5063443.5 | H5: 10672218
A6: 2023 | B6: 20 | C6: 5463513.6 | E6: 20 | F6: 5463513.6 | G6: 5366345.6 | H6: 10829859
A7: 2024 | B7: 20 | C7: 5366345.6 | E7: 30 | F7: 1734699.8 | G7: 1707927.2 | H7: 3442627
A8: 2023 | B8: 30 | C8: 1734699.8 | E8: 40 | F8: 10409800 | G8: 9252978.4 | H8: 19662779
A9: 2024 | B9: 30 | C9: 1707927.2 | E9: 50 | F9: 9611326.7 | G9: 11357724 | H9: 20969051
A10: 2023 | B10: 40 | C10: 10409800 | E10: 101 | F10: 5772193 | G10: 4788205 | H10: 10560398
A11: 2024 | B11: 40 | C11: 9252978.4 | E11: 102 | F11: 12757190 | G11: 26481878 | H11: 39239069
A12: 2023 | B12: 50 | C12: 9611326.7 | E12: 103 | F12: 2463755.1 | G12: 1513686.4 | H12: 3977441.5
A13: 2024 | B13: 50 | C13: 11357724 | E13: 104 | F13: 10883314 | G13: 15006065 | H13: 25889379
A14: 2023 | B14: 101 | C14: 5772193 | E14: 105 | F14: 2205367.8 | G14: 2442296.9 | H14: 4647664.8
A15: 2024 | B15: 101 | C15: 4788205 | E15: 106 | F15: 28543.18 | G15: 11431.62 | H15: 39974.8
... A44: 2023 | B44: 116 | C44: 14592806 | E44: 228 | F44: 64349596 | G44: 60740677 | H44: 1.2509027e+08
A45: 2024 | B45: 116 | C45: 17582178 | E45: 229 | F45: 3.3470244e+08 | H45: 3.3470244e+08
A46: 2023 | B46: 117 | C46: 1.0618396e+10 | E46: 230 | G46: 77544471 | H46: 77544471
A47: 2024 | B47: 117 | C47: 1.2018186e+10 | E47: 231 | G47: 2.1299922e+08 | H47: 2.1299922e+08
A48: 2023 | B48: 118 | C48: 657516.02 | E48: 232 | G48: 21459740 | H48: 21459740
A49: 2024 | B49: 118 | C49: 567119.09 | E49: 241 | F49: 4.2770735e+08 | G49: 4.8137087e+08 | H49: 9.0907822e+08
A50: 2023 | B50: 120 | C50: 7.0929452e+08 | E50: 250 | F50: 521287.47 | G50: 486126.65 | H50: 1007414.1
A51: 2024 | B51: 120 | C51: 8.0359728e+08 | E51: 251 | F51: 17371.07 | G51: 0 | H51: 17371.07
A52: 2023 | B52: 121 | C52: 2566501.5 | E52: 252 | F52: 2.5458633e+08 | G52: 2.5896982e+08 | H52: 5.1355615e+08
A53: 2024 | B53: 121 | C53: 1692934.6 | E53: 253 | F53: 7021553.3 | G53: 7438821.8 | H53: 14460375
A54: 2023 | B54: 130 | C54: 59990609 | E54: 254 | F54: 10619150 | G54: 12867274 | H54: 23486424
A55: 2024 | B55: 130 | C55: 50671305 | E55: 255 | F55: 4.6152678e+08 | G55: 5.5546256e+08 | H55: 1.0169893e+09
A56: 2023 | B56: 131 | C56: 1660609.1 | E56: 256 | F56: 14750 | G56: 17911.75 | H56: 32661.75
A57: 2024 | B57: 131 | C57: 1762605.5 | E57: 257 | F57: 33045.88 | G57: 71210.66 | H57: 104256.54
A58: 2023 | B58: 140 | C58: 3002691.3 | E58: 258 | F58: 908290.25 | G58: 916545.94 | H58: 1824836.2
A59: 2024 | B59: 140 | C59: 1816487.3 | E59: 259 | F59: 111042.31 | G59: 150289.35 | H59: 261331.66
A60: 2023 | B60: 211 | C60: 1158172.9 | E60: 261 | F60: 3100421.6 | G60: 4734960.6 | H60: 7835382.3
... A140: 2023 | B140: 292 | C140: 7194256.8 | E140: 900 | F140: 16749440 | G140: 13565550 | H140: 30314990
A141: 2024 | B141: 292 | C141: 5858280.5 | E141: NULL | F141: 2.7819431e+08 | G141: 2.957364e+08 | H141: 5.739307e+08
A142: 2023 | B142: 293 | C142: 1717525.9 | E142: Total Geral | F142: 2.7643406e+10 | G142: 2.9874279e+10 | H142: 5.7517685e+10
A143: 2024 | B143: 293 | C143: 2576152.6
A144: 2023 | B144: 294 | C144: 45936645
A145: 2024 | B145: 294 | C145: 47993803
A146: 2023 | B146: 295 | C146: 13869530
A147: 2024 | B147: 295 | C147: 14028507
...

Sheet Dados Amostra
A1: ano_calendario | B1: conteudo_codigo | C1: conteudo_descricao | D1: valor total | E1: % Total | F1: %Acum | G1: Gera crédito
A2: 2024 | B2: 10.01.00013 | C2: Remuneração paga a terceiros, com vínculo empregatício, INSS e FGTS | D2: 2.1835815e+09 | E2: =(D2/$D$29638)*100 -> 9.8835041 | F2: =E2 -> 9.8835041 | G2: N | H2: Soma de valor total | I2: Rótulos de Coluna
A3: 2023 | B3: 10.01.00013 | C3: Remuneração paga a terceiros, com vínculo empregatício, INSS e FGTS | D3: 1.9135952e+09 | E3: =(D3/$D$29638)*100 -> 8.6614703 | F3: =E3+F2 -> 18.544974 | G3: N | H3: Rótulos de Linha | I3: N | J3: S | K3: Total Geral
A4: 2024 | B4: 10.01.00006 | C4: Emolumentos pagos a terceiros | D4: 1.0277306e+09 | E4: =(D4/$D$29638)*100 -> 4.651798 | F4: =E4+F3 -> 23.196772 | G4: N | H4: 2023 | I4: 6.3258678e+09 | J4: 3.9866602e+09 | K4: 1.0312528e+10
A5: 2024 | B5: 10.01.00002 | C5: Aluguel do escritório/consultório | D5: 9.9844751e+08 | E5: =(D5/$D$29638)*100 -> 4.5192544 | F5: =E5+F4 -> 27.716027 | G5: S | H5: 2024 | I5: 7.3514564e+09 | J5: 4.4292068e+09 | K5: 1.1780663e+10
A6: 2023 | B6: 10.01.00006 | C6: Emolumentos pagos a terceiros | D6: 9.4120892e+08 | E6: =(D6/$D$29638)*100 -> 4.2601764 | F6: =E6+F5 -> 31.976203 | G6: N | H6: Total Geral | I6: 1.3677324e+10 | J6: 8.415867e+09 | K6: 2.2093191e+10
A7: 2023 | B7: 10.01.00002 | C7: Aluguel do escritório/consultório | D7: 9.077423e+08 | E7: =(D7/$D$29638)*100 -> 4.108697 | F7: =E7+F6 -> 36.0849 | G7: S | J7: =GETPIVOTDATA("valor total",$H$2,"Gera crédito","S")/GETPIVOTDATA("valor total",$H$2) -> 0.38092582
A8: 2024 | B8: 10.01.00012 | C8: Material de escritório | D8: 6.6531763e+08 | E8: =(D8/$D$29638)*100 -> 3.0114148 | F8: =E8+F7 -> 39.096315 | G8: S
A9: 2023 | B9: 10.01.00012 | C9: Material de escritório | D9: 6.2824293e+08 | E9: =(D9/$D$29638)*100 -> 2.8436043 | F9: =E9+F8 -> 41.939919 | G9: S
A10: 2024 | B10: 10.01.00003 | C10: Condomínio do escritório/consultório | D10: 2.9351424e+08 | E10: =(D10/$D$29638)*100 -> 1.328528 | F10: =E10+F9 -> 43.268447 | G10: N
A11: 2024 | B11: 10.01.00011 | C11: Material de conservação e limpeza do escritório/consultório | D11: 2.7852042e+08 | E11: =(D11/$D$29638)*100 -> 1.2606618 | F11: =E11+F10 -> 44.529109 | G11: S
A12: 2023 | B12: 10.01.00003 | C12: Condomínio do escritório/consultório | D12: 2.6671668e+08 | E12: =(D12/$D$29638)*100 -> 1.2072348 | F12: =E12+F11 -> 45.736344 | G12: N
A13: 2023 | B13: 10.01.00011 | C13: Material de conservação e limpeza do escritório/consultório | D13: 2.5905438e+08 | E13: =(D13/$D$29638)*100 -> 1.172553 | F13: =E13+F12 -> 46.908897 | G13: S
A14: 2024 | B14: 10.01.00004 | C14: Contribuições obrigatórias a entidades de classe | D14: 2.2580572e+08 | E14: =(D14/$D$29638)*100 -> 1.0220602 | F14: =E14+F13 -> 47.930957 | G14: N
A15: 2023 | B15: 10.01.00004 | C15: Contribuições obrigatórias a entidades de classe | D15: 2.0217642e+08 | E15: =(D15/$D$29638)*100 -> 0.91510734 | F15: =E15+F14 -> 48.846064 | G15: N
A16: 2024 | B16: 10.01.00007 | C16: Energia do escritório/consultório | D16: 1.5720258e+08 | E16: =(D16/$D$29638)*100 -> 0.7115431 | F16: =E16+F15 -> 49.557608 | G16: S
A17: 2024 | B17: 10.01.00010 | C17: ISS | D17: 1.3986044e+08 | E17: =(D17/$D$29638)*100 -> 0.63304772 | F17: =E17+F16 -> 50.190655 | G17: N
A18: 2023 | B18: 10.01.00010 | C18: ISS | D18: 1.3729448e+08 | E18: =(D18/$D$29638)*100 -> 0.62143344 | F18: =E18+F17 -> 50.812089 | G18: N
A19: 2023 | B19: 10.01.00007 | C19: Energia do escritório/consultório | D19: 1.3659081e+08 | E19: =(D19/$D$29638)*100 -> 0.61824845 | F19: =E19+F18 -> 51.430337 | G19: S
... A29637: 2024 | B29637: 10.01.00012 | C29637: Material de consumo para procedimento odontológico | D29637: 40637.44 | E29637: =(D29637/$D$29638)*100 -> 0.00018393649 | F29637: =E29637+F29636 -> 100 | G29637: S
D29638: =SUM(D2:D29637) -> 2.2093191e+10

Sheet Critérios
A1: Remuneração | B1: Não | D1: Aluguel | E1: Sim
A2: Emolumentos | B2: Não | D2: Água | E2: Sim
A3: Impostos | B3: Não | D3: Energia | E3: Sim
A4: Taxas | B4: Não | D4: Gás | E4: Sim
A5: Contribuições | B5: Não | D5: Documentos | E5: Sim
A6: Pensão | B6: Não | D6: Telefone | E6: Sim
A7: Previdência | B7: Não | D7: Material | E7: Sim
A8: INSS | B8: Não | D8: Aquisição | E8: Sim
A9: Salário | B9: Não | D9: Arrendamento | E9: Sim
A10: IRRF | B10: Não | D10: Combustível | E10: Sim
A11: IPTU | B11: Não | D11: Conservação | E11: Sim
A12: Capital | B12: Não | D12: Depreciação | E12: Sim
... A24: ISS | B24: Não | D24: Remuneração paga a terceiros, sem vínculo empregatício | E24: Sim
A25: Com vínculo empregatício | B25: Não | D25: Produtos utilizados na atividade

Sheet estim bc créditos
A1: Soma de total livro caixa | B1: Rótulos de Coluna | H1: DISTRIBUIÇÃO DAS OCUPAÇÕES "0" E NULL | K1: =Metodologia!C11 -> 0.38092582 | L1: % médio das despesas do livro caixa que dão direito a crédito de CBS
A2: Rótulos de Linha | B2: 2023 | C2: 2024 | D2: Total Geral | I2: Valor Despesa Livro Caixa | K2: Estimativa BC Crédito CBS
A3: 0 | B3: 1.0162234e+09 | C3: 1.0788772e+09 | D3: 2.0951006e+09 | H3: Ocupação | I3: 2023 | J3: 2024 | K3: 2023 | L3: 2024
A4: 10 | B4: 5608774.6 | C4: 5063443.5 | D4: 10672218 | E4: =D4/$D$144 -> 0.00019457575 | H4: 10 | I4: =B4+($B$3+$B$140)*E4 -> 5860636.9 | J4: =C4+($C$3+$C$140)*E4 -> 5330910 | K4: =I4*$K$1 -> 2232467.9 | L4: =J4*$K$1 -> 2030681.3
A5: 20 | B5: 5463513.6 | C5: 5366345.6 | D5: 10829859 | E5: =D5/$D$144 -> 0.00019744986 | H5: 20 | I5: =B5+($B$3+$B$140)*E5 -> 5719096.2 | J5: =C5+($C$3+$C$140)*E5 -> 5637762.8 | K5: =I5*$K$1 -> 2178551.4 | L5: =J5*$K$1 -> 2147569.4
A6: 30 | B6: 1734699.8 | C6: 1707927.2 | D6: 3442627 | E6: =D6/$D$144 -> 6.2765934e-05 | H6: 30 | I6: =B6+($B$3+$B$140)*E6 -> 1815945.1 | J6: =C6+($C$3+$C$140)*E6 -> 1794206.1 | K6: =I6*$K$1 -> 691740.37 | L6: =J6*$K$1 -> 683459.45
A7: 40 | B7: 10409800 | C7: 9252978.4 | D7: 19662779 | E7: =D7/$D$144 -> 0.00035849155 | H7: 40 | I7: =B7+($B$3+$B$140)*E7 -> 10873838 | J7: =C7+($C$3+$C$140)*E7 -> 9745765.8 | K7: =I7*$K$1 -> 4142125.7 | L7: =J7*$K$1 -> 3712413.8
A8: 50 | B8: 9611326.7 | C8: 11357724 | D8: 20969051 | E8: =D8/$D$144 -> 0.00038230749 | H8: 50 | I8: =B8+($B$3+$B$140)*E8 -> 10106192 | J8: =C8+($C$3+$C$140)*E8 -> 11883249 | K8: =I8*$K$1 -> 3849709.6 | L8: =J8*$K$1 -> 4526636.6
A9: 101 | B9: 5772193 | C9: 4788205 | D9: 10560398 | E9: =D9/$D$144 -> 0.00019253705 | H9: 101 | I9: =B9+($B$3+$B$140)*E9 -> 6021416.3 | J9: =C9+($C$3+$C$140)*E9 -> 5052869 | K9: =I9*$K$1 -> 2293713 | L9: =J9*$K$1 -> 1924768.3
A10: 102 | B10: 12757190 | C10: 26481878 | D10: 39239069 | E10: =D10/$D$144 -> 0.00071540623 | H10: 102 | I10: =B10+($B$3+$B$140)*E10 -> 13683225 | J10: =C10+($C$3+$C$140)*E10 -> 27465285 | K10: =I10*$K$1 -> 5212293.7 | L10: =J10*$K$1 -> 10462236
A11: 103 | B11: 2463755.1 | C11: 1513686.4 | D11: 3977441.5 | E11: =D11/$D$144 -> 7.2516665e-05 | H11: 103 | I11: =B11+($B$3+$B$140)*E11 -> 2557621.9 | J11: =C11+($C$3+$C$140)*E11 -> 1613368.8 | K11: =I11*$K$1 -> 974264.23 | L11: =J11*$K$1 -> 614573.84
A12: 104 | B12: 10883314 | C12: 15006065 | D12: 25889379 | E12: =D12/$D$144 -> 0.00047201485 | H12: 104 | I12: =B12+($B$3+$B$140)*E12 -> 11494298 | J12: =C12+($C$3+$C$140)*E12 -> 15654903 | K12: =I12*$K$1 -> 4378475.1 | L12: =J12*$K$1 -> 5963356.8
A13: 105 | B13: 2205367.8 | C13: 2442296.9 | D13: 4647664.8 | E13: =D13/$D$144 -> 8.4736168e-05 | H13: 105 | I13: =B13+($B$3+$B$140)*E13 -> 2315051.8 | J13: =C13+($C$3+$C$140)*E13 -> 2558776.4 | K13: =I13*$K$1 -> 881863.02 | L13: =J13*$K$1 -> 974704.01
A14: 106 | B14: 28543.18 | C14: 11431.62 | D14: 39974.8 | E14: =D14/$D$144 -> 7.2882007e-07 | H14: 106 | I14: =B14+($B$3+$B$140)*E14 -> 29486.578 | J14: =C14+($C$3+$C$140)*E14 -> 12433.466 | K14: =I14*$K$1 -> 11232.199 | L14: =J14*$K$1 -> 4736.2282
A15: 107 | B15: 629442.44 | C15: 3382080.8 | D15: 4011523.3 | E15: =D15/$D$144 -> 7.3138044e-05 | H15: 107 | I15: =B15+($B$3+$B$140)*E15 -> 724113.62 | J15: =C15+($C$3+$C$140)*E15 -> 3482617.4 | K15: =I15*$K$1 -> 275833.58 | L15: =J15*$K$1 -> 1326618.9
... A43: 228 | B43: 64349596 | C43: 60740677 | D43: 1.2509027e+08 | E43: =D43/$D$144 -> 0.0022806444 | H43: 228 | I43: =B43+($B$3+$B$140)*E43 -> 67301703 | J43: =C43+($C$3+$C$140)*E43 -> 63875682 | K43: =I43*$K$1 -> 25636956 | L43: =J43*$K$1 -> 24331897
A44: 229 | B44: 3.3470244e+08 | D44: 3.3470244e+08 | E44: =D44/$D$144 -> 0.0061022909 | H44: 229 | I44: =B44+($B$3+$B$140)*E44 -> 3.4260136e+08 | J44: =C44+($C$3+$C$140)*E44 -> 8388292 | K44: =I44*$K$1 -> 1.305057e+08 | L44: =J44*$K$1 -> 3195317
A45: 230 | C45: 77544471 | D45: 77544471 | E45: =D45/$D$144 -> 0.0014137899 | H45: 230 | I45: =B45+($B$3+$B$140)*E45 -> 1830034.6 | J45: =C45+($C$3+$C$140)*E45 -> 79487885 | K45: =I45*$K$1 -> 697107.45 | L45: =J45*$K$1 -> 30278988
A46: 231 | C46: 2.1299922e+08 | D46: 2.1299922e+08 | E46: =D46/$D$144 -> 0.0038833992 | H46: 231 | I46: =B46+($B$3+$B$140)*E46 -> 5026740.7 | J46: =C46+($C$3+$C$140)*E46 -> 2.1833739e+08 | K46: =I46*$K$1 -> 1914815.3 | L46: =J46*$K$1 -> 83170350
A47: 232 | C47: 21459740 | D47: 21459740 | E47: =D47/$D$144 -> 0.00039125372 | H47: 232 | I47: =B47+($B$3+$B$140)*E47 -> 506445.75 | J47: =C47+($C$3+$C$140)*E47 -> 21997563 | K47: =I47*$K$1 -> 192918.27 | L47: =J47*$K$1 -> 8379439.7
A48: 241 | B48: 4.2770735e+08 | C48: 4.8137087e+08 | D48: 9.0907822e+08 | E48: =D48/$D$144 -> 0.016574303 | H48: 241 | I48: =B48+($B$3+$B$140)*E48 -> 4.4916142e+08 | J48: =C48+($C$3+$C$140)*E48 -> 5.0415413e+08 | K48: =I48*$K$1 -> 1.7109718e+08 | L48: =J48*$K$1 -> 1.9204533e+08
A49: 250 | B49: 521287.47 | C49: 486126.65 | D49: 1007414.1 | E49: =D49/$D$144 -> 1.8367162e-05 | H49: 250 | I49: =B49+($B$3+$B$140)*E49 -> 545062.25 | J49: =C49+($C$3+$C$140)*E49 -> 511374.4 | K49: =I49*$K$1 -> 207628.29 | L49: =J49*$K$1 -> 194795.71
A50: 251 | B50: 17371.07 | C50: 0 | D50: 17371.07 | E50: =D50/$D$144 -> 3.1670914e-07 | H50: 251 | I50: =B50+($B$3+$B$140)*E50 -> 17781.024 | J50: =C50+($C$3+$C$140)*E50 -> 435.35268 | K50: =I50*$K$1 -> 6773.2511 | L50: =J50*$K$1 -> 165.83708
A51: 252 | B51: 2.5458633e+08 | C51: 2.5896982e+08 | D51: 5.1355615e+08 | E51: =D51/$D$144 -> 0.0093631496 | H51: 252 | I51: =B51+($B$3+$B$140)*E51 -> 2.6670616e+08 | J51: =C51+($C$3+$C$140)*E51 -> 2.7184053e+08 | K51: =I51*$K$1 -> 1.0159526e+08 | L51: =J51*$K$1 -> 1.0355108e+08
A52: 253 | B52: 7021553.3 | C52: 7438821.8 | D52: 14460375 | E52: =D52/$D$144 -> 0.00026364138 | H52: 253 | I52: =B52+($B$3+$B$140)*E52 -> 7362815.4 | J52: =C52+($C$3+$C$140)*E52 -> 7801226.8 | K52: =I52*$K$1 -> 2804686.5 | L52: =J52*$K$1 -> 2971688.7
A53: 254 | B53: 10619150 | C53: 12867274 | D53: 23486424 | E53: =D53/$D$144 -> 0.00042820421 | H53: 254 | I53: =B53+($B$3+$B$140)*E53 -> 11173425 | J53: =C53+($C$3+$C$140)*E53 -> 13455890 | K53: =I53*$K$1 -> 4256246.2 | L53: =J53*$K$1 -> 5125695.8
A54: 255 | B54: 4.6152678e+08 | C54: 5.5546256e+08 | D54: 1.0169893e+09 | E54: =D54/$D$144 -> 0.018541737 | H54: 255 | I54: =B54+($B$3+$B$140)*E54 -> 4.8552753e+08 | J54: =C54+($C$3+$C$140)*E54 -> 5.8095028e+08 | K54: =I54*$K$1 -> 1.8494997e+08 | L54: =J54*$K$1 -> 2.2129896e+08
A55: 256 | B55: 14750 | C55: 17911.75 | D55: 32661.75 | E55: =D55/$D$144 -> 5.9548863e-07 | H55: 256 | I55: =B55+($B$3+$B$140)*E55 -> 15520.811 | J55: =C55+($C$3+$C$140)*E55 -> 18730.317 | K55: =I55*$K$1 -> 5912.2777 | L55: =J55*$K$1 -> 7134.8613
A56: 257 | B56: 33045.88 | C56: 71210.66 | D56: 104256.54 | E56: =D56/$D$144 -> 1.900804e-06 | H56: 257 | I56: =B56+($B$3+$B$140)*E56 -> 35506.314 | J56: =C56+($C$3+$C$140)*E56 -> 73823.531 | K56: =I56*$K$1 -> 13525.272 | L56: =J56*$K$1 -> 28121.289
A57: 258 | B57: 908290.25 | C57: 916545.94 | D57: 1824836.2 | E57: =D57/$D$144 -> 3.3270391e-05 | H57: 258 | I57: =B57+($B$3+$B$140)*E57 -> 951356.03 | J57: =C57+($C$3+$C$140)*E57 -> 962279.87 | K57: =I57*$K$1 -> 362396.08 | L57: =J57*$K$1 -> 366557.25
A58: 259 | B58: 111042.31 | C58: 150289.35 | D58: 261331.66 | E58: =D58/$D$144 -> 4.7645957e-06 | H58: 259 | I58: =B58+($B$3+$B$140)*E58 -> 117209.69 | J58: =C58+($C$3+$C$140)*E58 -> 156838.83 | K58: =I58*$K$1 -> 44648.196 | L58: =J58*$K$1 -> 59743.959
A59: 261 | B59: 3100421.6 | C59: 4734960.6 | D59: 7835382.3 | E59: =D59/$D$144 -> 0.0001428546 | H59: 261 | I59: =B59+($B$3+$B$140)*E59 -> 3285335.2 | J59: =C59+($C$3+$C$140)*E59 -> 4931330.5 | K59: =I59*$K$1 -> 1251469 | L59: =J59*$K$1 -> 1878471.1
... A139: 900 | B139: 16749440 | C139: 13565550 | D139: 30314990 | E139: =D139/$D$144 -> 0.00055270253 | H139: 900 | I139: =B139+($B$3+$B$140)*E139 -> 17464868 | J139: =C139+($C$3+$C$140)*E139 -> 14325302 | K139: =I139*$K$1 -> 6652819.3 | L139: =J139*$K$1 -> 5456877.4
A140: NULL | B140: 2.7819431e+08 | C140: 2.957364e+08 | D140: 5.739307e+08
A141: Total Geral | B141: 2.7643406e+10 | C141: 2.9874279e+10 | D141: 5.7517685e+10 | I141: =SUM(I4:I140) -> 2.7643406e+10 | J141: =SUM(J4:J140) -> 2.9874279e+10 | K141: =SUM(K4:K140) -> 1.0530087e+10 | L141: =SUM(L4:L140) -> 1.1379884e+10
I142: =I141-B141 -> 0 | J142: =J141-C141 -> 0 | K142: =K141-Números!D17 -> 0 | L142: =L141-Números!D18 -> 0
D144: =SUM(D4:D139) -> 5.4848654e+10 | E144: =SUM(E4:E139) -> 1
D145: total sem "0" e null
