Workbook

Sheet Leia-me
B2: Planilha | C2: Descrição
B3: Rend Trab Não Assalariado | C3: Dados obtidos da ficha "Rendimentos Tributáveis Recebidos de Pessoa Física e do Exterior pelo Titular", referentes aos Rendimentos do Trabalho Não Assalariado, provenientes da DIRPF, totalizados por Ocupação: select (ir.ano-1) as 'Ano-Calendário', ir.principal as 'Ocupação', sum(zeroifnull(va_renda)) as 'Total Rendimentos' from u08105524775.gnirpf_irpf_repf as pf, u08105524775.gnirpf_irpf as ir where pf.nu_ident_decl = ir.nu_ident_decl and pf.an_exercicio = ir.ano and lpad(cast(pf.nu_cpf as string),11,'0') = ir.nu_cpf group by 1,2 union select (ir.ano-1) as 'Ano-Calendário', ir.principal as 'Ocupação', sum(zeroifnull(va_renda)) as 'Total Rendimentos' from u08105524775.gnirpf_irpf_repf_ac2023 as pf, u08105524775.gnirpf_irpf_ac2023 as ir where pf.nu_ident_decl = ir.nu_ident_decl and pf.an_exercicio = ir.ano and lpad(cast(pf.nu_cpf as string),11,'0') = ir.nu_cpf group by 1,2
B4: Correção Ocup Não Determinadas | C4: Devido ao alto percentual de declarações com ocupação '000' ("Outras Ocupações") e NULA, foi feita uma correção atribuindo os valores referentes aos rendimentos do trabalho não assalariado às demais ocupações, baseado no percentual do valor de cada ocupação
B5: Totais Rend TNA por Categoria | C5: Totais de Rendimentos do Trabalho Não Assalariado por categorias com direito a redução de alíquota, conforme definido na LC 214/2025 (https://www.planalto.gov.br/ccivil_03/leis/lcp/lcp214.htm)
B6: OBS.: Sobre tabelas utilizadas 1) Tabela de Rendimentos recebidos de pessoa física: cópia de view original da base de dados da DIRPF create table u08105524775.gnirpf_irpf_repf stored as parquet as select * from dbbr_irpf_119_11706_ada.tab_8_aa_irpfmx_rend_pf_view where an_exercicio = <ano>; 2) Tabela de Declarações de IRPF: tabela com dados originários da base de dados da DIRPF, tratados para manter apenas declarações válidas e vigentes, conforme processo utilizado para geração do estudo dos Grandes Números IRPF select * from dbbr_irpf_119_11706_ada.tab_7_aa_irpfmx_declaracao_view where an_exercicio = <ano> and co_situacao_decl not in (85, 80);

Sheet Rend Trab Não Assalariado
A1: Ano-Calendário | B1: Ocupação | C1: Total Rendimentos | E1: Soma de Total Rendimentos | F1: Rótulos de Coluna
A2: 2023 | B2: 0 | C2: 1.4055528e+10 | E2: Rótulos de Linha | F2: 2023 | G2: 2024 | H2: Total Geral
A3: 2024 | B3: 0 | C3: 1.5468314e+10 | E3: 0 | F3: 1.4055528e+10 | G3: 1.5468314e+10 | H3: 29523842604
A4: 2023 | B4: 10 | C4: 9338433.6 | E4: 10 | F4: 9338433.6 | G4: 9587995.4 | H4: 18926429
A5: 2024 | B5: 10 | C5: 9587995.4 | E5: 20 | F5: 12758227 | G5: 13441167 | H5: 26199394
A6: 2023 | B6: 20 | C6: 12758227 | E6: 30 | F6: 5904522.9 | G6: 7259005.9 | H6: 13163529
A7: 2024 | B7: 20 | C7: 13441167 | E7: 40 | F7: 22216650 | G7: 19358249 | H7: 41574899
A8: 2023 | B8: 30 | C8: 5904522.9 | E8: 50 | F8: 17087686 | G8: 22642785 | H8: 39730471
A9: 2024 | B9: 30 | C9: 7259005.9 | E9: 101 | F9: 12952139 | G9: 13299949 | H9: 26252088
A10: 2023 | B10: 40 | C10: 22216650 | E10: 102 | F10: 37864261 | G10: 46618052 | H10: 84482313
A11: 2024 | B11: 40 | C11: 19358249 | E11: 103 | F11: 7396350.6 | G11: 6593270.4 | H11: 13989621
A12: 2023 | B12: 50 | C12: 17087686 | E12: 104 | F12: 23944201 | G12: 31194993 | H12: 55139194
A13: 2024 | B13: 50 | C13: 22642785 | E13: 105 | F13: 17519638 | G13: 18129015 | H13: 35648653
A14: 2023 | B14: 101 | C14: 12952139 | E14: 106 | F14: 1152421.9 | G14: 884371.6 | H14: 2036793.5
... A43: 2024 | B43: 115 | C43: 2172993.4 | E43: 228 | F43: 2.229935e+08 | G43: 2.2374165e+08 | H43: 4.4673515e+08
A44: 2023 | B44: 116 | C44: 40706113 | E44: 229 | F44: 1.9885598e+09 | H44: 1.9885598e+09
A45: 2024 | B45: 116 | C45: 46503561 | E45: 230 | G45: 3.3595447e+08 | H45: 3.3595447e+08
A46: 2023 | B46: 117 | C46: 1.866156e+10 | E46: 231 | G46: 1.3690989e+09 | H46: 1.3690989e+09
A47: 2024 | B47: 117 | C47: 2.1551212e+10 | E47: 232 | G47: 105550389 | H47: 105550389
A48: 2023 | B48: 118 | C48: 7931147 | E48: 241 | F48: 1.9435946e+09 | G48: 2.2017309e+09 | H48: 4.1453255e+09
A49: 2024 | B49: 118 | C49: 9769247.7 | E49: 250 | F49: 2068651.1 | G49: 1394623.3 | H49: 3463274.4
A50: 2023 | B50: 120 | C50: 6.1155302e+09 | E50: 251 | F50: 696438.81 | G50: 576984.87 | H50: 1273423.7
A51: 2024 | B51: 120 | C51: 6.6827014e+09 | E51: 252 | F51: 4.5718217e+08 | G51: 4.74876e+08 | H51: 9.3205817e+08
A52: 2023 | B52: 121 | C52: 20239642 | E52: 253 | F52: 62139217 | G52: 75003519 | H52: 1.3714274e+08
A53: 2024 | B53: 121 | C53: 24816822 | E53: 254 | F53: 68904434 | G53: 75400951 | H53: 1.4430538e+08
A54: 2023 | B54: 130 | C54: 5.722635e+08 | E54: 255 | F54: 2.5517901e+09 | G54: 2.9961335e+09 | H54: 5.5479236e+09
A55: 2024 | B55: 130 | C55: 5.9155456e+08 | E55: 256 | F55: 844681.17 | G55: 1057799.1 | H55: 1902480.3
A56: 2023 | B56: 131 | C56: 13916910 | E56: 257 | F56: 786425.88 | G56: 667704.82 | H56: 1454130.7
A57: 2024 | B57: 131 | C57: 10141049 | E57: 258 | F57: 7745979.1 | G57: 9405280.8 | H57: 17151260
A58: 2023 | B58: 140 | C58: 26175867 | E58: 259 | F58: 677635.42 | G58: 771109.12 | H58: 1448744.5
A59: 2024 | B59: 140 | C59: 24186205 | E59: 261 | F59: 22257654 | G59: 24097620 | H59: 46355274
... A139: 2024 | B139: 291 | C139: 63070843 | E139: 900 | F139: 3.3660304e+08 | G139: 3.2906425e+08 | H139: 665667286
A140: 2023 | B140: 292 | C140: 43797264 | E140: NULL | F140: 3.3898535e+09 | G140: 3.6717366e+09 | H140: 7.0615901e+09
A141: 2024 | B141: 292 | C141: 43625567 | E141: Total Geral | F141: 7.5404564e+10 | G141: 8.2363429e+10 | H141: 1.5776799e+11
A142: 2023 | B142: 293 | C142: 17297598
A143: 2024 | B143: 293 | C143: 17904564
A144: 2023 | B144: 294 | C144: 1.2721629e+08
A145: 2024 | B145: 294 | C145: 1.3178199e+08
A146: 2023 | B146: 295 | C146: 1.2665024e+08
A147: 2024 | B147: 295 | C147: 1.3335903e+08
...

Sheet Correção Ocup Não Determinadas
A1: Ocupação | B1: 2023 | C1: 2024 | D1: Percentual Corrigido 2023 | E1: Percentual Corrigido 2024 | F1: Valor Corrigido 2023 | G1: Valor Corrigido 2024
A2: 0 | B2: 1.4055528e+10 | C2: 1.5468314e+10 | D2: - | E2: - | F2: - | G2: -
A3: 10 | B3: 9338433.6 | C3: 9587995.4 | D3: =B3/$B$141 -> 0.00016112087 | E3: =C3/$C$141 -> 0.00015165269 | F3: =B3+(D3*$B$2)+(D3*$B$139) -> 12149249 | G3: =C3+(E3*$C$2)+(E3*$C$139) -> 12490636
A4: 20 | B4: 12758227 | C4: 13441167 | D4: =B4/$B$141 -> 0.00022012434 | E4: =C4/$C$141 -> 0.00021259805 | F4: =B4+(D4*$B$2)+(D4*$B$139) -> 16598380 | G4: =C4+(E4*$C$2)+(E4*$C$139) -> 17510304
A5: 30 | B5: 5904522.9 | C5: 7259005.9 | D5: =B5/$B$141 -> 0.00010187381 | E5: =C5/$C$141 -> 0.00011481522 | F5: =B5+(D5*$B$2)+(D5*$B$139) -> 7681750.4 | G5: =C5+(E5*$C$2)+(E5*$C$139) -> 9456575
A6: 40 | B6: 22216650 | C6: 19358249 | D6: =B6/$B$141 -> 0.00038331545 | E6: =C6/$C$141 -> 0.00030618814 | F6: =B6+(D6*$B$2)+(D6*$B$139) -> 28903734 | G6: =C6+(E6*$C$2)+(E6*$C$139) -> 25218705
A7: 50 | B7: 17087686 | C7: 22642785 | D7: =B7/$B$141 -> 0.00029482276 | E7: =C7/$C$141 -> 0.00035813943 | F7: =B7+(D7*$B$2)+(D7*$B$139) -> 22230982 | G7: =C7+(E7*$C$2)+(E7*$C$139) -> 29497592
A8: 101 | B8: 12952139 | C8: 13299949 | D8: =B8/$B$141 -> 0.00022347001 | E8: =C8/$C$141 -> 0.00021036442 | F8: =B8+(D8*$B$2)+(D8*$B$139) -> 16850658 | G8: =C8+(E8*$C$2)+(E8*$C$139) -> 17326335
A9: 102 | B9: 37864261 | C9: 46618052 | D9: =B9/$B$141 -> 0.00065329185 | E9: =C9/$C$141 -> 0.00073735464 | F9: =B9+(D9*$B$2)+(D9*$B$139) -> 49261187 | G9: =C9+(E9*$C$2)+(E9*$C$139) -> 60731057
A10: 103 | B10: 7396350.6 | C10: 6593270.4 | D10: =B10/$B$141 -> 0.00012761309 | E10: =C10/$C$141 -> 0.00010428532 | F10: =B10+(D10*$B$2)+(D10*$B$139) -> 9622609.8 | G10: =C10+(E10*$C$2)+(E10*$C$139) -> 8589296.8
A11: 104 | B11: 23944201 | C11: 31194993 | D11: =B11/$B$141 -> 0.00041312179 | E11: =C11/$C$141 -> 0.00049340915 | F11: =B11+(D11*$B$2)+(D11*$B$139) -> 31151268 | G11: =C11+(E11*$C$2)+(E11*$C$139) -> 40638869
A12: 105 | B12: 17519638 | C12: 18129015 | D12: =B12/$B$141 -> 0.00030227546 | E12: =C12/$C$141 -> 0.00028674543 | F12: =B12+(D12*$B$2)+(D12*$B$139) -> 22792949 | G12: =C12+(E12*$C$2)+(E12*$C$139) -> 23617337
A13: 106 | B13: 1152421.9 | C13: 884371.6 | D13: =B13/$B$141 -> 1.9883336e-05 | E13: =C13/$C$141 -> 1.3988047e-05 | F13: =B13+(D13*$B$2)+(D13*$B$139) -> 1499294.3 | G13: =C13+(E13*$C$2)+(E13*$C$139) -> 1152103.5
A14: 107 | B14: 5879819.6 | C14: 10551342 | D14: =B14/$B$141 -> 0.00010144759 | E14: =C14/$C$141 -> 0.00016688987 | F14: =B14+(D14*$B$2)+(D14*$B$139) -> 7649611.6 | G14: =C14+(E14*$C$2)+(E14*$C$139) -> 13745622
... A42: 228 | B42: 2.229935e+08 | C42: 2.2374165e+08 | D42: =B42/$B$141 -> 0.0038474232 | E42: =C42/$C$141 -> 0.0035389069 | F42: =B42+(D42*$B$2)+(D42*$B$139) -> 2.9011327e+08 | G42: =C42+(E42*$C$2)+(E42*$C$139) -> 2.9147651e+08
A43: 229 | B43: 1.9885598e+09 | D43: =B43/$B$141 -> 0.03430966 | E43: =C43/$C$141 -> 0 | F43: =B43+(D43*$B$2)+(D43*$B$139) -> 2.5871049e+09 | G43: =C43+(E43*$C$2)+(E43*$C$139) -> 0
A44: 230 | C44: 3.3595447e+08 | D44: =B44/$B$141 -> 0 | E44: =C44/$C$141 -> 0.0053137697 | F44: =B44+(D44*$B$2)+(D44*$B$139) -> 0 | G44: =C44+(E44*$C$2)+(E44*$C$139) -> 4.3766029e+08
A45: 231 | C45: 1.3690989e+09 | D45: =B45/$B$141 -> 0 | E45: =C45/$C$141 -> 0.021654947 | F45: =B45+(D45*$B$2)+(D45*$B$139) -> 0 | G45: =C45+(E45*$C$2)+(E45*$C$139) -> 1.7835757e+09
A46: 232 | C46: 105550389 | D46: =B46/$B$141 -> 0 | E46: =C46/$C$141 -> 0.0016694835 | F46: =B46+(D46*$B$2)+(D46*$B$139) -> 0 | G46: =C46+(E46*$C$2)+(E46*$C$139) -> 1.3750439e+08
A47: 241 | B47: 1.9435946e+09 | C47: 2.2017309e+09 | D47: =B47/$B$141 -> 0.033533851 | E47: =C47/$C$141 -> 0.034824632 | F47: =B47+(D47*$B$2)+(D47*$B$139) -> 2.5286054e+09 | G47: =C47+(E47*$C$2)+(E47*$C$139) -> 2.8682761e+09
A48: 250 | B48: 2068651.1 | C48: 1394623.3 | D48: =B48/$B$141 -> 3.5691517e-05 | E48: =C48/$C$141 -> 2.2058664e-05 | F48: =B48+(D48*$B$2)+(D48*$B$139) -> 2691303.3 | G48: =C48+(E48*$C$2)+(E48*$C$139) -> 1816827.2
A49: 251 | B49: 696438.81 | C49: 576984.87 | D49: =B49/$B$141 -> 1.2016022e-05 | E49: =C49/$C$141 -> 9.1261316e-06 | F49: =B49+(D49*$B$2)+(D49*$B$139) -> 906062.9 | G49: =C49+(E49*$C$2)+(E49*$C$139) -> 751659.49
A50: 252 | B50: 4.5718217e+08 | C50: 4.74876e+08 | D50: =B50/$B$141 -> 0.0078880023 | E50: =C50/$C$141 -> 0.0075110823 | F50: =B50+(D50*$B$2)+(D50*$B$139) -> 5.9479138e+08 | G50: =C50+(E50*$C$2)+(E50*$C$139) -> 6.186385e+08
A51: 253 | B51: 62139217 | C51: 75003519 | D51: =B51/$B$141 -> 0.0010721203 | E51: =C51/$C$141 -> 0.0011863257 | F51: =B51+(D51*$B$2)+(D51*$B$139) -> 80842765 | G51: =C51+(E51*$C$2)+(E51*$C$139) -> 97709853
A52: 254 | B52: 68904434 | C52: 75400951 | D52: =B52/$B$141 -> 0.0011888441 | E52: =C52/$C$141 -> 0.0011926119 | F52: =B52+(D52*$B$2)+(D52*$B$139) -> 89644274 | G52: =C52+(E52*$C$2)+(E52*$C$139) -> 98227602
A53: 255 | B53: 2.5517901e+09 | C53: 2.9961335e+09 | D53: =B53/$B$141 -> 0.044027365 | E53: =C53/$C$141 -> 0.047389646 | F53: =B53+(D53*$B$2)+(D53*$B$139) -> 3.3198642e+09 | G53: =C53+(E53*$C$2)+(E53*$C$139) -> 3.9031737e+09
A54: 256 | B54: 844681.17 | C54: 1057799.1 | D54: =B54/$B$141 -> 1.4573725e-05 | E54: =C54/$C$141 -> 1.6731139e-05 | F54: =B54+(D54*$B$2)+(D54*$B$139) -> 1098925.4 | G54: =C54+(E54*$C$2)+(E54*$C$139) -> 1378033.9
A55: 257 | B55: 786425.88 | C55: 667704.82 | D55: =B55/$B$141 -> 1.3568616e-05 | E55: =C55/$C$141 -> 1.0561043e-05 | F55: =B55+(D55*$B$2)+(D55*$B$139) -> 1023135.6 | G55: =C55+(E55*$C$2)+(E55*$C$139) -> 869843.72
A56: 258 | B56: 7745979.1 | C56: 9405280.8 | D56: =B56/$B$141 -> 0.00013364542 | E56: =C56/$C$141 -> 0.00014876271 | F56: =B56+(D56*$B$2)+(D56*$B$139) -> 10077474 | G56: =C56+(E56*$C$2)+(E56*$C$139) -> 12252607
A57: 259 | B57: 677635.42 | C57: 771109.12 | D57: =B57/$B$141 -> 1.1691597e-05 | E57: =C57/$C$141 -> 1.2196582e-05 | F57: =B57+(D57*$B$2)+(D57*$B$139) -> 881599.8 | G57: =C57+(E57*$C$2)+(E57*$C$139) -> 1004552.3
A58: 261 | B58: 22257654 | C58: 24097620 | D58: =B58/$B$141 -> 0.00038402292 | E58: =C58/$C$141 -> 0.00038115046 | F58: =B58+(D58*$B$2)+(D58*$B$139) -> 28957081 | G58: =C58+(E58*$C$2)+(E58*$C$139) -> 31392859
... A138: 900 | B138: 3.3660304e+08 | C138: 3.2906425e+08 | D138: =B138/$B$141 -> 0.0058075878 | E138: =C138/$C$141 -> 0.0052047875 | F138: =B138+(D138*$B$2)+(D138*$B$139) -> 4.3791862e+08 | G138: =C138+(E138*$C$2)+(E138*$C$139) -> 4.2868414e+08
A139: NULL | B139: 3.3898535e+09 | C139: 3.6717366e+09 | D139: - | E139: - | F139: - | G139: -
A140: Total Não Determinadas | B140: =B2+B139 -> 1.7445382e+10 | C140: =C2+C139 -> 1.9140051e+10 | D140: - | E140: - | F140: - | G140: -
A141: Total Determinadas | B141: =SUM(B3:B138) -> 5.7959182e+10 | C141: =SUM(C3:C138) -> 6.3223378e+10 | D141: - | E141: - | F141: - | G141: -
A142: Total Geral | B142: 7.5404564e+10 | C142: 8.2363429e+10 | D142: - | E142: - | F142: =SUM(F3:F141) -> 7.5404564e+10 | G142: =SUM(G3:G141) -> 8.2363429e+10
A143: Percentual Não Determinadas | B143: =B140/B142 -> 0.23135711 | C143: =C140/C142 -> 0.23238531

Sheet Totais Rend TNA por Categoria
L1: Valor destinado a Consumo Intermediário | N1: BC Créditos Livro Caixa
A2: Código | B2: Descrição | C2: Categoria | D2: Valor Rend TNA 2023 | E2: Valor Rend TNA 2024 | F2: Atividade de Divulgação - SCN 2010 | H2: Classe Cnae 2.0 (4 dígitos) | J2: % Consumo Final Contas Nacionais | K2: % Consumo Intermediáro | L2: 2023 | M2: 2024 | N2: 2023 | O2: 2024
A3: 0 | B3: OUTRAS OCUPAÇÕES NÃO ESPECIFICADAS ANTERIORMENTE | C3: NA | D3: =VLOOKUP(A3,'Correção Ocup Não Determinadas'!A:G,6,FALSE) -> - | E3: =VLOOKUP(A3,'Correção Ocup Não Determinadas'!A:G,7,FALSE) -> - | J3: =IFERROR(VLOOKUP(F3,'[1]Prod-CNAE-CF'!$A$5:$H$72,8,FALSE),'estimativa bc débitos'!$K$17) -> 0.5 | K3: =1-J3 -> 0.5 | N3: =IFERROR(VLOOKUP(A3,'[2]estim bc créditos'!$H$4:$L$139,4,FALSE),0) -> 0 | O3: =IFERROR(VLOOKUP(A3,'[2]estim bc créditos'!$H$4:$L$139,5,FALSE),0) -> 0
A4: 10 | B4: MILITAR DA AERONÁUTICA | C4: NA | D4: =VLOOKUP(A4,'Correção Ocup Não Determinadas'!A:G,6,FALSE) -> 12149249 | E4: =VLOOKUP(A4,'Correção Ocup Não Determinadas'!A:G,7,FALSE) -> 12490636 | J4: =IFERROR(VLOOKUP(F4,'[1]Prod-CNAE-CF'!$A$5:$H$72,8,FALSE),'estimativa bc débitos'!$K$17) -> 0.5 | K4: =1-J4 -> 0.5 | L4: =D4*$K4 -> 6074624.3 | M4: =E4*$K4 -> 6245317.8 | N4: =IFERROR(VLOOKUP(A4,'[2]estim bc créditos'!$H$4:$L$139,4,FALSE),0) -> 2232467.9 | O4: =IFERROR(VLOOKUP(A4,'[2]estim bc créditos'!$H$4:$L$139,5,FALSE),0) -> 2030681.3
A5: 20 | B5: MILITAR DO EXÉRCITO | C5: NA | D5: =VLOOKUP(A5,'Correção Ocup Não Determinadas'!A:G,6,FALSE) -> 16598380 | E5: =VLOOKUP(A5,'Correção Ocup Não Determinadas'!A:G,7,FALSE) -> 17510304 | J5: =IFERROR(VLOOKUP(F5,'[1]Prod-CNAE-CF'!$A$5:$H$72,8,FALSE),'estimativa bc débitos'!$K$17) -> 0.5 | K5: =1-J5 -> 0.5 | L5: =D5*$K5 -> 8299190.1 | M5: =E5*$K5 -> 8755152.2 | N5: =IFERROR(VLOOKUP(A5,'[2]estim bc créditos'!$H$4:$L$139,4,FALSE),0) -> 2178551.4 | O5: =IFERROR(VLOOKUP(A5,'[2]estim bc créditos'!$H$4:$L$139,5,FALSE),0) -> 2147569.4
A6: 30 | B6: MILITAR DA MARINHA | C6: NA | D6: =VLOOKUP(A6,'Correção Ocup Não Determinadas'!A:G,6,FALSE) -> 7681750.4 | E6: =VLOOKUP(A6,'Correção Ocup Não Determinadas'!A:G,7,FALSE) -> 9456575 | J6: =IFERROR(VLOOKUP(F6,'[1]Prod-CNAE-CF'!$A$5:$H$72,8,FALSE),'estimativa bc débitos'!$K$17) -> 0.5 | K6: =1-J6 -> 0.5 | L6: =D6*$K6 -> 3840875.2 | M6: =E6*$K6 -> 4728287.5 | N6: =IFERROR(VLOOKUP(A6,'[2]estim bc créditos'!$H$4:$L$139,4,FALSE),0) -> 691740.37 | O6: =IFERROR(VLOOKUP(A6,'[2]estim bc créditos'!$H$4:$L$139,5,FALSE),0) -> 683459.45
A7: 40 | B7: POLICIAL MILITAR | C7: NA | D7: =VLOOKUP(A7,'Correção Ocup Não Determinadas'!A:G,6,FALSE) -> 28903734 | E7: =VLOOKUP(A7,'Correção Ocup Não Determinadas'!A:G,7,FALSE) -> 25218705 | J7: =IFERROR(VLOOKUP(F7,'[1]Prod-CNAE-CF'!$A$5:$H$72,8,FALSE),'estimativa bc débitos'!$K$17) -> 0.5 | K7: =1-J7 -> 0.5 | L7: =D7*$K7 -> 14451867 | M7: =E7*$K7 -> 12609353 | N7: =IFERROR(VLOOKUP(A7,'[2]estim bc créditos'!$H$4:$L$139,4,FALSE),0) -> 4142125.7 | O7: =IFERROR(VLOOKUP(A7,'[2]estim bc créditos'!$H$4:$L$139,5,FALSE),0) -> 3712413.8
A8: 50 | B8: BOMBEIRO MILITAR | C8: NA | D8: =VLOOKUP(A8,'Correção Ocup Não Determinadas'!A:G,6,FALSE) -> 22230982 | E8: =VLOOKUP(A8,'Correção Ocup Não Determinadas'!A:G,7,FALSE) -> 29497592 | J8: =IFERROR(VLOOKUP(F8,'[1]Prod-CNAE-CF'!$A$5:$H$72,8,FALSE),'estimativa bc débitos'!$K$17) -> 0.5 | K8: =1-J8 -> 0.5 | L8: =D8*$K8 -> 11115491 | M8: =E8*$K8 -> 14748796 | N8: =IFERROR(VLOOKUP(A8,'[2]estim bc créditos'!$H$4:$L$139,4,FALSE),0) -> 3849709.6 | O8: =IFERROR(VLOOKUP(A8,'[2]estim bc créditos'!$H$4:$L$139,5,FALSE),0) -> 4526636.6
A9: 101 | B9: MEMBRO DO PODER EXECUTIVO (PRESIDENTE DA REPÚBLICA, VICE-PRESIDENTE DA REPÚBLICA, MINISTRO DE ESTADO, GOVERNADOR, VICE-GOVERNADOR, PREFEITO, VICE-PREFEITO) | C9: NA | D9: =VLOOKUP(A9,'Correção Ocup Não Determinadas'!A:G,6,FALSE) -> 16850658 | E9: =VLOOKUP(A9,'Correção Ocup Não Determinadas'!A:G,7,FALSE) -> 17326335 | J9: =IFERROR(VLOOKUP(F9,'[1]Prod-CNAE-CF'!$A$5:$H$72,8,FALSE),'estimativa bc débitos'!$K$17) -> 0.5 | K9: =1-J9 -> 0.5 | L9: =D9*$K9 -> 8425329.2 | M9: =E9*$K9 -> 8663167.5 | N9: =IFERROR(VLOOKUP(A9,'[2]estim bc créditos'!$H$4:$L$139,4,FALSE),0) -> 2293713 | O9: =IFERROR(VLOOKUP(A9,'[2]estim bc créditos'!$H$4:$L$139,5,FALSE),0) -> 1924768.3
A10: 102 | B10: MEMBRO DO PODER JUDICIÁRIO (MINISTRO, JUIZ E DESEMBARGADOR) E DE TRIBUNAL DE CONTAS (MINISTRO E CONSELHEIRO) | C10: NA | D10: =VLOOKUP(A10,'Correção Ocup Não Determinadas'!A:G,6,FALSE) -> 49261187 | E10: =VLOOKUP(A10,'Correção Ocup Não Determinadas'!A:G,7,FALSE) -> 60731057 | J10: =IFERROR(VLOOKUP(F10,'[1]Prod-CNAE-CF'!$A$5:$H$72,8,FALSE),'estimativa bc débitos'!$K$17) -> 0.5 | K10: =1-J10 -> 0.5 | L10: =D10*$K10 -> 24630594 | M10: =E10*$K10 -> 30365529 | N10: =IFERROR(VLOOKUP(A10,'[2]estim bc créditos'!$H$4:$L$139,4,FALSE),0) -> 5212293.7 | O10: =IFERROR(VLOOKUP(A10,'[2]estim bc créditos'!$H$4:$L$139,5,FALSE),0) -> 10462236
A11: 103 | B11: MEMBRO DO PODER LEGISLATIVO (SENADOR, DEPUTADO FEDERAL, DEPUTADO ESTADUAL E VEREADOR) | C11: NA | D11: =VLOOKUP(A11,'Correção Ocup Não Determinadas'!A:G,6,FALSE) -> 9622609.8 | E11: =VLOOKUP(A11,'Correção Ocup Não Determinadas'!A:G,7,FALSE) -> 8589296.8 | J11: =IFERROR(VLOOKUP(F11,'[1]Prod-CNAE-CF'!$A$5:$H$72,8,FALSE),'estimativa bc débitos'!$K$17) -> 0.5 | K11: =1-J11 -> 0.5 | L11: =D11*$K11 -> 4811304.9 | M11: =E11*$K11 -> 4294648.4 | N11: =IFERROR(VLOOKUP(A11,'[2]estim bc créditos'!$H$4:$L$139,4,FALSE),0) -> 974264.23 | O11: =IFERROR(VLOOKUP(A11,'[2]estim bc créditos'!$H$4:$L$139,5,FALSE),0) -> 614573.84
A12: 104 | B12: MEMBRO DO MINISTÉRIO PÚBLICO (PROCURADOR E PROMOTOR) | C12: NA | D12: =VLOOKUP(A12,'Correção Ocup Não Determinadas'!A:G,6,FALSE) -> 31151268 | E12: =VLOOKUP(A12,'Correção Ocup Não Determinadas'!A:G,7,FALSE) -> 40638869 | J12: =IFERROR(VLOOKUP(F12,'[1]Prod-CNAE-CF'!$A$5:$H$72,8,FALSE),'estimativa bc débitos'!$K$17) -> 0.5 | K12: =1-J12 -> 0.5 | L12: =D12*$K12 -> 15575634 | M12: =E12*$K12 -> 20319435 | N12: =IFERROR(VLOOKUP(A12,'[2]estim bc créditos'!$H$4:$L$139,4,FALSE),0) -> 4378475.1 | O12: =IFERROR(VLOOKUP(A12,'[2]estim bc créditos'!$H$4:$L$139,5,FALSE),0) -> 5963356.8
A13: 105 | B13: DIRIGENTE SUPERIOR DA ADMINISTRAÇÃO PÚBLICA (OCUPANTE DE CARGO DE DIREÇÃO, CHEFIA, ASSESSORIA E DE NATUREZA ESPECIAL), INCLUSIVE OS DAS FUNDAÇÕES PÚBLICAS E AUTARQUIAS | C13: NA | D13: =VLOOKUP(A13,'Correção Ocup Não Determinadas'!A:G,6,FALSE) -> 22792949 | E13: =VLOOKUP(A13,'Correção Ocup Não Determinadas'!A:G,7,FALSE) -> 23617337 | J13: =IFERROR(VLOOKUP(F13,'[1]Prod-CNAE-CF'!$A$5:$H$72,8,FALSE),'estimativa bc débitos'!$K$17) -> 0.5 | K13: =1-J13 -> 0.5 | L13: =D13*$K13 -> 11396475 | M13: =E13*$K13 -> 11808668 | N13: =IFERROR(VLOOKUP(A13,'[2]estim bc créditos'!$H$4:$L$139,4,FALSE),0) -> 881863.02 | O13: =IFERROR(VLOOKUP(A13,'[2]estim bc créditos'!$H$4:$L$139,5,FALSE),0) -> 974704.01
A14: 106 | B14: DIPLOMATA E AFINS | C14: NA | D14: =VLOOKUP(A14,'Correção Ocup Não Determinadas'!A:G,6,FALSE) -> 1499294.3 | E14: =VLOOKUP(A14,'Correção Ocup Não Determinadas'!A:G,7,FALSE) -> 1152103.5 | J14: =IFERROR(VLOOKUP(F14,'[1]Prod-CNAE-CF'!$A$5:$H$72,8,FALSE),'estimativa bc débitos'!$K$17) -> 0.5 | K14: =1-J14 -> 0.5 | L14: =D14*$K14 -> 749647.16 | M14: =E14*$K14 -> 576051.77 | N14: =IFERROR(VLOOKUP(A14,'[2]estim bc créditos'!$H$4:$L$139,4,FALSE),0) -> 11232.199 | O14: =IFERROR(VLOOKUP(A14,'[2]estim bc créditos'!$H$4:$L$139,5,FALSE),0) -> 4736.2282
A15: 107 | B15: SERVIDOR DAS CARREIRAS DO PODER LEGISLATIVO | C15: NA | D15: =VLOOKUP(A15,'Correção Ocup Não Determinadas'!A:G,6,FALSE) -> 7649611.6 | E15: =VLOOKUP(A15,'Correção Ocup Não Determinadas'!A:G,7,FALSE) -> 13745622 | J15: =IFERROR(VLOOKUP(F15,'[1]Prod-CNAE-CF'!$A$5:$H$72,8,FALSE),'estimativa bc débitos'!$K$17) -> 0.5 | K15: =1-J15 -> 0.5 | L15: =D15*$K15 -> 3824805.8 | M15: =E15*$K15 -> 6872811.1 | N15: =IFERROR(VLOOKUP(A15,'[2]estim bc créditos'!$H$4:$L$139,4,FALSE),0) -> 275833.58 | O15: =IFERROR(VLOOKUP(A15,'[2]estim bc créditos'!$H$4:$L$139,5,FALSE),0) -> 1326618.9
... A24: 116 | B24: SERVIDOR DAS DEMAIS CARREIRAS DA ADMINISTRAÇÃO PÚBLICA DIRETA, AUTÁRQUICA E FUNDACIONAL | C24: NA | D24: =VLOOKUP(A24,'Correção Ocup Não Determinadas'!A:G,6,FALSE) -> 52958420 | E24: =VLOOKUP(A24,'Correção Ocup Não Determinadas'!A:G,7,FALSE) -> 60581906 | J24: =IFERROR(VLOOKUP(F24,'[1]Prod-CNAE-CF'!$A$5:$H$72,8,FALSE),'estimativa bc débitos'!$K$17) -> 0.5 | K24: =1-J24 -> 0.5 | L24: =D24*$K24 -> 26479210 | M24: =E24*$K24 -> 30290953 | N24: =IFERROR(VLOOKUP(A24,'[2]estim bc créditos'!$H$4:$L$139,4,FALSE),0) -> 5848022.4 | O24: =IFERROR(VLOOKUP(A24,'[2]estim bc créditos'!$H$4:$L$139,5,FALSE),0) -> 7004671.8
A25: 117 | B25: TITULAR DE CARTÓRIO | C25: TITULAR DE CARTÓRIO | D25: =VLOOKUP(A25,'Correção Ocup Não Determinadas'!A:G,6,FALSE) -> 2.4278582e+10 | E25: =VLOOKUP(A25,'Correção Ocup Não Determinadas'!A:G,7,FALSE) -> 2.807556e+10 | F25: 6980 | G25: Atividades jurídicas, contábeis, consultoria e sedes de empresas | H25: 6912 | I25: Cartórios | J25: =IFERROR(VLOOKUP(F25,'[1]Prod-CNAE-CF'!$A$5:$H$72,8,FALSE),'estimativa bc débitos'!$K$17) -> 0.07745464 | K25: =1-J25 -> 0.92254536 | L25: =D25*$K25 -> 2.2398093e+10 | M25: =E25*$K25 -> 2.5900978e+10 | N25: =IFERROR(VLOOKUP(A25,'[2]estim bc créditos'!$H$4:$L$139,4,FALSE),0) -> 4.2483188e+09 | O25: =IFERROR(VLOOKUP(A25,'[2]estim bc créditos'!$H$4:$L$139,5,FALSE),0) -> 4.794143e+09
A26: 118 | B26: DIRIGENTE OU ADMINISTRADOR DE PARTIDO POLÍTICO, ORGANIZAÇÃO PATRONAL, SINDICAL, FILANTRÓPICA E RELIGIOSA | C26: NA | D26: =VLOOKUP(A26,'Correção Ocup Não Determinadas'!A:G,6,FALSE) -> 10318377 | E26: =VLOOKUP(A26,'Correção Ocup Não Determinadas'!A:G,7,FALSE) -> 12726760 | J26: =IFERROR(VLOOKUP(F26,'[1]Prod-CNAE-CF'!$A$5:$H$72,8,FALSE),'estimativa bc débitos'!$K$17) -> 0.5 | K26: =1-J26 -> 0.5 | L26: =D26*$K26 -> 5159188.4 | M26: =E26*$K26 -> 6363379.8 | N26: =IFERROR(VLOOKUP(A26,'[2]estim bc créditos'!$H$4:$L$139,4,FALSE),0) -> 261474.03 | O26: =IFERROR(VLOOKUP(A26,'[2]estim bc créditos'!$H$4:$L$139,5,FALSE),0) -> 227721.58
A27: 120 | B27: DIRIGENTE, PRESIDENTE E DIRETOR DE EMPRESA INDUSTRIAL, COMERCIAL OU PRESTADORA DE SERVIÇOS | C27: NA | D27: =VLOOKUP(A27,'Correção Ocup Não Determinadas'!A:G,6,FALSE) -> 7.9562697e+09 | E27: =VLOOKUP(A27,'Correção Ocup Não Determinadas'!A:G,7,FALSE) -> 8.7058018e+09 | J27: =IFERROR(VLOOKUP(F27,'[1]Prod-CNAE-CF'!$A$5:$H$72,8,FALSE),'estimativa bc débitos'!$K$17) -> 0.5 | K27: =1-J27 -> 0.5 | L27: =D27*$K27 -> 3.9781349e+09 | M27: =E27*$K27 -> 4.3529009e+09 | N27: =IFERROR(VLOOKUP(A27,'[2]estim bc créditos'!$H$4:$L$139,4,FALSE),0) -> 2.8378916e+08 | O27: =IFERROR(VLOOKUP(A27,'[2]estim bc créditos'!$H$4:$L$139,5,FALSE),0) -> 3.2055414e+08
A28: 121 | B28: PRESIDENTE E DIRETOR DE EMPRESA PÚBLICA E SOCIEDADE DE ECONOMIA MISTA | C28: NA | D28: =VLOOKUP(A28,'Correção Ocup Não Determinadas'!A:G,6,FALSE) -> 26331658 | E28: =VLOOKUP(A28,'Correção Ocup Não Determinadas'!A:G,7,FALSE) -> 32329791 | J28: =IFERROR(VLOOKUP(F28,'[1]Prod-CNAE-CF'!$A$5:$H$72,8,FALSE),'estimativa bc débitos'!$K$17) -> 0.5 | K28: =1-J28 -> 0.5 | L28: =D28*$K28 -> 13165829 | M28: =E28*$K28 -> 16164895 | N28: =IFERROR(VLOOKUP(A28,'[2]estim bc créditos'!$H$4:$L$139,4,FALSE),0) -> 1015938.1 | O28: =IFERROR(VLOOKUP(A28,'[2]estim bc créditos'!$H$4:$L$139,5,FALSE),0) -> 685546.24
A29: 130 | B29: GERENTE OU SUPERVISOR DE EMPRESA INDUSTRIAL, COMERCIAL OU PRESTADORA DE SERVIÇOS | C29: NA | D29: =VLOOKUP(A29,'Correção Ocup Não Determinadas'!A:G,6,FALSE) -> 7.4451153e+08 | E29: =VLOOKUP(A29,'Correção Ocup Não Determinadas'!A:G,7,FALSE) -> 7.7063997e+08 | J29: =IFERROR(VLOOKUP(F29,'[1]Prod-CNAE-CF'!$A$5:$H$72,8,FALSE),'estimativa bc débitos'!$K$17) -> 0.5 | K29: =1-J29 -> 0.5 | L29: =D29*$K29 -> 3.7225577e+08 | M29: =E29*$K29 -> 3.8531998e+08 | N29: =IFERROR(VLOOKUP(A29,'[2]estim bc créditos'!$H$4:$L$139,4,FALSE),0) -> 23846798 | O29: =IFERROR(VLOOKUP(A29,'[2]estim bc créditos'!$H$4:$L$139,5,FALSE),0) -> 20358469
A30: 131 | B30: GERENTE OU SUPERVISOR DE EMPRESA PÚBLICA E SOCIEDADE DE ECONOMIA MISTA | C30: NA | D30: =VLOOKUP(A30,'Correção Ocup Não Determinadas'!A:G,6,FALSE) -> 18105821 | E30: =VLOOKUP(A30,'Correção Ocup Não Determinadas'!A:G,7,FALSE) -> 13211119 | J30: =IFERROR(VLOOKUP(F30,'[1]Prod-CNAE-CF'!$A$5:$H$72,8,FALSE),'estimativa bc débitos'!$K$17) -> 0.5 | K30: =1-J30 -> 0.5 | L30: =D30*$K30 -> 9052910.4 | M30: =E30*$K30 -> 6605559.7 | N30: =IFERROR(VLOOKUP(A30,'[2]estim bc créditos'!$H$4:$L$139,4,FALSE),0) -> 663342.83 | O30: =IFERROR(VLOOKUP(A30,'[2]estim bc créditos'!$H$4:$L$139,5,FALSE),0) -> 704102.49
A31: 140 | B31: PRESIDENTE, DIRETOR, GERENTE E SUPERVISOR DE ORGANISMO INTERNACIONAL E DE ORGANIZAÇÃO NÃO-GOVERNAMENTAL | C31: NA | D31: =VLOOKUP(A31,'Correção Ocup Não Determinadas'!A:G,6,FALSE) -> 34054652 | E31: =VLOOKUP(A31,'Correção Ocup Não Determinadas'!A:G,7,FALSE) -> 31508262 | J31: =IFERROR(VLOOKUP(F31,'[1]Prod-CNAE-CF'!$A$5:$H$72,8,FALSE),'estimativa bc débitos'!$K$17) -> 0.5 | K31: =1-J31 -> 0.5 | L31: =D31*$K31 -> 17027326 | M31: =E31*$K31 -> 15754131 | N31: =IFERROR(VLOOKUP(A31,'[2]estim bc créditos'!$H$4:$L$139,4,FALSE),0) -> 1187126 | O31: =IFERROR(VLOOKUP(A31,'[2]estim bc créditos'!$H$4:$L$139,5,FALSE),0) -> 737954.37
A32: 211 | B32: MATEMÁTICO, ESTATÍSTICO, ATUÁRIO E AFINS | C32: LC 214/2025, art 127 | D32: =VLOOKUP(A32,'Correção Ocup Não Determinadas'!A:G,6,FALSE) -> 9615026.9 | E32: =VLOOKUP(A32,'Correção Ocup Não Determinadas'!A:G,7,FALSE) -> 8971193.6 | F32: 7380 | G32: Outras atividades profissionais, científicas e técnicas | H32: 7490 | I32: Atividades profissionais, científicas e técnicas não especificadas anteriormente | J32: =IFERROR(VLOOKUP(F32,'[1]Prod-CNAE-CF'!$A$5:$H$72,8,FALSE),'estimativa bc débitos'!$K$17) -> 0.017361587 | K32: =1-J32 -> 0.98263841 | L32: =D32*$K32 -> 9448094.7 | M32: =E32*$K32 -> 8815439.4 | N32: =IFERROR(VLOOKUP(A32,'[2]estim bc créditos'!$H$4:$L$139,4,FALSE),0) -> 460725.41 | O32: =IFERROR(VLOOKUP(A32,'[2]estim bc créditos'!$H$4:$L$139,5,FALSE),0) -> 407869.58
A33: 212 | B33: ANALISTA DE SISTEMAS, DESENVOLVEDOR DE SOFTWARE, ADMINISTRADOR DE REDES E BANCOS DE DADOS E OUTROS ESPECIALISTAS EM INFORMÁTICA (EXCETO TÉCNICOS) | C33: NA | D33: =VLOOKUP(A33,'Correção Ocup Não Determinadas'!A:G,6,FALSE) -> 1.4360764e+08 | E33: =VLOOKUP(A33,'Correção Ocup Não Determinadas'!A:G,7,FALSE) -> 1.4136043e+08 | J33: =IFERROR(VLOOKUP(F33,'[1]Prod-CNAE-CF'!$A$5:$H$72,8,FALSE),'estimativa bc débitos'!$K$17) -> 0.5 | K33: =1-J33 -> 0.5 | L33: =D33*$K33 -> 71803820 | M33: =E33*$K33 -> 70680216 | N33: =IFERROR(VLOOKUP(A33,'[2]estim bc créditos'!$H$4:$L$139,4,FALSE),0) -> 6926771.4 | O33: =IFERROR(VLOOKUP(A33,'[2]estim bc créditos'!$H$4:$L$139,5,FALSE),0) -> 4482001.8
A34: 213 | B34: FÍSICO, QUÍMICO, METEOROLOGISTA, GEÓLOGO, OCEANÓGRAFO E AFINS | C34: LC 214/2025, art 127 | D34: =VLOOKUP(A34,'Correção Ocup Não Determinadas'!A:G,6,FALSE) -> 13623743 | E34: =VLOOKUP(A34,'Correção Ocup Não Determinadas'!A:G,7,FALSE) -> 13384804 | F34: 7380 | G34: Outras atividades profissionais, científicas e técnicas | H34: 7490 | I34: Atividades profissionais, científicas e técnicas não especificadas anteriormente | J34: =IFERROR(VLOOKUP(F34,'[1]Prod-CNAE-CF'!$A$5:$H$72,8,FALSE),'estimativa bc débitos'!$K$17) -> 0.017361587 | K34: =1-J34 -> 0.98263841 | L34: =D34*$K34 -> 13387213 | M34: =E34*$K34 -> 13152422 | N34: =IFERROR(VLOOKUP(A34,'[2]estim bc créditos'!$H$4:$L$139,4,FALSE),0) -> 278140.31 | O34: =IFERROR(VLOOKUP(A34,'[2]estim bc créditos'!$H$4:$L$139,5,FALSE),0) -> 365736.09
A35: 214 | B35: ENGENHEIRO, ARQUITETO E AFINS | C35: LC 214/2025, art 127 | D35: =VLOOKUP(A35,'Correção Ocup Não Determinadas'!A:G,6,FALSE) -> 8.3728993e+08 | E35: =VLOOKUP(A35,'Correção Ocup Não Determinadas'!A:G,7,FALSE) -> 8.6477276e+08 | F35: 7180 | G35: Serviços de arquitetura, engenharia, testes/análises técnicas e P & D | H35: 7112 | I35: Serviços de engenharia | J35: =IFERROR(VLOOKUP(F35,'[1]Prod-CNAE-CF'!$A$5:$H$72,8,FALSE),'estimativa bc débitos'!$K$17) -> 0.41733223 | K35: =1-J35 -> 0.58266777 | L35: =D35*$K35 -> 4.8786185e+08 | M35: =E35*$K35 -> 5.0387521e+08 | N35: =IFERROR(VLOOKUP(A35,'[2]estim bc créditos'!$H$4:$L$139,4,FALSE),0) -> 32663215 | O35: =IFERROR(VLOOKUP(A35,'[2]estim bc créditos'!$H$4:$L$139,5,FALSE),0) -> 33902673
A36: 215 | B36: PILOTO DE AERONAVES, COMANDANTE DE EMBARCAÇÕES E OFICIAIS DE MÁQUINAS | C36: NA | D36: =VLOOKUP(A36,'Correção Ocup Não Determinadas'!A:G,6,FALSE) -> 6642594.7 | E36: =VLOOKUP(A36,'Correção Ocup Não Determinadas'!A:G,7,FALSE) -> 7397601.6 | J36: =IFERROR(VLOOKUP(F36,'[1]Prod-CNAE-CF'!$A$5:$H$72,8,FALSE),'estimativa bc débitos'!$K$17) -> 0.5 | K36: =1-J36 -> 0.5 | L36: =D36*$K36 -> 3321297.4 | M36: =E36*$K36 -> 3698800.8 | N36: =IFERROR(VLOOKUP(A36,'[2]estim bc créditos'!$H$4:$L$139,4,FALSE),0) -> 573849.11 | O36: =IFERROR(VLOOKUP(A36,'[2]estim bc créditos'!$H$4:$L$139,5,FALSE),0) -> 659340.66
A37: 221 | B37: BIÓLOGO, BIOMÉDICO E AFINS | C37: LC 214/2025, art 127 | D37: =VLOOKUP(A37,'Correção Ocup Não Determinadas'!A:G,6,FALSE) -> 72390751 | E37: =VLOOKUP(A37,'Correção Ocup Não Determinadas'!A:G,7,FALSE) -> 88454434 | F37: 7380 | G37: Outras atividades profissionais, científicas e técnicas | H37: 7490 | I37: Atividades profissionais, científicas e técnicas não especificadas anteriormente | J37: =IFERROR(VLOOKUP(F37,'[1]Prod-CNAE-CF'!$A$5:$H$72,8,FALSE),'estimativa bc débitos'!$K$17) -> 0.017361587 | K37: =1-J37 -> 0.98263841 | L37: =D37*$K37 -> 71133932 | M37: =E37*$K37 -> 86918725 | N37: =IFERROR(VLOOKUP(A37,'[2]estim bc créditos'!$H$4:$L$139,4,FALSE),0) -> 6202028 | O37: =IFERROR(VLOOKUP(A37,'[2]estim bc créditos'!$H$4:$L$139,5,FALSE),0) -> 7861026.7
A38: 222 | B38: AGRÔNOMO E AFINS | C38: LC 214/2025, art 127 | D38: =VLOOKUP(A38,'Correção Ocup Não Determinadas'!A:G,6,FALSE) -> 43770177 | E38: =VLOOKUP(A38,'Correção Ocup Não Determinadas'!A:G,7,FALSE) -> 46634790 | F38: 7380 | G38: Outras atividades profissionais, científicas e técnicas | H38: 7490 | I38: Atividades profissionais, científicas e técnicas não especificadas anteriormente | J38: =IFERROR(VLOOKUP(F38,'[1]Prod-CNAE-CF'!$A$5:$H$72,8,FALSE),'estimativa bc débitos'!$K$17) -> 0.017361587 | K38: =1-J38 -> 0.98263841 | L38: =D38*$K38 -> 43010257 | M38: =E38*$K38 -> 45825136 | N38: =IFERROR(VLOOKUP(A38,'[2]estim bc créditos'!$H$4:$L$139,4,FALSE),0) -> 1536027.4 | O38: =IFERROR(VLOOKUP(A38,'[2]estim bc créditos'!$H$4:$L$139,5,FALSE),0) -> 1266013
A39: 224 | B39: PROFISSIONAL DA EDUCAÇÃO FÍSICA (EXCETO PROFESSOR) | C39: LC 214/2025, art 127 | D39: =VLOOKUP(A39,'Correção Ocup Não Determinadas'!A:G,6,FALSE) -> 2.6112619e+08 | E39: =VLOOKUP(A39,'Correção Ocup Não Determinadas'!A:G,7,FALSE) -> 2.9361113e+08 | F39: 8592 | G39: Educação privada | H39: 8591 | I39: Ensino de esportes | J39: =IFERROR(VLOOKUP(F39,'[1]Prod-CNAE-CF'!$A$5:$H$72,8,FALSE),'estimativa bc débitos'!$K$17) -> 0.86214152 | K39: =1-J39 -> 0.13785848 | L39: =D39*$K39 -> 35998461 | M39: =E39*$K39 -> 40476785 | N39: =IFERROR(VLOOKUP(A39,'[2]estim bc créditos'!$H$4:$L$139,4,FALSE),0) -> 4534075.9 | O39: =IFERROR(VLOOKUP(A39,'[2]estim bc créditos'!$H$4:$L$139,5,FALSE),0) -> 5559179.9
A40: 225 | B40: MÉDICO | C40: Profissionais de saúde | D40: =VLOOKUP(A40,'Correção Ocup Não Determinadas'!A:G,6,FALSE) -> 4.8463473e+09 | E40: =VLOOKUP(A40,'Correção Ocup Não Determinadas'!A:G,7,FALSE) -> 4.9517154e+09 | F40: 8692 | G40: Saúde privada | H40: 8630 | I40: Atividades de atenção ambulatorial executadas por médicos e odontólogos | J40: =IFERROR(VLOOKUP(F40,'[1]Prod-CNAE-CF'!$A$5:$H$72,8,FALSE),'estimativa bc débitos'!$K$17) -> 0.87671712 | K40: =1-J40 -> 0.12328288 | L40: =D40*$K40 -> 5.9747166e+08 | M40: =E40*$K40 -> 6.1046175e+08 | N40: =IFERROR(VLOOKUP(A40,'[2]estim bc créditos'!$H$4:$L$139,4,FALSE),0) -> 2.0934557e+09 | O40: =IFERROR(VLOOKUP(A40,'[2]estim bc créditos'!$H$4:$L$139,5,FALSE),0) -> 2.1653161e+09
A41: 226 | B41: ODONTÓLOGO | C41: Profissionais de saúde | D41: =VLOOKUP(A41,'Correção Ocup Não Determinadas'!A:G,6,FALSE) -> 1.2846096e+10 | E41: =VLOOKUP(A41,'Correção Ocup Não Determinadas'!A:G,7,FALSE) -> 1.3407102e+10 | F41: 8692 | G41: Saúde privada | H41: 8630 | I41: Atividades de atenção ambulatorial executadas por médicos e odontólogos | J41: =IFERROR(VLOOKUP(F41,'[1]Prod-CNAE-CF'!$A$5:$H$72,8,FALSE),'estimativa bc débitos'!$K$17) -> 0.87671712 | K41: =1-J41 -> 0.12328288 | L41: =D41*$K41 -> 1.5837037e+09 | M41: =E41*$K41 -> 1.6528662e+09 | N41: =IFERROR(VLOOKUP(A41,'[2]estim bc créditos'!$H$4:$L$139,4,FALSE),0) -> 2.4317728e+09 | O41: =IFERROR(VLOOKUP(A41,'[2]estim bc créditos'!$H$4:$L$139,5,FALSE),0) -> 2.5559071e+09
A42: 227 | B42: ENFERMEIRO DE NÍVEL SUPERIOR, NUTRICIONISTA, FARMACÊUTICO E AFINS | C42: Profissionais de saúde | D42: =VLOOKUP(A42,'Correção Ocup Não Determinadas'!A:G,6,FALSE) -> 3.3667132e+08 | E42: =VLOOKUP(A42,'Correção Ocup Não Determinadas'!A:G,7,FALSE) -> 3.8819542e+08 | F42: 8692 | G42: Saúde privada | H42: 8650 | I42: Atividades de profissionais da área de saúde, exceto médicos e odontólogos | J42: =IFERROR(VLOOKUP(F42,'[1]Prod-CNAE-CF'!$A$5:$H$72,8,FALSE),'estimativa bc débitos'!$K$17) -> 0.87671712 | K42: =1-J42 -> 0.12328288 | L42: =D42*$K42 -> 41505811 | M42: =E42*$K42 -> 47857851 | N42: =IFERROR(VLOOKUP(A42,'[2]estim bc créditos'!$H$4:$L$139,4,FALSE),0) -> 17802328 | O42: =IFERROR(VLOOKUP(A42,'[2]estim bc créditos'!$H$4:$L$139,5,FALSE),0) -> 19978654
A43: 228 | B43: VETERINÁRIO, PATOLOGISTA (VETERINÁRIO) E ZOOTECNISTA | C43: LC 214/2025, art 127 | D43: =VLOOKUP(A43,'Correção Ocup Não Determinadas'!A:G,6,FALSE) -> 2.9011327e+08 | E43: =VLOOKUP(A43,'Correção Ocup Não Determinadas'!A:G,7,FALSE) -> 2.9147651e+08 | F43: 7380 | G43: Outras atividades profissionais, científicas e técnicas | H43: 7490 | I43: Atividades profissionais, científicas e técnicas não especificadas anteriormente | J43: =IFERROR(VLOOKUP(F43,'[1]Prod-CNAE-CF'!$A$5:$H$72,8,FALSE),'estimativa bc débitos'!$K$17) -> 0.017361587 | K43: =1-J43 -> 0.98263841 | L43: =D43*$K43 -> 2.8507645e+08 | M43: =E43*$K43 -> 2.8641601e+08 | N43: =IFERROR(VLOOKUP(A43,'[2]estim bc créditos'!$H$4:$L$139,4,FALSE),0) -> 25636956 | O43: =IFERROR(VLOOKUP(A43,'[2]estim bc créditos'!$H$4:$L$139,5,FALSE),0) -> 24331897
A44: 229 | B44: FONOAUDIÓLOGO, FISIOTERAPEUTA, TERAPEUTA OCUPACIONAL E AFINS | C44: Profissionais de saúde | D44: =VLOOKUP(A44,'Correção Ocup Não Determinadas'!A:G,6,FALSE) -> 2.5871049e+09 | E44: =VLOOKUP(A44,'Correção Ocup Não Determinadas'!A:G,7,FALSE) -> 0 | F44: 8692 | G44: Saúde privada | H44: 8650 | I44: Atividades de profissionais da área de saúde, exceto médicos e odontólogos | J44: =IFERROR(VLOOKUP(F44,'[1]Prod-CNAE-CF'!$A$5:$H$72,8,FALSE),'estimativa bc débitos'!$K$17) -> 0.87671712 | K44: =1-J44 -> 0.12328288 | L44: =D44*$K44 -> 3.1894575e+08 | M44: =E44*$K44 -> 0 | N44: =IFERROR(VLOOKUP(A44,'[2]estim bc créditos'!$H$4:$L$139,4,FALSE),0) -> 1.305057e+08 | O44: =IFERROR(VLOOKUP(A44,'[2]estim bc créditos'!$H$4:$L$139,5,FALSE),0) -> 3195317
A45: 230 | B45: FONOAUDIÓLOGO | C45: Profissionais de saúde | D45: =VLOOKUP(A45,'Correção Ocup Não Determinadas'!A:G,6,FALSE) -> 0 | E45: =VLOOKUP(A45,'Correção Ocup Não Determinadas'!A:G,7,FALSE) -> 4.3766029e+08 | F45: 8692 | G45: Saúde privada | H45: 8650 | I45: Atividades de profissionais da área de saúde, exceto médicos e odontólogos | J45: =IFERROR(VLOOKUP(F45,'[1]Prod-CNAE-CF'!$A$5:$H$72,8,FALSE),'estimativa bc débitos'!$K$17) -> 0.87671712 | K45: =1-J45 -> 0.12328288 | L45: =D45*$K45 -> 0 | M45: =E45*$K45 -> 53956022 | N45: =IFERROR(VLOOKUP(A45,'[2]estim bc créditos'!$H$4:$L$139,4,FALSE),0) -> 697107.45 | O45: =IFERROR(VLOOKUP(A45,'[2]estim bc créditos'!$H$4:$L$139,5,FALSE),0) -> 30278988
A46: 231 | B46: FISIOTERAPEUTA | C46: Profissionais de saúde | D46: =VLOOKUP(A46,'Correção Ocup Não Determinadas'!A:G,6,FALSE) -> 0 | E46: =VLOOKUP(A46,'Correção Ocup Não Determinadas'!A:G,7,FALSE) -> 1.7835757e+09 | F46: 8692 | G46: Saúde privada | H46: 8650 | I46: Atividades de profissionais da área de saúde, exceto médicos e odontólogos | J46: =IFERROR(VLOOKUP(F46,'[1]Prod-CNAE-CF'!$A$5:$H$72,8,FALSE),'estimativa bc débitos'!$K$17) -> 0.87671712 | K46: =1-J46 -> 0.12328288 | L46: =D46*$K46 -> 0 | M46: =E46*$K46 -> 2.1988435e+08 | N46: =IFERROR(VLOOKUP(A46,'[2]estim bc créditos'!$H$4:$L$139,4,FALSE),0) -> 1914815.3 | O46: =IFERROR(VLOOKUP(A46,'[2]estim bc créditos'!$H$4:$L$139,5,FALSE),0) -> 83170350
A47: 232 | B47: TERAPEUTA OCUPACIONAL | C47: Profissionais de saúde | D47: =VLOOKUP(A47,'Correção Ocup Não Determinadas'!A:G,6,FALSE) -> 0 | E47: =VLOOKUP(A47,'Correção Ocup Não Determinadas'!A:G,7,FALSE) -> 1.3750439e+08 | F47: 8692 | G47: Saúde privada | H47: 8650 | I47: Atividades de profissionais da área de saúde, exceto médicos e odontólogos | J47: =IFERROR(VLOOKUP(F47,'[1]Prod-CNAE-CF'!$A$5:$H$72,8,FALSE),'estimativa bc débitos'!$K$17) -> 0.87671712 | K47: =1-J47 -> 0.12328288 | L47: =D47*$K47 -> 0 | M47: =E47*$K47 -> 16951937 | N47: =IFERROR(VLOOKUP(A47,'[2]estim bc créditos'!$H$4:$L$139,4,FALSE),0) -> 192918.27 | O47: =IFERROR(VLOOKUP(A47,'[2]estim bc créditos'!$H$4:$L$139,5,FALSE),0) -> 8379439.7
A48: 241 | B48: ADVOGADO | C48: LC 214/2025, art 127 | D48: =VLOOKUP(A48,'Correção Ocup Não Determinadas'!A:G,6,FALSE) -> 2.5286054e+09 | E48: =VLOOKUP(A48,'Correção Ocup Não Determinadas'!A:G,7,FALSE) -> 2.8682761e+09 | F48: 6980 | G48: Atividades jurídicas, contábeis, consultoria e sedes de empresas | H48: 6911 | I48: Atividades jurídicas, exceto cartórios | J48: =IFERROR(VLOOKUP(F48,'[1]Prod-CNAE-CF'!$A$5:$H$72,8,FALSE),'estimativa bc débitos'!$K$17) -> 0.07745464 | K48: =1-J48 -> 0.92254536 | L48: =D48*$K48 -> 2.3327532e+09 | M48: =E48*$K48 -> 2.6461148e+09 | N48: =IFERROR(VLOOKUP(A48,'[2]estim bc créditos'!$H$4:$L$139,4,FALSE),0) -> 1.7109718e+08 | O48: =IFERROR(VLOOKUP(A48,'[2]estim bc créditos'!$H$4:$L$139,5,FALSE),0) -> 1.9204533e+08
...

Sheet estimativa bc débitos
E1: Base de Cálculo Débitos (total) | I1: Base de Cálculo Débitos (total) COM ALTERAÇÃO COMPORTAMENTO | K1: Parcela Consumo Intermediário (ajuste mod. Central) | N1: Parcela Consumo Intermediário (ajuste mod. Central) COM ALTERAÇÃO COMPORTAMENTO | Q1: Base de Cálculo dos Créditos CBS | S1: Base de Cálculo dos Créditos CBS COM ALTERAÇÃO COMPORTAMENTO
A2: Categoria | B2: Ocupação | C2: Nome no Módulo | D2: Incidência CBS Débitos | E2: 2023 | F2: 2024 | G2: 20.23 | H2: 20.24 | I2: 2023 | J2: 2024 | K2: 2023 | L2: 2024 | N2: 2023 | O2: 2024 | P2: Incidência CBS Créditos | Q2: 2023 | R2: 2024 | S2: 2023 | T2: 2024
A3: NA | B3: Geral | C3: Alíq. Referência - Demais serviços e bens | D3: Alíquota de referência | E3: =SUMIFS('Totais Rend TNA por Categoria'!$D$3:$D$140,'Totais Rend TNA por Categoria'!$C$3:$C$140,'estimativa bc débitos'!A3) -> 1.9210976e+10 | F3: =SUMIFS('Totais Rend TNA por Categoria'!$E$3:$E$140,'Totais Rend TNA por Categoria'!$C$3:$C$140,'estimativa bc débitos'!A3) -> 2.0701991e+10 | G3: =E3/$E$10 -> 0.25477206 | H3: =F3/$F$10 -> 0.25134931 | I3: =E3*(1-$F$20) -> 1.5368781e+10 | J3: =F3*(1-$F$20) -> 1.6561593e+10 | K3: =SUMIFS('Totais Rend TNA por Categoria'!$L$3:$L$140,'Totais Rend TNA por Categoria'!$C$3:$C$140,'estimativa bc débitos'!A3) -> 9.605488e+09 | L3: =SUMIFS('Totais Rend TNA por Categoria'!$M$3:$M$140,'Totais Rend TNA por Categoria'!$C$3:$C$140,'estimativa bc débitos'!A3) -> 1.0350996e+10 | M3: =L3/F3 -> 0.5 | N3: =K3*(1-$F$20) -> 7.6843904e+09 | O3: =L3*(1-$F$20) -> 8.2807965e+09 | P3: Alíquota de referência | Q3: =SUMIFS('Totais Rend TNA por Categoria'!$N$3:$N$140,'Totais Rend TNA por Categoria'!$C$3:$C$140,'estimativa bc débitos'!A3) -> 9.4186526e+08 | R3: =SUMIFS('Totais Rend TNA por Categoria'!$O$3:$O$140,'Totais Rend TNA por Categoria'!$C$3:$C$140,'estimativa bc débitos'!A3) -> 9.9089072e+08 | S3: =Q3*(1-$F$20) -> 7.5349221e+08 | T3: =R3*(1-$F$20) -> 7.9271257e+08
A4: TITULAR DE CARTÓRIO | B4: cartório | C4: Alíq. Referência - Titular de Cartório | D4: Alíquota de referência | E4: =SUMIFS('Totais Rend TNA por Categoria'!$D$3:$D$140,'Totais Rend TNA por Categoria'!$C$3:$C$140,'estimativa bc débitos'!A4) -> 2.4278582e+10 | F4: =SUMIFS('Totais Rend TNA por Categoria'!$E$3:$E$140,'Totais Rend TNA por Categoria'!$C$3:$C$140,'estimativa bc débitos'!A4) -> 2.807556e+10 | G4: =E4/$E$10 -> 0.32197762 | H4: =F4/$F$10 -> 0.3408741 | I4: =E4 -> 2.4278582e+10 | J4: =F4 -> 2.807556e+10 | K4: =SUMIFS('Totais Rend TNA por Categoria'!$L$3:$L$140,'Totais Rend TNA por Categoria'!$C$3:$C$140,'estimativa bc débitos'!A4) -> 2.2398093e+10 | L4: =SUMIFS('Totais Rend TNA por Categoria'!$M$3:$M$140,'Totais Rend TNA por Categoria'!$C$3:$C$140,'estimativa bc débitos'!A4) -> 2.5900978e+10 | M4: =L4/F4 -> 0.92254536 | N4: =K4 -> 2.2398093e+10 | O4: =L4 -> 2.5900978e+10 | P4: Alíquota de referência | Q4: =SUMIFS('Totais Rend TNA por Categoria'!$N$3:$N$140,'Totais Rend TNA por Categoria'!$C$3:$C$140,'estimativa bc débitos'!A4) -> 4.2483188e+09 | R4: =SUMIFS('Totais Rend TNA por Categoria'!$O$3:$O$140,'Totais Rend TNA por Categoria'!$C$3:$C$140,'estimativa bc débitos'!A4) -> 4.794143e+09 | S4: =Q4 -> 4.2483188e+09 | T4: =R4 -> 4.794143e+09
A5: LC 214/2025, art 127 | B5: Profissional liberal | C5: Alíq. Reduzida em 30% - Profissionais Liberais - Art. 127 | D5: Redução de 30% | E5: =SUMIFS('Totais Rend TNA por Categoria'!$D$3:$D$140,'Totais Rend TNA por Categoria'!$C$3:$C$140,'estimativa bc débitos'!A5) -> 5.4115694e+09 | F5: =SUMIFS('Totais Rend TNA por Categoria'!$E$3:$E$140,'Totais Rend TNA por Categoria'!$C$3:$C$140,'estimativa bc débitos'!A5) -> 5.9154837e+09 | G5: =E5/$E$10 -> 0.071767133 | H5: =F5/$F$10 -> 0.071821727 | I5: =E5*(1-$F$20) -> 4.3292555e+09 | J5: =F5*(1-$F$20) -> 4.732387e+09 | K5: =SUMIFS('Totais Rend TNA por Categoria'!$L$3:$L$140,'Totais Rend TNA por Categoria'!$C$3:$C$140,'estimativa bc débitos'!A5) -> 4.5162159e+09 | L5: =SUMIFS('Totais Rend TNA por Categoria'!$M$3:$M$140,'Totais Rend TNA por Categoria'!$C$3:$C$140,'estimativa bc débitos'!A5) -> 4.9451103e+09 | M5: =L5/F5 -> 0.83596043 | N5: =K5*(1-$F$20) -> 3.6129727e+09 | O5: =L5*(1-$F$20) -> 3.9560883e+09 | P5: Alíquota de referência | Q5: =SUMIFS('Totais Rend TNA por Categoria'!$N$3:$N$140,'Totais Rend TNA por Categoria'!$C$3:$C$140,'estimativa bc débitos'!A5) -> 3.9280935e+08 | R5: =SUMIFS('Totais Rend TNA por Categoria'!$O$3:$O$140,'Totais Rend TNA por Categoria'!$C$3:$C$140,'estimativa bc débitos'!A5) -> 4.1773866e+08 | S5: =Q5*(1-$F$20) -> 3.1424748e+08 | T5: =R5*(1-$F$20) -> 3.3419093e+08
A6: Profissionais de saúde | B6: Profissionais de saúde | C6: Alíq. reduzida em 60% - Serviços de saúde - Art. 130 (Anexo III) | D6: Redução de 60% | E6: =SUMIFS('Totais Rend TNA por Categoria'!$D$3:$D$140,'Totais Rend TNA por Categoria'!$C$3:$C$140,'estimativa bc débitos'!A6) -> 2.4343716e+10 | F6: =SUMIFS('Totais Rend TNA por Categoria'!$E$3:$E$140,'Totais Rend TNA por Categoria'!$C$3:$C$140,'estimativa bc débitos'!A6) -> 2.5442834e+10 | G6: =E6/$E$10 -> 0.32284142 | H6: =F6/$F$10 -> 0.30890935 | I6: =E6*(1-$F$20) -> 1.9474973e+10 | J6: =F6*(1-$F$20) -> 2.0354267e+10 | K6: =SUMIFS('Totais Rend TNA por Categoria'!$L$3:$L$140,'Totais Rend TNA por Categoria'!$C$3:$C$140,'estimativa bc débitos'!A6) -> 3.0011635e+09 | L6: =SUMIFS('Totais Rend TNA por Categoria'!$M$3:$M$140,'Totais Rend TNA por Categoria'!$C$3:$C$140,'estimativa bc débitos'!A6) -> 3.1366658e+09 | M6: =L6/F6 -> 0.12328288 | N6: =K6*(1-$F$20) -> 2.4009308e+09 | O6: =L6*(1-$F$20) -> 2.5093327e+09 | P6: Alíquota de referência | Q6: =SUMIFS('Totais Rend TNA por Categoria'!$N$3:$N$140,'Totais Rend TNA por Categoria'!$C$3:$C$140,'estimativa bc débitos'!A6) -> 4.8815468e+09 | R6: =SUMIFS('Totais Rend TNA por Categoria'!$O$3:$O$140,'Totais Rend TNA por Categoria'!$C$3:$C$140,'estimativa bc débitos'!A6) -> 5.1084311e+09 | S6: =Q6*(1-$F$20) -> 3.9052374e+09 | T6: =R6*(1-$F$20) -> 4.0867448e+09
A7: LC 214/2025, art 139 | B7: Prof. artes, cultura, eventos, jornalistica e audio | C7: Alíq. reduzida em 60% - Prof. artes, cultura, eventos, jornalistica e audio - Art. 139 (Anexo X) | D7: Redução de 60% | E7: =SUMIFS('Totais Rend TNA por Categoria'!$D$3:$D$140,'Totais Rend TNA por Categoria'!$C$3:$C$140,'estimativa bc débitos'!A7) -> 2.7770196e+08 | F7: =SUMIFS('Totais Rend TNA por Categoria'!$E$3:$E$140,'Totais Rend TNA por Categoria'!$C$3:$C$140,'estimativa bc débitos'!A7) -> 2.852416e+08 | G7: =E7/$E$10 -> 0.003682827 | H7: =F7/$F$10 -> 0.0034632069 | I7: =E7*(1-$F$20) -> 2.2216157e+08 | J7: =F7*(1-$F$20) -> 2.2819328e+08 | K7: =SUMIFS('Totais Rend TNA por Categoria'!$L$3:$L$140,'Totais Rend TNA por Categoria'!$C$3:$C$140,'estimativa bc débitos'!A7) -> 1.4567096e+08 | L7: =SUMIFS('Totais Rend TNA por Categoria'!$M$3:$M$140,'Totais Rend TNA por Categoria'!$C$3:$C$140,'estimativa bc débitos'!A7) -> 1.4818792e+08 | M7: =L7/F7 -> 0.51951723 | N7: =K7*(1-$F$20) -> 1.1653676e+08 | O7: =L7*(1-$F$20) -> 1.1855034e+08 | P7: Alíquota de referência | Q7: =SUMIFS('Totais Rend TNA por Categoria'!$N$3:$N$140,'Totais Rend TNA por Categoria'!$C$3:$C$140,'estimativa bc débitos'!A7) -> 7916253.2 | R7: =SUMIFS('Totais Rend TNA por Categoria'!$O$3:$O$140,'Totais Rend TNA por Categoria'!$C$3:$C$140,'estimativa bc débitos'!A7) -> 8181694.4 | S7: =Q7*(1-$F$20) -> 6333002.6 | T7: =R7*(1-$F$20) -> 6545355.5
A8: LC 214/2025, art 129 | B8: Profissionais da educação | C8: Alíq. reduzida em 60% - Prof. educação - Art. 129 | D8: Redução de 60% | E8: =SUMIFS('Totais Rend TNA por Categoria'!$D$3:$D$140,'Totais Rend TNA por Categoria'!$C$3:$C$140,'estimativa bc débitos'!A8) -> 6.0287021e+08 | F8: =SUMIFS('Totais Rend TNA por Categoria'!$E$3:$E$140,'Totais Rend TNA por Categoria'!$C$3:$C$140,'estimativa bc débitos'!A8) -> 6.3329841e+08 | G8: =E8/$E$10 -> 0.0079951421 | H8: =F8/$F$10 -> 0.0076890729 | I8: =E8*(1-$F$20) -> 4.8229616e+08 | J8: =F8*(1-$F$20) -> 5.0663873e+08 | K8: =SUMIFS('Totais Rend TNA por Categoria'!$L$3:$L$140,'Totais Rend TNA por Categoria'!$C$3:$C$140,'estimativa bc débitos'!A8) -> 83110772 | L8: =SUMIFS('Totais Rend TNA por Categoria'!$M$3:$M$140,'Totais Rend TNA por Categoria'!$C$3:$C$140,'estimativa bc débitos'!A8) -> 87305559 | M8: =L8/F8 -> 0.13785848 | N8: =K8*(1-$F$20) -> 66488618 | O8: =L8*(1-$F$20) -> 69844447 | P8: Alíquota de referência | Q8: =SUMIFS('Totais Rend TNA por Categoria'!$N$3:$N$140,'Totais Rend TNA por Categoria'!$C$3:$C$140,'estimativa bc débitos'!A8) -> 33375402 | R8: =SUMIFS('Totais Rend TNA por Categoria'!$O$3:$O$140,'Totais Rend TNA por Categoria'!$C$3:$C$140,'estimativa bc débitos'!A8) -> 34836844 | S8: =Q8*(1-$F$20) -> 26700322 | T8: =R8*(1-$F$20) -> 27869475
A9: Não contribuinte | B9: Transportador autonomo | D9: Não contribuinte | E9: =SUMIFS('Totais Rend TNA por Categoria'!$D$3:$D$140,'Totais Rend TNA por Categoria'!$C$3:$C$140,'estimativa bc débitos'!A9) -> 1.2791481e+09 | F9: =SUMIFS('Totais Rend TNA por Categoria'!$E$3:$E$140,'Totais Rend TNA por Categoria'!$C$3:$C$140,'estimativa bc débitos'!A9) -> 1.3090204e+09 | G9: =E9/$E$10 -> 0.016963802 | H9: =F9/$F$10 -> 0.015893223 | I9: =SUMIFS('Totais Rend TNA por Categoria'!$D$3:$D$140,'Totais Rend TNA por Categoria'!$C$3:$C$140,'estimativa bc débitos'!E9) -> 0 | J9: =SUMIFS('Totais Rend TNA por Categoria'!$E$3:$E$140,'Totais Rend TNA por Categoria'!$C$3:$C$140,'estimativa bc débitos'!E9) -> 0 | K9: =SUMIFS('Totais Rend TNA por Categoria'!$L$3:$L$140,'Totais Rend TNA por Categoria'!$C$3:$C$140,'estimativa bc débitos'!A9) -> 6.3957405e+08 | L9: =SUMIFS('Totais Rend TNA por Categoria'!$M$3:$M$140,'Totais Rend TNA por Categoria'!$C$3:$C$140,'estimativa bc débitos'!A9) -> 6.5451019e+08 | M9: =L9/F9 -> 0.5 | P9: Não contribuinte | Q9: =SUMIFS('Totais Rend TNA por Categoria'!$N$3:$N$140,'Totais Rend TNA por Categoria'!$C$3:$C$140,'estimativa bc débitos'!A9) -> 24255391 | R9: =SUMIFS('Totais Rend TNA por Categoria'!$O$3:$O$140,'Totais Rend TNA por Categoria'!$C$3:$C$140,'estimativa bc débitos'!A9) -> 25662288 | S9: =SUMIFS('Totais Rend TNA por Categoria'!$N$3:$N$140,'Totais Rend TNA por Categoria'!$C$3:$C$140,'estimativa bc débitos'!C9) -> 0 | T9: =SUMIFS('Totais Rend TNA por Categoria'!$O$3:$O$140,'Totais Rend TNA por Categoria'!$C$3:$C$140,'estimativa bc débitos'!C9) -> 0
E10: =SUM(E3:E9) -> 7.5404564e+10 | F10: =SUM(F3:F9) -> 8.2363429e+10 | G10: =E10/$E$10 -> 1 | H10: =F10/$F$10 -> 1 | I10: =SUM(I3:I9) -> 6.4156049e+10 | J10: =SUM(J3:J9) -> 7.0458639e+10 | K10: =SUM(K3:K9) -> 4.0389317e+10 | L10: =SUM(L3:L9) -> 4.5223753e+10 | M10: =L10/F10 -> 0.54907565 | N10: =SUM(N3:N9) -> 3.6279413e+10 | O10: =SUM(O3:O9) -> 4.083559e+10 | Q10: =SUM(Q3:Q9) -> 1.0530087e+10 | R10: =SUM(R3:R9) -> 1.1379884e+10 | S10: =SUM(S3:S9) -> 9.2543293e+09 | T10: =SUM(T3:T9) -> 1.0042206e+10
E11: =E10-'Totais Rend TNA por Categoria'!D142 -> 0 | F11: =F10-'Totais Rend TNA por Categoria'!E142 -> 0 | K11: =K10-'Totais Rend TNA por Categoria'!L142 -> 0 | L11: =L10-'Totais Rend TNA por Categoria'!M142 -> 0 | Q11: =Q10-'Totais Rend TNA por Categoria'!N142 -> 0 | R11: =R10-'Totais Rend TNA por Categoria'!O142 -> 0
Q12: =SUM(Q3:Q8) -> 1.0505832e+10 | R12: =SUM(R3:R8) -> 1.1354222e+10
E15: HIPÓTESE DE ALTERAÇÃO DE COMPORTAMENTO
E16: omissão de receita | F16: perde tudo | K16: definição quanto é consumo intermediário para demais atividades
E17: vira pj | F17: perde parte | K17: 0.5
E20: redutor | F20: 0.2
